# Ancient Warfare Structure Template File
# Auto-generated structure template file. created on: 11/7/2024 at: 23:26:55
# Lines beginning with # denote comments

header:
version=2.1
name=Medium_hbm_house
size=15,9,17
offset=13,-1,15
:endheader

#### VALIDATION ####
validation:
type=ground
survival=true
worldGenEnabled=false
unique=false
preserveBlocks=false
selectionWeight=0
clusterValue=0
minDuplicateDistance=0
dimensionWhiteList=false
dimensionList=
biomeWhiteList=false
biomeList=
leveling=0
fill=0
border=0
validTargetBlocks=
blockSwap=false
data:
:enddata
:endvalidation

#### LAYERS ####
layer: 0
0,0,0,0,0,0,0,0,0,0,0,0,0,0,0
0,0,0,0,0,0,0,0,0,0,0,0,0,0,0
6,0,0,1,0,1,0,0,0,0,1,5,5,2,2
0,0,0,0,3,3,3,3,3,3,3,4,4,4,1
0,0,0,1,3,2,2,2,2,3,3,3,3,3,0
1,0,1,0,3,2,2,2,2,2,2,2,2,3,1
1,3,3,0,3,2,2,2,2,2,2,2,2,3,0
0,3,2,2,2,2,2,2,2,2,2,2,2,3,0
1,3,2,2,2,2,2,2,2,2,2,2,2,3,0
1,3,2,2,2,2,2,2,2,2,2,2,2,3,0
0,3,2,2,2,2,2,2,2,2,2,2,2,3,1
1,3,3,3,3,3,3,3,3,3,3,3,3,3,0
0,3,2,2,2,2,2,2,3,4,4,4,4,2,1
0,3,2,2,2,2,2,2,2,4,4,4,2,2,0
0,3,2,2,2,2,2,2,0,4,4,2,2,0,0
0,3,3,3,3,3,3,3,3,2,2,2,0,0,0
1,0,1,0,0,0,0,1,0,1,0,0,0,0,0
:endlayer
layer: 1
0,0,0,0,0,0,0,0,0,0,0,0,0,0,0
0,0,0,0,0,0,0,0,0,0,0,0,0,0,0
0,0,0,1,7,7,7,7,7,7,1,0,0,10,10
0,0,0,7,8,8,8,8,8,8,0,0,0,0,1
0,0,0,7,8,0,0,0,0,8,8,0,8,8,7
1,7,7,7,8,0,0,0,0,0,0,0,0,8,1
7,8,8,8,8,0,0,0,0,0,0,0,0,8,7
7,8,0,0,0,0,0,0,0,0,0,0,0,8,7
7,8,0,0,0,0,0,0,0,0,0,0,0,8,7
7,8,0,0,0,0,0,0,0,0,0,0,0,8,7
7,8,0,0,0,0,0,0,0,0,0,0,0,8,1
1,8,8,8,9,8,8,8,8,8,8,8,8,8,7
7,8,0,0,0,0,0,0,8,0,0,0,0,0,1
7,8,0,0,0,0,0,0,9,0,0,0,0,0,0
7,8,0,0,0,0,0,0,8,0,0,0,0,0,0
7,8,8,8,8,8,8,8,8,0,0,0,0,0,0
1,7,1,7,7,7,7,1,7,1,0,0,0,0,0
:endlayer
layer: 2
0,0,0,0,0,0,0,0,0,0,0,0,0,0,0
0,0,0,0,0,0,0,0,0,0,0,0,0,0,0
0,0,0,1,0,0,0,0,0,0,1,0,0,0,0
0,0,0,0,8,2,11,11,2,8,0,0,0,0,1
0,0,0,0,8,0,0,0,0,8,8,0,8,8,0
1,0,0,0,8,0,0,0,0,0,0,0,0,2,1
0,8,8,8,8,0,0,0,0,0,0,0,0,2,0
0,2,0,0,0,0,0,0,0,0,0,0,0,11,0
0,11,0,0,0,0,0,0,0,0,0,0,0,11,0
0,11,0,0,0,0,0,0,0,0,0,0,0,2,0
0,2,0,0,0,0,0,0,0,0,0,0,0,2,1
1,8,8,8,14,8,8,8,8,2,11,11,2,8,0
0,2,0,0,0,0,13,0,8,0,0,0,0,0,1
0,11,0,0,0,0,0,0,12,0,0,0,0,0,0
0,2,0,0,0,0,0,0,8,0,0,0,0,0,0
0,8,8,2,11,11,2,8,8,0,0,0,0,0,0
1,0,1,0,0,0,0,1,0,1,0,0,0,0,0
:endlayer
layer: 3
0,0,0,0,0,0,0,0,0,0,0,0,0,0,0
0,0,0,0,0,0,0,0,0,0,0,0,0,0,0
0,0,0,1,15,0,0,0,0,15,1,0,0,0,0
0,0,0,15,8,2,11,11,2,8,0,0,0,0,1
0,0,0,0,8,0,0,0,0,8,8,2,8,8,15
1,15,0,0,8,0,0,0,0,0,0,0,0,8,1
15,8,8,8,8,0,0,0,0,0,0,0,0,8,15
0,8,0,0,0,0,0,0,0,0,0,0,0,8,0
0,8,0,0,0,0,0,0,0,0,0,0,0,8,0
0,8,0,0,0,0,0,0,0,0,0,0,0,8,15
15,8,0,0,0,0,0,0,0,0,0,0,0,8,1
1,8,8,8,2,8,8,8,8,2,11,11,2,8,15
15,8,0,0,0,0,13,0,8,0,0,0,0,15,1
0,8,0,0,0,0,0,0,2,0,0,0,0,0,0
0,8,0,0,0,0,0,0,8,0,0,0,0,0,0
15,8,8,2,11,11,2,8,8,0,0,0,0,0,0
1,15,1,0,0,0,0,1,15,1,0,0,0,0,0
:endlayer
layer: 4
0,0,0,0,0,0,0,0,0,0,0,0,0,0,0
0,0,0,0,0,0,0,0,0,0,0,0,0,0,0
0,0,0,5,5,5,5,5,5,5,5,5,5,5,5
0,0,0,22,8,8,8,8,8,8,17,17,17,17,16
0,0,0,22,8,4,4,4,4,8,8,8,8,8,16
18,17,17,17,8,4,4,4,4,21,0,0,20,8,16
18,8,8,8,8,4,4,4,4,21,0,0,20,8,16
18,4,4,4,4,4,4,4,4,21,0,0,20,8,16
18,4,4,4,4,4,4,4,4,21,0,0,20,8,16
18,4,4,4,4,4,4,4,4,21,0,0,20,8,16
18,4,4,4,4,4,4,4,4,21,0,0,20,8,16
18,4,4,4,4,4,4,4,8,8,8,8,8,8,16
18,4,4,4,4,4,19,4,8,17,17,17,17,17,16
18,4,4,4,4,4,4,4,8,16,0,0,0,0,0
18,4,4,4,4,4,4,4,8,16,0,0,0,0,0
18,8,8,8,8,8,8,8,8,16,0,0,0,0,0
18,17,17,17,17,17,17,17,17,16,0,0,0,0,0
:endlayer
layer: 5
0,0,0,0,0,0,0,0,0,0,0,0,0,0,0
0,0,0,0,0,0,0,0,0,0,0,0,0,0,0
0,0,0,0,0,0,0,0,0,0,0,0,0,0,0
0,0,0,7,27,27,27,27,18,2,7,0,23,16,0
0,0,0,2,4,27,4,27,4,8,8,8,8,27,0
0,18,2,2,4,29,25,30,29,4,4,4,4,25,0
0,26,8,8,8,8,8,8,25,4,4,4,4,27,0
0,26,0,0,0,0,0,0,4,4,4,4,4,25,0
0,26,24,0,0,0,0,23,25,4,4,4,4,25,0
0,26,0,0,0,0,0,0,4,4,4,4,4,27,0
0,26,0,0,0,0,0,0,4,4,4,4,4,25,0
0,26,0,0,0,0,0,0,4,8,8,8,8,27,0
0,28,0,0,0,0,0,0,26,24,0,0,23,16,0
0,27,24,0,0,0,0,23,25,0,0,0,0,0,0
0,26,0,0,0,0,0,0,25,0,0,0,0,0,0
0,26,8,8,8,8,8,8,25,0,0,0,0,0,0
0,18,24,0,0,0,0,23,16,0,0,0,0,0,0
:endlayer
layer: 6
0,0,0,0,0,0,0,0,0,0,0,0,0,0,0
0,0,0,0,0,0,0,0,0,0,0,0,0,0,0
0,0,0,0,0,0,0,0,0,0,0,0,0,0,0
0,0,0,0,0,0,0,0,0,18,24,23,16,0,0
0,0,0,0,0,0,0,0,0,26,8,8,25,0,0
0,0,18,24,0,0,23,16,0,26,4,4,25,0,0
0,0,26,8,11,11,8,25,0,26,4,4,25,0,0
0,0,26,0,0,0,0,25,0,26,4,4,27,0,0
0,0,26,24,0,0,23,27,0,26,4,4,27,0,0
0,0,26,24,0,0,23,25,0,26,4,4,25,0,0
0,0,27,24,0,0,23,25,0,27,4,4,27,0,0
0,0,27,24,0,0,23,27,0,27,8,8,25,0,0
0,0,26,24,0,0,0,25,0,18,24,23,16,0,0
0,0,26,24,0,0,0,25,0,0,0,0,0,0,0
0,0,28,0,0,0,0,25,0,0,0,0,0,0,0
0,0,27,8,11,0,8,25,0,0,0,0,0,0,0
0,0,18,24,0,0,23,16,0,0,0,0,0,0,0
:endlayer
layer: 7
0,0,0,0,0,0,0,0,0,0,0,0,0,0,0
0,0,0,0,0,0,0,0,0,0,0,0,0,0,0
0,0,0,0,0,0,0,0,0,0,0,0,0,0,0
0,0,0,0,0,0,0,0,0,0,7,7,0,0,0
0,0,0,0,0,0,0,0,0,0,27,0,0,0,0
0,0,0,18,24,23,16,0,0,0,0,27,0,0,0
0,0,0,27,8,8,27,0,0,0,27,27,0,0,0
0,0,0,26,0,0,28,0,0,0,27,0,0,0,0
0,0,0,26,24,23,25,0,0,0,27,0,0,0,0
0,0,0,26,24,23,27,0,0,0,27,27,0,0,0
0,0,0,26,24,23,27,0,0,0,27,27,0,0,0
0,0,0,26,24,23,27,0,0,0,27,27,0,0,0
0,0,0,27,24,23,27,0,0,0,7,7,0,0,0
0,0,0,26,24,23,25,0,0,0,0,0,0,0,0
0,0,0,26,0,0,28,0,0,0,0,0,0,0,0
0,0,0,27,8,8,25,0,0,0,0,0,0,0,0
0,0,0,18,24,23,16,0,0,0,0,0,0,0,0
:endlayer
layer: 8
0,0,0,0,0,0,0,0,0,0,0,0,0,0,0
0,0,0,0,0,0,0,0,0,0,0,0,0,0,0
0,0,0,0,0,0,0,0,0,0,0,0,0,0,0
0,0,0,0,0,0,0,0,0,0,0,0,0,0,0
0,0,0,0,0,0,0,0,0,0,0,0,0,0,0
0,0,0,0,7,7,0,0,0,0,0,0,0,0,0
0,0,0,0,27,27,0,0,0,0,0,0,0,0,0
0,0,0,0,27,27,0,0,0,0,0,0,0,0,0
0,0,0,0,0,27,0,0,0,0,0,0,0,0,0
0,0,0,0,27,0,0,0,0,0,0,0,0,0,0
0,0,0,0,27,27,0,0,0,0,0,0,0,0,0
0,0,0,0,27,27,0,0,0,0,0,0,0,0,0
0,0,0,0,0,27,0,0,0,0,0,0,0,0,0
0,0,0,0,27,0,0,0,0,0,0,0,0,0,0
0,0,0,0,27,27,0,0,0,0,0,0,0,0,0
0,0,0,0,27,27,0,0,0,0,0,0,0,0,0
0,0,0,0,7,7,0,0,0,0,0,0,0,0,0
:endlayer

#### RULES ####
rule:
plugin=vanillaBlocks
number=1
data:
JSON:{{"val":{"buildPass":{"val":"0","id":"pi"},"blockName":{"val":"minecraft:log","id":"ss"},"meta":{"val":"0","id":"pi"}},"id":"ct"}}
:enddata
:endrule

rule:
plugin=vanillaBlocks
number=2
data:
JSON:{{"val":{"buildPass":{"val":"0","id":"pi"},"blockName":{"val":"minecraft:planks","id":"ss"},"meta":{"val":"1","id":"pi"}},"id":"ct"}}
:enddata
:endrule

rule:
plugin=vanillaBlocks
number=3
data:
JSON:{{"val":{"buildPass":{"val":"0","id":"pi"},"blockName":{"val":"minecraft:monster_egg","id":"ss"},"meta":{"val":"2","id":"pi"}},"id":"ct"}}
:enddata
:endrule

rule:
plugin=vanillaBlocks
number=4
data:
JSON:{{"val":{"buildPass":{"val":"0","id":"pi"},"blockName":{"val":"minecraft:planks","id":"ss"},"meta":{"val":"0","id":"pi"}},"id":"ct"}}
:enddata
:endrule

rule:
plugin=vanillaBlocks
number=5
data:
JSON:{{"val":{"buildPass":{"val":"0","id":"pi"},"blockName":{"val":"minecraft:spruce_stairs","id":"ss"},"meta":{"val":"2","id":"pi"}},"id":"ct"}}
:enddata
:endrule

rule:
plugin=modBlockDefault
number=6
data:
JSON:{{"val":{"blockName":{"val":"BiomesOPlenty:saplings","id":"ss"},"meta":{"val":"2","id":"pi"}},"id":"ct"}}
:enddata
:endrule

rule:
plugin=vanillaBlocks
number=7
data:
JSON:{{"val":{"buildPass":{"val":"0","id":"pi"},"blockName":{"val":"minecraft:wooden_slab","id":"ss"},"meta":{"val":"1","id":"pi"}},"id":"ct"}}
:enddata
:endrule

rule:
plugin=vanillaBlocks
number=8
data:
JSON:{{"val":{"buildPass":{"val":"0","id":"pi"},"blockName":{"val":"minecraft:brick_block","id":"ss"},"meta":{"val":"0","id":"pi"}},"id":"ct"}}
:enddata
:endrule

rule:
plugin=vanillaDoors
number=9
data:
JSON:{{"val":{"buildPass":{"val":"2","id":"pi"},"blockName":{"val":"minecraft:wooden_door","id":"ss"},"meta":{"val":"6","id":"pi"},"sideFlag":{"val":"8","id":"pb"}},"id":"ct"}}
:enddata
:endrule

rule:
plugin=vanillaBlocks
number=10
data:
JSON:{{"val":{"buildPass":{"val":"0","id":"pi"},"blockName":{"val":"minecraft:fence","id":"ss"},"meta":{"val":"0","id":"pi"}},"id":"ct"}}
:enddata
:endrule

rule:
plugin=vanillaBlocks
number=11
data:
JSON:{{"val":{"buildPass":{"val":"0","id":"pi"},"blockName":{"val":"minecraft:glass_pane","id":"ss"},"meta":{"val":"0","id":"pi"}},"id":"ct"}}
:enddata
:endrule

rule:
plugin=vanillaDoors
number=12
data:
JSON:{{"val":{"buildPass":{"val":"2","id":"pi"},"blockName":{"val":"minecraft:wooden_door","id":"ss"},"meta":{"val":"8","id":"pi"},"sideFlag":{"val":"0","id":"pb"}},"id":"ct"}}
:enddata
:endrule

rule:
plugin=vanillaBlocks
number=13
data:
JSON:{{"val":{"buildPass":{"val":"2","id":"pi"},"blockName":{"val":"minecraft:ladder","id":"ss"},"meta":{"val":"3","id":"pi"}},"id":"ct"}}
:enddata
:endrule

rule:
plugin=vanillaDoors
number=14
data:
JSON:{{"val":{"buildPass":{"val":"2","id":"pi"},"blockName":{"val":"minecraft:wooden_door","id":"ss"},"meta":{"val":"8","id":"pi"},"sideFlag":{"val":"0","id":"pb"}},"id":"ct"}}
:enddata
:endrule

rule:
plugin=vanillaBlocks
number=15
data:
JSON:{{"val":{"buildPass":{"val":"0","id":"pi"},"blockName":{"val":"minecraft:wooden_slab","id":"ss"},"meta":{"val":"9","id":"pi"}},"id":"ct"}}
:enddata
:endrule

rule:
plugin=vanillaBlocks
number=16
data:
JSON:{{"val":{"buildPass":{"val":"0","id":"pi"},"blockName":{"val":"minecraft:spruce_stairs","id":"ss"},"meta":{"val":"1","id":"pi"}},"id":"ct"}}
:enddata
:endrule

rule:
plugin=vanillaBlocks
number=17
data:
JSON:{{"val":{"buildPass":{"val":"0","id":"pi"},"blockName":{"val":"minecraft:log","id":"ss"},"meta":{"val":"4","id":"pi"}},"id":"ct"}}
:enddata
:endrule

rule:
plugin=vanillaBlocks
number=18
data:
JSON:{{"val":{"buildPass":{"val":"0","id":"pi"},"blockName":{"val":"minecraft:spruce_stairs","id":"ss"},"meta":{"val":"0","id":"pi"}},"id":"ct"}}
:enddata
:endrule

rule:
plugin=vanillaBlocks
number=19
data:
JSON:{{"val":{"buildPass":{"val":"2","id":"pi"},"blockName":{"val":"minecraft:trapdoor","id":"ss"},"meta":{"val":"4","id":"pi"}},"id":"ct"}}
:enddata
:endrule

rule:
plugin=vanillaBlocks
number=20
data:
JSON:{{"val":{"buildPass":{"val":"0","id":"pi"},"blockName":{"val":"minecraft:oak_stairs","id":"ss"},"meta":{"val":"4","id":"pi"}},"id":"ct"}}
:enddata
:endrule

rule:
plugin=vanillaBlocks
number=21
data:
JSON:{{"val":{"buildPass":{"val":"0","id":"pi"},"blockName":{"val":"minecraft:oak_stairs","id":"ss"},"meta":{"val":"5","id":"pi"}},"id":"ct"}}
:enddata
:endrule

rule:
plugin=vanillaBlocks
number=22
data:
JSON:{{"val":{"buildPass":{"val":"0","id":"pi"},"blockName":{"val":"minecraft:log","id":"ss"},"meta":{"val":"8","id":"pi"}},"id":"ct"}}
:enddata
:endrule

rule:
plugin=vanillaBlocks
number=23
data:
JSON:{{"val":{"buildPass":{"val":"0","id":"pi"},"blockName":{"val":"minecraft:spruce_stairs","id":"ss"},"meta":{"val":"4","id":"pi"}},"id":"ct"}}
:enddata
:endrule

rule:
plugin=vanillaBlocks
number=24
data:
JSON:{{"val":{"buildPass":{"val":"0","id":"pi"},"blockName":{"val":"minecraft:spruce_stairs","id":"ss"},"meta":{"val":"5","id":"pi"}},"id":"ct"}}
:enddata
:endrule

rule:
plugin=vanillaBlocks
number=25
data:
JSON:{{"val":{"buildPass":{"val":"0","id":"pi"},"blockName":{"val":"minecraft:oak_stairs","id":"ss"},"meta":{"val":"1","id":"pi"}},"id":"ct"}}
:enddata
:endrule

rule:
plugin=vanillaBlocks
number=26
data:
JSON:{{"val":{"buildPass":{"val":"0","id":"pi"},"blockName":{"val":"minecraft:oak_stairs","id":"ss"},"meta":{"val":"0","id":"pi"}},"id":"ct"}}
:enddata
:endrule

rule:
plugin=vanillaBlocks
number=27
data:
JSON:{{"val":{"buildPass":{"val":"0","id":"pi"},"blockName":{"val":"minecraft:wooden_slab","id":"ss"},"meta":{"val":"0","id":"pi"}},"id":"ct"}}
:enddata
:endrule

rule:
plugin=vanillaBlocks
number=28
data:
JSON:{{"val":{"buildPass":{"val":"0","id":"pi"},"blockName":{"val":"minecraft:double_wooden_slab","id":"ss"},"meta":{"val":"0","id":"pi"}},"id":"ct"}}
:enddata
:endrule

rule:
plugin=vanillaBlocks
number=29
data:
JSON:{{"val":{"buildPass":{"val":"0","id":"pi"},"blockName":{"val":"minecraft:oak_stairs","id":"ss"},"meta":{"val":"3","id":"pi"}},"id":"ct"}}
:enddata
:endrule

rule:
plugin=vanillaBlocks
number=30
data:
JSON:{{"val":{"buildPass":{"val":"0","id":"pi"},"blockName":{"val":"minecraft:oak_stairs","id":"ss"},"meta":{"val":"2","id":"pi"}},"id":"ct"}}
:enddata
:endrule

#### ENTITIES ####
