# Ancient Warfare Structure Template File
# Auto-generated structure template file. created on: 12/14/2024 at: 13:21:26
# Lines beginning with # denote comments

header:
version=2.1
name=NPC_wooden_stone_dorm
size=23,18,22
offset=11,0,17
:endheader

#### VALIDATION ####
validation:
type=ground
survival=true
worldGenEnabled=false
unique=false
preserveBlocks=false
selectionWeight=0
clusterValue=0
minDuplicateDistance=0
dimensionWhiteList=false
dimensionList=
biomeWhiteList=false
biomeList=
leveling=0
fill=0
border=0
validTargetBlocks=
blockSwap=false
data:
:enddata
:endvalidation

#### LAYERS ####
layer: 0
0,0,0,0,0,0,0,0,0,0,0,0,0,0,0,0,0,0,0,0,0,0,0
0,1,1,1,1,1,1,1,1,1,1,1,1,1,1,1,1,1,1,1,1,1,0
0,1,2,2,2,2,2,2,2,2,2,2,2,2,2,2,2,2,2,2,2,1,0
0,1,2,2,2,2,2,2,2,2,2,2,2,2,2,2,2,2,2,2,2,1,0
0,1,2,2,2,2,2,2,2,2,2,2,2,2,2,2,2,2,2,2,2,1,0
0,1,2,2,2,2,2,2,2,2,2,2,2,2,2,2,2,2,2,2,2,1,0
0,1,2,2,2,2,2,2,2,2,2,2,2,2,2,2,2,2,2,2,2,1,0
0,1,2,2,2,2,2,2,2,2,2,2,2,2,2,2,2,2,2,2,2,1,0
0,1,2,2,2,2,2,2,2,2,2,2,2,2,2,2,2,2,2,2,2,1,0
0,1,2,2,2,2,2,2,2,2,2,2,2,2,2,2,2,2,2,2,2,1,0
0,1,2,2,2,2,2,2,2,2,2,2,2,2,2,2,2,2,2,2,2,1,0
0,1,2,2,2,2,2,2,2,2,2,2,2,2,2,2,2,2,2,2,2,1,0
0,1,2,2,2,2,2,2,2,2,2,2,2,2,2,2,2,2,2,2,2,1,0
0,1,1,2,2,2,2,2,2,2,2,2,2,2,2,2,2,2,2,2,2,1,0
0,1,2,2,2,2,2,2,2,2,2,2,2,2,2,2,2,2,2,2,2,1,0
0,1,2,2,2,2,2,2,2,2,2,2,2,2,2,2,2,2,2,2,2,1,0
0,1,2,2,2,2,2,2,2,2,2,2,2,2,2,2,2,2,2,2,2,1,0
0,1,2,2,2,2,2,2,2,2,2,2,2,2,2,2,2,2,2,2,2,1,0
0,1,2,2,2,2,2,2,2,1,0,0,0,1,2,2,2,2,2,2,2,1,0
0,1,1,1,1,1,1,1,1,1,0,0,0,1,1,1,1,1,1,1,1,1,0
0,0,0,0,0,0,0,0,0,0,0,0,0,0,0,0,0,0,0,0,0,0,0
0,0,0,0,0,0,0,0,0,0,0,0,0,0,0,0,0,0,0,0,0,0,0
:endlayer
layer: 1
0,0,0,0,0,0,0,0,0,0,0,0,0,0,0,0,0,0,0,0,0,0,0
0,1,1,1,1,1,1,1,1,1,1,1,1,1,1,1,1,1,1,1,1,1,0
0,1,0,0,0,0,0,0,0,2,0,0,2,2,6,0,0,0,0,0,0,1,0
0,1,0,0,0,0,0,0,0,2,0,0,2,2,6,0,0,0,0,0,0,1,0
0,1,0,0,0,0,0,0,0,2,0,0,0,2,5,0,0,0,0,0,0,1,0
0,1,0,0,0,0,0,0,0,2,0,0,0,2,0,0,0,0,0,0,0,1,0
0,1,0,0,0,0,0,0,0,2,0,0,0,4,0,0,0,0,0,0,0,1,0
0,1,0,0,0,0,0,0,0,3,2,2,2,3,0,0,0,0,0,0,0,1,0
0,1,0,0,0,0,0,0,0,0,0,0,0,0,0,0,0,0,0,0,0,1,0
0,1,0,0,0,0,0,0,0,0,0,0,0,0,0,0,0,0,0,0,0,1,0
0,1,2,2,2,2,3,0,0,0,0,0,0,0,0,0,3,2,2,2,2,1,0
0,1,0,0,0,0,0,0,0,0,0,0,0,0,0,0,0,0,0,0,0,1,0
0,1,0,0,0,0,0,0,0,0,0,0,0,0,0,0,0,0,0,0,0,1,0
0,1,1,0,0,0,0,0,0,3,0,0,0,3,0,0,0,0,0,0,0,1,0
0,1,0,0,0,0,0,0,0,2,0,0,0,2,0,0,0,0,0,0,0,1,0
0,1,0,0,0,0,0,0,0,2,0,0,0,2,0,0,0,0,0,0,0,1,0
0,1,0,0,0,0,0,0,0,2,0,0,0,2,0,0,0,0,0,0,0,1,0
0,1,0,0,0,0,0,0,0,2,1,4,1,2,0,0,0,0,0,0,0,1,0
0,1,0,0,0,0,0,0,0,1,0,0,0,1,0,0,0,0,0,0,0,1,0
0,1,1,1,1,1,1,1,1,1,0,0,0,1,1,1,1,1,1,1,1,1,0
0,0,0,0,0,0,0,0,0,0,0,0,0,0,0,0,0,0,0,0,0,0,0
0,0,0,0,0,0,0,0,0,0,0,0,0,0,0,0,0,0,0,0,0,0,0
:endlayer
layer: 2
0,0,0,0,0,0,0,0,0,0,0,0,0,0,0,0,0,0,0,0,0,0,0
0,1,1,7,7,1,1,7,7,1,1,1,1,1,7,7,1,1,7,7,1,1,0
0,1,0,0,0,0,0,0,0,2,0,9,6,0,0,0,0,0,0,0,0,1,0
0,7,0,0,0,0,0,0,0,2,0,9,6,0,0,0,0,0,0,0,0,7,0
0,7,0,0,0,0,0,0,0,2,0,0,2,2,0,0,0,0,0,0,0,7,0
0,1,0,0,0,0,0,0,0,2,0,0,0,2,0,0,0,0,0,0,0,1,0
0,1,0,0,0,0,0,0,0,2,0,0,0,10,0,0,0,0,0,0,0,1,0
0,7,0,0,0,0,0,0,0,3,2,2,2,3,0,0,0,0,0,0,0,7,0
0,7,0,0,0,0,0,0,0,0,0,0,0,0,0,0,0,0,0,0,0,7,0
0,1,0,0,0,0,0,0,0,0,0,0,0,0,0,0,0,0,0,0,0,1,0
0,1,2,2,2,2,3,0,0,0,0,0,0,0,0,0,3,2,2,2,2,1,0
0,1,0,0,0,0,0,0,0,0,0,0,0,0,0,0,0,0,0,0,0,1,0
0,7,0,0,0,0,0,0,0,0,0,0,0,0,0,0,0,0,0,0,0,7,0
0,7,0,0,0,0,0,0,0,3,0,0,0,3,0,0,0,0,0,0,0,7,0
0,1,0,0,0,0,0,0,0,2,0,0,0,2,0,0,0,0,0,0,0,1,0
0,1,0,0,0,0,0,0,0,2,0,0,0,2,0,0,0,0,0,0,0,1,0
0,7,0,0,0,0,0,0,0,2,0,0,0,2,0,0,0,0,0,0,0,7,0
0,7,0,0,0,0,0,0,0,2,1,8,1,2,0,0,0,0,0,0,0,7,0
0,1,0,0,0,0,0,0,0,1,0,0,0,1,0,0,0,0,0,0,0,1,0
0,1,7,7,1,1,7,7,1,1,0,0,0,1,1,7,7,1,1,7,7,1,0
0,0,0,0,0,0,0,0,0,0,0,0,0,0,0,0,0,0,0,0,0,0,0
0,0,0,0,0,0,0,0,0,0,0,0,0,0,0,0,0,0,0,0,0,0,0
:endlayer
layer: 3
0,0,0,0,0,0,0,0,0,0,0,0,0,0,0,0,0,0,0,0,0,0,0
0,1,1,7,7,1,1,7,7,1,1,1,1,1,7,7,1,1,7,7,1,1,0
0,1,0,0,0,0,0,0,0,2,2,6,0,0,0,0,0,0,0,0,0,1,0
0,7,0,0,0,0,0,0,0,2,2,6,0,0,0,0,0,0,0,0,0,7,0
0,7,0,0,0,0,0,0,0,2,0,2,2,2,0,0,0,0,0,0,0,7,0
0,1,0,0,0,0,0,0,0,2,0,0,0,2,0,0,0,0,0,0,0,1,0
0,1,0,0,0,0,0,0,0,2,0,0,0,2,0,0,0,0,0,0,0,1,0
0,7,0,0,0,0,0,0,0,3,2,2,2,3,0,0,0,0,0,0,0,7,0
0,7,0,0,0,0,0,0,0,0,0,0,0,0,0,0,0,0,0,0,0,7,0
0,1,0,0,0,0,0,0,0,0,0,0,0,0,0,0,0,0,0,0,0,1,0
0,1,2,2,2,2,3,0,0,0,0,0,0,0,0,0,3,2,2,2,2,1,0
0,1,0,0,0,0,0,0,0,0,0,0,0,0,0,0,0,0,0,0,0,1,0
0,7,0,0,0,0,0,0,0,0,0,0,0,0,0,0,0,0,0,0,0,7,0
0,7,0,0,0,0,0,0,0,3,0,0,0,3,0,0,0,0,0,0,0,7,0
0,1,0,0,0,0,0,0,0,2,0,0,0,2,0,0,0,0,0,0,0,1,0
0,1,0,0,0,0,0,0,0,2,0,0,0,2,0,0,0,0,0,0,0,1,0
0,7,0,0,0,0,0,0,0,2,0,0,0,2,0,0,0,0,0,0,0,7,0
0,7,0,0,0,0,0,0,0,2,1,1,1,2,0,0,0,0,0,0,0,7,0
0,1,0,0,0,0,0,0,0,1,11,12,11,1,0,0,0,0,0,0,0,1,0
0,1,7,7,1,1,7,7,1,1,0,0,0,1,1,7,7,1,1,7,7,1,0
0,0,0,0,0,0,0,0,0,0,0,0,0,0,0,0,0,0,0,0,0,0,0
0,0,0,0,0,0,0,0,0,0,0,0,0,0,0,0,0,0,0,0,0,0,0
:endlayer
layer: 4
0,0,0,0,0,0,0,0,0,0,0,0,0,0,0,0,0,0,0,0,0,0,0
0,1,1,1,1,1,1,1,1,1,1,1,1,1,1,1,1,1,1,1,1,1,0
0,1,0,0,0,0,14,0,0,2,6,0,0,0,0,0,14,0,0,0,0,1,0
0,1,0,0,0,0,14,0,0,2,6,0,0,0,0,0,14,0,0,0,0,1,0
0,1,0,0,0,0,14,0,0,2,2,2,2,2,0,0,14,0,0,0,0,1,0
0,1,0,0,0,0,14,0,0,2,0,0,0,2,0,0,14,0,0,0,0,1,0
0,1,0,0,0,0,14,0,0,2,0,0,0,2,0,0,14,0,0,0,0,1,0
0,1,0,0,13,13,13,13,13,14,13,13,13,13,13,13,13,13,13,13,13,1,0
0,1,0,0,0,0,14,0,0,14,0,0,0,14,0,0,14,0,0,0,0,1,0
0,1,0,0,0,0,14,0,0,14,0,0,0,14,0,0,14,0,0,0,0,1,0
0,1,2,2,2,2,13,13,13,13,13,13,13,13,13,13,2,2,2,2,2,1,0
0,1,0,0,0,0,14,0,0,14,0,0,0,14,0,0,14,2,2,2,2,1,0
0,1,0,0,0,0,14,0,0,14,0,0,0,14,0,0,14,0,0,0,0,1,0
0,1,13,13,13,13,13,13,13,14,13,13,13,14,13,13,13,13,13,13,13,1,0
0,1,0,0,0,0,14,0,0,2,0,0,0,2,0,0,14,0,0,0,0,1,0
0,1,0,0,0,0,14,0,0,2,0,0,0,2,0,0,14,0,0,0,0,1,0
0,1,0,0,0,0,14,0,0,2,0,0,0,2,0,0,14,0,0,0,0,1,0
0,1,0,0,0,0,14,0,0,2,1,1,1,2,0,0,14,0,0,0,0,1,0
0,1,0,0,0,0,14,0,0,1,1,1,1,1,0,0,14,0,0,0,0,1,0
0,1,1,1,1,1,1,1,1,1,15,11,16,1,1,1,1,1,1,1,1,1,0
0,0,0,0,0,0,0,0,0,0,0,0,0,0,0,0,0,0,0,0,0,0,0
0,0,0,0,0,0,0,0,0,0,0,0,0,0,0,0,0,0,0,0,0,0,0
:endlayer
layer: 5
0,0,0,0,0,0,0,0,0,0,0,0,0,0,0,0,0,0,0,0,0,0,0
0,1,1,1,1,1,1,1,1,1,1,1,1,1,1,1,1,1,1,1,1,1,0
0,1,1,1,1,1,1,1,1,6,0,0,0,0,1,1,1,1,1,1,1,1,0
0,1,1,1,1,1,1,1,1,6,0,0,0,0,1,1,1,1,1,1,1,1,0
0,1,1,1,1,1,1,1,1,1,1,1,1,1,1,1,1,1,1,1,1,1,0
0,1,1,1,1,1,1,1,1,1,1,1,1,1,1,1,1,1,1,1,1,1,0
0,1,1,1,1,1,1,1,1,1,1,1,1,1,1,1,1,1,1,1,1,1,0
0,1,1,1,1,1,1,1,1,1,1,1,1,1,1,1,1,1,1,1,1,1,0
0,1,1,1,1,1,1,1,1,1,1,1,1,1,1,1,1,1,1,1,1,1,0
0,1,1,1,1,1,1,1,1,1,1,1,1,1,1,1,1,1,1,1,1,1,0
0,1,1,1,1,1,1,1,1,1,1,1,1,1,1,1,1,1,1,1,1,1,0
0,1,1,1,1,1,1,1,1,1,1,1,1,1,1,1,1,1,1,1,1,1,0
0,1,1,1,1,1,1,1,1,1,1,1,1,1,1,1,1,1,1,1,1,1,0
0,1,1,1,1,1,1,1,1,1,1,1,1,1,1,1,1,1,1,1,1,1,0
0,1,1,1,1,1,1,1,1,1,1,1,1,1,1,1,1,1,1,1,1,1,0
0,1,1,1,1,1,1,1,1,1,1,1,1,1,1,1,1,1,1,1,1,1,0
0,1,1,1,1,1,1,1,1,1,1,1,1,1,1,1,1,1,1,1,1,1,0
0,1,1,1,1,1,1,1,1,1,1,1,1,1,1,1,1,1,1,1,1,1,0
0,1,1,1,1,1,1,1,1,1,1,1,1,1,1,1,1,1,1,1,1,1,0
0,1,1,1,1,1,1,1,1,1,1,1,1,1,1,1,1,1,1,1,1,1,0
0,0,0,0,0,0,0,0,0,0,0,0,0,0,0,0,0,0,0,0,0,0,0
0,0,0,0,0,0,0,0,0,0,0,0,0,0,0,0,0,0,0,0,0,0,0
:endlayer
layer: 6
0,0,0,0,0,0,0,0,0,0,0,0,0,0,0,0,0,0,0,0,0,0,0
0,17,18,18,1,1,1,1,1,1,1,1,1,1,1,1,1,1,1,18,18,17,0
0,18,0,0,1,0,0,0,0,0,0,0,0,0,18,0,0,0,1,0,0,18,0
0,18,0,0,1,0,0,0,0,0,0,0,0,0,18,0,0,0,1,0,0,18,0
0,18,0,0,1,0,0,0,18,18,18,18,18,18,18,0,0,0,1,0,0,18,0
0,18,0,0,1,0,0,0,0,0,0,0,0,0,0,0,0,0,1,0,0,18,0
0,18,0,0,1,20,20,20,0,0,0,0,0,0,0,0,0,0,1,0,0,18,0
0,18,0,0,1,2,2,6,0,0,0,0,0,0,0,0,0,0,1,0,0,18,0
0,18,0,0,1,2,2,6,0,0,0,0,0,0,0,0,0,0,1,0,0,18,0
0,18,0,0,1,19,19,0,0,0,0,0,0,0,0,0,0,0,1,0,0,18,0
0,17,0,0,1,0,0,0,0,0,0,0,0,0,0,0,0,0,1,0,0,17,0
0,18,0,0,1,0,0,0,0,0,0,0,0,0,0,0,0,0,1,0,0,18,0
0,18,0,0,1,0,0,0,0,0,0,0,0,0,0,0,0,0,1,0,0,18,0
0,18,0,0,1,0,0,0,0,0,0,0,0,0,0,0,0,0,1,0,0,18,0
0,18,0,0,1,0,0,0,0,0,0,0,0,0,0,0,0,0,1,0,0,18,0
0,18,0,0,1,0,0,0,0,0,0,0,0,0,0,0,0,0,1,0,0,18,0
0,18,0,0,1,1,1,1,1,1,1,4,1,1,1,1,1,1,1,0,0,18,0
0,18,0,0,0,0,0,0,0,0,0,0,0,0,0,0,0,0,0,0,0,18,0
0,18,0,0,0,0,0,0,0,0,0,0,0,0,0,0,0,0,0,0,0,18,0
0,17,18,18,18,18,18,18,18,17,18,18,18,17,18,18,18,18,18,18,18,17,0
0,0,0,0,0,0,0,0,0,0,0,0,0,0,0,0,0,0,0,0,0,0,0
0,0,0,0,0,0,0,0,0,0,0,0,0,0,0,0,0,0,0,0,0,0,0
:endlayer
layer: 7
0,0,0,0,0,0,0,0,0,0,0,0,0,0,0,0,0,0,0,0,0,0,0
0,21,0,0,1,1,7,7,1,1,7,7,7,1,1,7,7,1,1,0,0,21,0
0,0,0,0,1,0,0,0,0,0,0,0,0,0,0,0,0,0,1,0,0,0,0
0,0,0,0,7,0,0,0,0,0,0,0,0,0,0,0,0,0,7,0,0,0,0
0,0,0,0,7,0,0,0,0,0,0,0,0,0,0,0,0,0,7,0,0,0,0
0,0,0,0,7,0,0,0,0,0,0,0,0,0,0,0,0,0,7,0,0,0,0
0,0,0,0,1,0,0,0,0,0,0,0,0,0,0,0,0,0,1,0,0,0,0
0,0,0,0,1,0,0,0,0,0,0,0,0,0,0,0,0,0,1,0,0,0,0
0,0,0,0,1,0,0,0,0,0,0,0,0,0,0,0,0,0,1,0,0,0,0
0,0,0,0,1,20,20,0,0,0,0,0,0,0,0,0,0,0,1,0,0,0,0
0,21,0,0,1,19,19,0,0,0,0,0,0,0,0,0,0,0,1,0,0,21,0
0,0,0,0,1,0,0,0,0,0,0,0,0,0,0,0,0,0,1,0,0,0,0
0,0,0,0,7,0,0,0,0,0,0,0,0,0,0,0,0,0,7,0,0,0,0
0,0,0,0,7,0,0,0,0,0,0,0,0,0,0,0,0,0,7,0,0,0,0
0,0,0,0,7,0,0,0,0,0,0,0,0,0,0,0,0,0,7,0,0,0,0
0,0,0,0,1,0,0,0,0,0,0,0,0,0,0,0,0,0,1,0,0,0,0
0,0,0,0,1,1,7,7,7,1,1,22,1,1,7,7,7,1,1,0,0,0,0
0,0,0,0,0,0,0,0,0,0,0,0,0,0,0,0,0,0,0,0,0,0,0
0,0,0,0,0,0,0,0,0,0,0,0,0,0,0,0,0,0,0,0,0,0,0
0,21,0,0,0,0,0,0,0,21,0,0,0,21,0,0,0,0,0,0,0,21,0
0,0,0,0,0,0,0,0,0,0,0,0,0,0,0,0,0,0,0,0,0,0,0
0,0,0,0,0,0,0,0,0,0,0,0,0,0,0,0,0,0,0,0,0,0,0
:endlayer
layer: 8
0,0,0,0,0,0,0,0,0,0,0,0,0,0,0,0,0,0,0,0,0,0,0
0,21,0,0,1,1,7,7,1,1,7,7,7,1,1,7,7,1,1,0,0,21,0
0,0,0,0,1,0,0,0,0,0,0,0,0,0,0,0,0,0,1,0,0,0,0
0,0,0,0,7,0,0,0,0,0,0,0,0,0,0,0,0,0,7,0,0,0,0
0,0,0,0,7,0,0,0,0,0,0,0,0,0,0,0,0,0,7,0,0,0,0
0,0,0,0,7,0,0,0,0,0,0,0,0,0,0,0,0,0,7,0,0,0,0
0,0,0,0,1,0,0,0,0,0,0,0,0,0,0,0,0,0,1,0,0,0,0
0,0,0,0,1,0,0,0,0,0,0,0,0,0,0,0,0,0,1,0,0,0,0
0,0,0,0,1,0,0,0,0,0,0,0,0,0,0,0,0,0,1,0,0,0,0
0,0,0,0,1,0,0,0,0,0,0,0,0,0,0,0,0,0,1,0,0,0,0
0,21,0,0,1,20,20,0,0,0,0,0,0,0,0,0,0,0,1,0,0,21,0
0,0,0,0,1,19,19,0,0,0,0,0,0,0,0,0,0,0,1,0,0,0,0
0,0,0,0,7,0,0,0,0,0,0,0,0,0,0,0,0,0,7,0,0,0,0
0,0,0,0,7,0,0,0,0,0,0,0,0,0,0,0,0,0,7,0,0,0,0
0,0,0,0,7,0,0,0,0,0,0,0,0,0,0,0,0,0,7,0,0,0,0
0,0,0,0,1,0,0,0,0,0,0,0,0,0,0,0,0,0,1,0,0,0,0
0,0,0,0,1,1,7,7,7,1,1,1,1,1,7,7,7,1,1,0,0,0,0
0,0,0,0,0,0,0,0,0,0,0,0,0,0,0,0,0,0,0,0,0,0,0
0,0,0,0,0,0,0,0,0,0,0,0,0,0,0,0,0,0,0,0,0,0,0
0,21,0,0,0,0,0,0,0,21,0,0,0,21,0,0,0,0,0,0,0,21,0
0,0,0,0,0,0,0,0,0,0,0,0,0,0,0,0,0,0,0,0,0,0,0
0,0,0,0,0,0,0,0,0,0,0,0,0,0,0,0,0,0,0,0,0,0,0
:endlayer
layer: 9
0,0,0,0,0,0,0,0,0,0,0,0,0,0,0,0,0,0,0,0,0,0,0
0,21,0,0,1,1,1,1,1,1,1,1,1,1,1,1,1,1,1,0,0,21,0
0,0,0,0,1,0,0,0,0,0,0,0,0,0,0,0,0,0,1,0,0,0,0
0,0,0,0,1,0,0,0,0,0,0,0,0,0,0,0,0,0,1,0,0,0,0
0,0,0,0,1,0,0,0,0,0,0,0,0,0,0,0,0,0,1,0,0,0,0
0,0,0,0,1,0,0,0,0,0,0,0,0,0,0,0,0,0,1,0,0,0,0
0,0,0,0,1,0,0,0,0,0,0,0,0,0,0,0,0,0,1,0,0,0,0
0,0,0,0,1,0,0,0,0,0,0,0,0,0,0,0,0,0,1,0,0,0,0
0,0,0,0,1,0,0,0,0,0,0,0,0,0,0,0,0,0,1,0,0,0,0
0,0,0,0,1,0,0,0,0,0,0,0,0,0,0,0,0,0,1,0,0,0,0
0,21,0,0,1,0,0,0,0,0,0,0,0,0,0,0,0,0,1,0,0,21,0
0,0,0,0,1,20,20,0,0,0,0,0,0,0,0,0,0,0,1,0,0,0,0
0,0,0,0,1,19,19,0,0,0,0,0,0,0,0,0,0,0,1,0,0,0,0
0,0,0,0,1,0,0,0,0,0,0,0,0,0,0,0,0,0,1,0,0,0,0
0,0,0,0,1,0,0,0,0,0,0,0,0,0,0,0,0,0,1,0,0,0,0
0,0,0,0,1,0,0,0,0,0,0,0,0,0,0,0,0,0,1,0,0,0,0
0,0,0,0,1,1,1,1,1,1,1,1,1,1,1,1,1,1,1,0,0,0,0
0,0,0,0,0,0,0,0,0,0,0,0,0,0,0,0,0,0,0,0,0,0,0
0,0,0,0,0,0,0,0,0,0,0,0,0,0,0,0,0,0,0,0,0,0,0
0,21,0,0,0,0,0,0,0,21,0,0,0,21,0,0,0,0,0,0,0,21,0
0,0,0,0,0,0,0,0,0,0,0,0,0,0,0,0,0,0,0,0,0,0,0
0,0,0,0,0,0,0,0,0,0,0,0,0,0,0,0,0,0,0,0,0,0,0
:endlayer
layer: 10
20,20,20,20,20,20,20,20,20,20,20,20,20,20,20,20,20,20,20,20,20,20,20
23,2,2,2,2,2,2,2,2,2,2,2,2,2,2,2,2,2,2,2,2,2,6
23,2,2,2,2,2,2,2,2,2,2,2,2,2,2,2,2,2,2,2,2,2,6
23,2,2,2,2,2,2,2,2,2,2,2,2,2,2,2,2,2,2,2,2,2,6
23,2,2,2,2,2,2,2,2,2,2,2,2,2,2,2,2,2,2,2,2,2,6
23,2,2,2,2,2,2,2,2,2,2,2,2,2,2,2,2,2,2,2,2,2,6
23,2,2,2,2,2,2,2,2,2,2,2,2,2,2,2,2,2,2,2,2,2,6
23,2,2,2,2,0,0,2,2,2,2,2,2,2,2,2,2,2,2,2,2,2,6
23,2,2,2,2,0,0,2,2,2,2,2,2,2,2,2,2,2,2,2,2,2,6
23,2,2,2,2,0,0,2,2,2,2,2,2,2,2,2,2,2,2,2,2,2,6
23,2,2,2,2,0,0,2,2,2,2,2,2,2,2,2,2,2,2,2,2,2,6
23,2,2,2,2,0,0,2,2,2,2,2,2,2,2,2,2,2,2,2,2,2,6
23,2,2,2,2,20,20,2,2,2,2,2,2,2,2,2,2,2,2,2,2,2,6
23,2,2,2,2,2,2,2,2,2,2,2,2,2,2,2,2,2,2,2,2,2,6
23,2,2,2,2,2,2,2,2,2,2,2,2,2,2,2,2,2,2,2,2,2,6
23,2,2,2,2,2,2,2,2,2,2,2,2,2,2,2,2,2,2,2,2,2,6
23,2,2,2,2,2,2,2,2,2,2,2,2,2,2,2,2,2,2,2,2,2,6
23,2,2,2,2,2,2,2,2,2,2,2,2,2,2,2,2,2,2,2,2,2,6
23,2,2,2,2,2,2,2,2,2,2,2,2,2,2,2,2,2,2,2,2,2,6
23,2,2,2,2,2,2,2,2,2,2,2,2,2,2,2,2,2,2,2,2,2,6
5,5,5,5,5,5,5,5,5,5,5,5,5,5,5,5,5,5,5,5,5,5,6
0,0,0,0,0,0,0,0,0,0,0,0,0,0,0,0,0,0,0,0,0,0,0
:endlayer
layer: 11
0,0,0,0,0,0,0,0,0,0,0,0,0,0,0,0,0,0,0,0,0,0,0
0,23,20,20,20,20,20,20,20,20,20,20,20,20,20,20,20,20,20,20,20,20,0
0,23,2,2,2,2,2,2,2,2,2,2,2,2,2,2,2,2,2,2,2,6,0
0,23,2,2,2,2,2,2,2,2,2,2,2,2,2,2,2,2,2,2,2,6,0
0,23,2,2,0,0,0,0,0,0,0,0,0,0,0,0,0,0,0,2,2,6,0
0,23,2,2,0,0,0,0,0,0,0,0,0,0,0,0,0,0,0,2,2,6,0
0,23,2,2,18,18,18,18,0,0,0,0,0,0,0,0,0,0,0,2,2,6,0
0,23,2,2,0,0,0,18,0,0,0,0,0,0,0,0,0,0,0,2,2,6,0
0,23,2,0,0,0,0,18,0,0,0,0,0,0,0,0,0,0,0,0,2,6,0
0,23,2,0,0,0,0,18,0,0,0,0,0,0,0,0,0,0,0,0,2,6,0
0,23,2,0,0,0,0,18,0,0,0,0,0,0,0,18,0,0,0,0,2,6,0
0,23,2,0,0,0,0,18,0,0,0,0,0,0,0,0,0,0,0,0,2,6,0
0,23,2,0,0,0,0,18,0,0,0,0,0,0,0,0,0,0,0,0,2,6,0
0,23,2,2,0,0,0,18,0,0,0,0,0,0,0,0,0,0,0,2,2,6,0
0,23,2,2,0,0,0,0,0,0,0,0,0,0,0,0,0,0,0,2,2,6,0
0,23,2,2,0,0,0,0,0,0,0,0,0,0,0,0,0,0,0,2,2,6,0
0,23,2,2,0,0,0,0,0,0,0,0,0,0,0,0,0,0,0,2,2,6,0
0,23,2,2,2,2,2,2,2,24,25,25,25,26,2,2,2,2,2,2,2,6,0
0,23,2,2,2,2,2,2,2,2,2,2,2,2,2,2,2,2,2,2,2,6,0
0,5,5,5,5,5,5,5,5,5,5,5,5,5,5,5,5,5,5,5,5,6,0
0,0,0,0,0,0,0,0,0,0,0,0,0,0,0,0,0,0,0,0,0,0,0
0,0,0,0,0,0,0,0,0,0,0,0,0,0,0,0,0,0,0,0,0,0,0
:endlayer
layer: 12
0,0,0,0,0,0,0,0,0,0,0,0,0,0,0,0,0,0,0,0,0,0,0
0,0,0,0,0,0,0,0,0,0,0,0,0,0,0,0,0,0,0,0,0,0,0
0,0,20,20,20,20,20,20,20,20,20,20,20,20,20,20,20,20,20,20,6,0,0
0,0,23,2,2,2,2,2,2,2,2,2,2,2,2,2,2,2,2,2,6,0,0
0,0,23,2,0,0,0,0,0,0,0,0,0,0,0,0,0,0,0,2,6,0,0
0,0,23,2,0,0,0,0,0,0,0,0,0,0,0,0,0,0,0,2,6,0,0
0,0,23,2,0,0,0,0,0,0,0,0,0,0,0,0,0,0,0,2,6,0,0
0,0,23,2,0,0,0,0,0,0,0,0,0,0,0,0,0,0,0,2,6,0,0
0,0,2,0,0,0,0,0,0,0,0,0,0,0,0,0,0,0,0,0,2,0,0
0,0,7,0,0,0,0,0,0,0,0,0,0,0,0,0,0,0,0,0,7,0,0
0,0,7,0,0,0,0,0,0,0,0,0,0,0,0,0,0,0,0,0,7,0,0
0,0,7,0,0,0,0,0,0,0,0,0,0,0,0,0,0,0,0,0,7,0,0
0,0,2,0,0,0,0,0,0,0,0,0,0,0,0,0,0,0,0,0,2,0,0
0,0,23,2,0,0,0,0,0,0,0,0,0,0,0,0,0,0,0,2,6,0,0
0,0,23,2,0,0,0,0,0,0,0,0,0,0,0,0,0,0,0,2,6,0,0
0,0,23,2,0,0,0,0,0,0,0,0,0,0,0,0,0,0,0,2,6,0,0
0,0,23,2,0,0,0,0,0,0,0,0,0,0,0,0,0,0,0,2,6,0,0
0,0,23,2,2,2,2,2,2,0,0,0,0,0,2,2,2,2,2,2,6,0,0
0,0,23,5,5,5,5,5,5,2,7,7,7,2,5,5,5,5,5,5,5,0,0
0,0,0,0,0,0,0,0,0,0,0,0,0,0,0,0,0,0,0,0,0,0,0
0,0,0,0,0,0,0,0,0,0,0,0,0,0,0,0,0,0,0,0,0,0,0
0,0,0,0,0,0,0,0,0,0,0,0,0,0,0,0,0,0,0,0,0,0,0
:endlayer
layer: 13
0,0,0,0,0,0,0,0,0,0,0,0,0,0,0,0,0,0,0,0,0,0,0
0,0,0,0,0,0,0,0,0,0,0,0,0,0,0,0,0,0,0,0,0,0,0
0,0,0,0,0,0,0,0,0,0,0,0,0,0,0,0,0,0,0,0,0,0,0
0,0,0,23,20,20,20,20,20,20,20,20,20,20,20,20,20,20,20,20,0,0,0
0,0,0,23,19,19,19,19,19,19,19,19,19,19,19,19,19,19,9,6,0,0,0
0,0,0,23,28,0,0,0,0,0,0,0,0,0,0,0,0,0,9,6,0,0,0
0,0,0,23,28,0,0,0,0,0,0,0,0,0,0,0,0,0,9,6,0,0,0
0,0,0,23,28,0,0,0,0,0,0,0,0,0,0,0,0,0,9,6,0,0,0
0,0,2,19,19,0,0,0,0,0,0,0,0,0,0,0,0,0,19,19,2,0,0
0,0,7,0,0,0,0,0,0,0,0,0,0,0,0,0,0,0,0,0,7,0,0
0,0,7,0,0,0,0,0,0,0,0,0,0,0,0,0,0,0,0,0,7,0,0
0,0,7,0,0,0,0,0,0,0,0,0,0,0,0,0,0,0,0,0,7,0,0
0,0,2,27,28,0,0,0,0,0,0,0,0,0,0,0,0,0,27,27,2,0,0
0,0,0,23,28,0,0,0,0,0,0,0,0,0,0,0,0,0,9,6,0,0,0
0,0,0,23,28,0,0,0,0,0,0,0,0,0,0,0,0,0,9,6,0,0,0
0,0,0,23,28,0,0,0,0,0,0,0,0,0,0,0,0,0,9,6,0,0,0
0,0,0,23,27,27,27,27,27,28,0,0,0,9,27,27,27,27,9,6,0,0,0
0,0,0,5,5,5,5,5,5,28,0,0,0,9,5,5,5,5,5,6,0,0,0
0,0,0,0,0,0,0,0,0,2,7,7,7,2,0,0,0,0,0,0,0,0,0
0,0,0,0,0,0,0,0,0,0,0,0,0,0,0,0,0,0,0,0,0,0,0
0,0,0,0,0,0,0,0,0,0,0,0,0,0,0,0,0,0,0,0,0,0,0
0,0,0,0,0,0,0,0,0,0,0,0,0,0,0,0,0,0,0,0,0,0,0
:endlayer
layer: 14
0,0,0,0,0,0,0,0,0,0,0,0,0,0,0,0,0,0,0,0,0,0,0
0,0,0,0,0,0,0,0,0,0,0,0,0,0,0,0,0,0,0,0,0,0,0
0,0,0,0,0,0,0,0,0,0,0,0,0,0,0,0,0,0,0,0,0,0,0
0,0,0,0,0,0,0,0,0,0,0,0,0,0,0,0,0,0,0,0,0,0,0
0,0,0,0,23,20,20,20,20,20,20,20,20,20,20,20,20,20,20,0,0,0,0
0,0,0,0,23,2,2,2,2,2,2,2,2,2,2,2,2,2,6,0,0,0,0
0,0,0,0,23,2,0,0,0,0,0,0,0,0,0,0,0,2,6,0,0,0,0
0,0,0,0,23,2,0,0,0,0,0,0,0,0,0,0,0,2,6,0,0,0,0
0,0,20,20,20,2,0,0,0,0,0,0,0,0,0,0,0,2,20,20,6,0,0
0,0,23,2,2,2,0,0,0,0,0,0,0,0,0,0,0,2,2,2,6,0,0
0,0,23,2,2,2,0,0,0,0,0,0,0,0,0,0,0,2,2,2,6,0,0
0,0,23,2,2,2,0,0,0,0,0,0,0,0,0,0,0,2,2,2,6,0,0
0,0,23,5,5,2,0,0,0,0,0,0,0,0,0,0,0,2,5,5,6,0,0
0,0,0,0,23,2,0,0,0,0,0,0,0,0,0,0,0,2,6,0,0,0,0
0,0,0,0,23,2,0,0,0,0,0,0,0,0,0,0,0,2,6,0,0,0,0
0,0,0,0,23,2,2,2,2,2,2,2,2,2,2,2,2,2,6,0,0,0,0
0,0,0,0,5,5,5,5,5,23,2,2,2,6,5,5,5,5,6,0,0,0,0
0,0,0,0,0,0,0,0,0,23,2,2,2,6,0,0,0,0,0,0,0,0,0
0,0,0,0,0,0,0,0,0,23,5,5,5,5,0,0,0,0,0,0,0,0,0
0,0,0,0,0,0,0,0,0,0,0,0,0,0,0,0,0,0,0,0,0,0,0
0,0,0,0,0,0,0,0,0,0,0,0,0,0,0,0,0,0,0,0,0,0,0
0,0,0,0,0,0,0,0,0,0,0,0,0,0,0,0,0,0,0,0,0,0,0
:endlayer
layer: 15
0,0,0,0,0,0,0,0,0,0,0,0,0,0,0,0,0,0,0,0,0,0,0
0,0,0,0,0,0,0,0,0,0,0,0,0,0,0,0,0,0,0,0,0,0,0
0,0,0,0,0,0,0,0,0,0,0,0,0,0,0,0,0,0,0,0,0,0,0
0,0,0,0,0,0,0,0,0,0,0,0,0,0,0,0,0,0,0,0,0,0,0
0,0,0,0,0,0,0,0,0,0,0,0,0,0,0,0,0,0,0,0,0,0,0
0,0,0,0,0,20,20,20,20,20,20,20,20,20,20,20,20,6,0,0,0,0,0
0,0,0,0,0,23,2,2,2,2,2,2,2,2,2,2,2,6,0,0,0,0,0
0,0,0,0,0,23,2,0,0,0,0,0,0,0,0,0,2,6,0,0,0,0,0
0,0,0,0,0,23,2,0,0,0,0,0,0,0,0,0,2,6,0,0,0,0,0
0,0,0,20,20,20,2,0,0,0,0,0,0,0,0,0,2,20,20,20,0,0,0
0,0,0,23,2,2,2,0,0,0,0,0,0,0,0,0,2,2,2,6,0,0,0
0,0,0,23,5,5,2,0,0,0,0,0,0,0,0,0,2,5,5,5,0,0,0
0,0,0,0,0,23,2,0,0,0,0,0,0,0,0,0,2,6,0,0,0,0,0
0,0,0,0,0,23,2,0,0,0,0,0,0,0,0,0,2,6,0,0,0,0,0
0,0,0,0,0,23,2,2,2,2,2,2,2,2,2,2,2,6,0,0,0,0,0
0,0,0,0,0,23,5,5,5,5,23,2,6,5,5,5,5,6,0,0,0,0,0
0,0,0,0,0,0,0,0,0,0,23,2,6,0,0,0,0,0,0,0,0,0,0
0,0,0,0,0,0,0,0,0,0,23,5,5,0,0,0,0,0,0,0,0,0,0
0,0,0,0,0,0,0,0,0,0,0,0,0,0,0,0,0,0,0,0,0,0,0
0,0,0,0,0,0,0,0,0,0,0,0,0,0,0,0,0,0,0,0,0,0,0
0,0,0,0,0,0,0,0,0,0,0,0,0,0,0,0,0,0,0,0,0,0,0
0,0,0,0,0,0,0,0,0,0,0,0,0,0,0,0,0,0,0,0,0,0,0
:endlayer
layer: 16
0,0,0,0,0,0,0,0,0,0,0,0,0,0,0,0,0,0,0,0,0,0,0
0,0,0,0,0,0,0,0,0,0,0,0,0,0,0,0,0,0,0,0,0,0,0
0,0,0,0,0,0,0,0,0,0,0,0,0,0,0,0,0,0,0,0,0,0,0
0,0,0,0,0,0,0,0,0,0,0,0,0,0,0,0,0,0,0,0,0,0,0
0,0,0,0,0,0,0,0,0,0,0,0,0,0,0,0,0,0,0,0,0,0,0
0,0,0,0,0,0,0,0,0,0,0,0,0,0,0,0,0,0,0,0,0,0,0
0,0,0,0,0,0,20,20,20,20,20,20,20,20,20,20,6,0,0,0,0,0,0
0,0,0,0,0,0,23,2,2,2,2,2,2,2,2,2,6,0,0,0,0,0,0
0,0,0,0,0,0,23,2,2,2,2,2,2,2,2,2,6,0,0,0,0,0,0
0,0,0,0,0,0,23,2,2,2,2,2,2,2,2,2,6,0,0,0,0,0,0
0,0,0,0,29,29,23,2,2,2,2,2,2,2,2,2,6,29,29,0,0,0,0
0,0,0,0,0,0,23,2,2,2,2,2,2,2,2,2,6,0,0,0,0,0,0
0,0,0,0,0,0,23,2,2,2,2,2,2,2,2,2,6,0,0,0,0,0,0
0,0,0,0,0,0,23,2,2,2,2,2,2,2,2,2,6,0,0,0,0,0,0
0,0,0,0,0,0,23,5,5,5,5,5,5,5,5,5,5,0,0,0,0,0,0
0,0,0,0,0,0,0,0,0,0,0,29,0,0,0,0,0,0,0,0,0,0,0
0,0,0,0,0,0,0,0,0,0,0,29,0,0,0,0,0,0,0,0,0,0,0
0,0,0,0,0,0,0,0,0,0,0,0,0,0,0,0,0,0,0,0,0,0,0
0,0,0,0,0,0,0,0,0,0,0,0,0,0,0,0,0,0,0,0,0,0,0
0,0,0,0,0,0,0,0,0,0,0,0,0,0,0,0,0,0,0,0,0,0,0
0,0,0,0,0,0,0,0,0,0,0,0,0,0,0,0,0,0,0,0,0,0,0
0,0,0,0,0,0,0,0,0,0,0,0,0,0,0,0,0,0,0,0,0,0,0
:endlayer
layer: 17
0,0,0,0,0,0,0,0,0,0,0,0,0,0,0,0,0,0,0,0,0,0,0
0,0,0,0,0,0,0,0,0,0,0,0,0,0,0,0,0,0,0,0,0,0,0
0,0,0,0,0,0,0,0,0,0,0,0,0,0,0,0,0,0,0,0,0,0,0
0,0,0,0,0,0,0,0,0,0,0,0,0,0,0,0,0,0,0,0,0,0,0
0,0,0,0,0,0,0,0,0,0,0,0,0,0,0,0,0,0,0,0,0,0,0
0,0,0,0,0,0,0,0,0,0,0,0,0,0,0,0,0,0,0,0,0,0,0
0,0,0,0,0,0,0,0,0,0,0,0,0,0,0,0,0,0,0,0,0,0,0
0,0,0,0,0,0,0,0,0,0,0,0,0,0,0,0,0,0,0,0,0,0,0
0,0,0,0,0,0,0,0,0,0,0,0,0,0,0,0,0,0,0,0,0,0,0
0,0,0,0,0,0,0,0,0,0,0,0,0,0,0,0,0,0,0,0,0,0,0
0,0,0,0,0,0,0,0,0,0,0,0,0,0,0,0,0,0,0,0,0,0,0
0,0,0,0,0,0,0,0,0,0,0,0,0,0,0,0,0,0,0,0,0,0,0
0,0,0,0,0,0,0,0,0,0,0,0,0,0,0,0,0,0,0,0,0,0,0
0,0,0,0,0,0,0,0,0,0,0,0,0,0,0,0,0,0,0,0,0,0,0
0,0,0,0,0,0,0,0,0,0,0,0,0,0,0,0,0,0,0,0,0,0,0
0,0,0,0,0,0,0,0,0,0,0,0,0,0,0,0,0,0,0,0,0,0,0
0,0,0,0,0,0,0,0,0,0,0,0,0,0,0,0,0,0,0,0,0,0,0
0,0,0,0,0,0,0,0,0,0,0,0,0,0,0,0,0,0,0,0,0,0,0
0,0,0,0,0,0,0,0,0,0,0,0,0,0,0,0,0,0,0,0,0,0,0
0,0,0,0,0,0,0,0,0,0,0,0,0,0,0,0,0,0,0,0,0,0,0
0,0,0,0,0,0,0,0,0,0,0,0,0,0,0,0,0,0,0,0,0,0,0
0,0,0,0,0,0,0,0,0,0,0,0,0,0,0,0,0,0,0,0,0,0,0
:endlayer

#### RULES ####
rule:
plugin=vanillaBlocks
number=1
data:
JSON:{{"val":{"buildPass":{"val":"0","id":"pi"},"blockName":{"val":"minecraft:stonebrick","id":"ss"},"meta":{"val":"0","id":"pi"}},"id":"ct"}}
:enddata
:endrule

rule:
plugin=vanillaBlocks
number=2
data:
JSON:{{"val":{"buildPass":{"val":"0","id":"pi"},"blockName":{"val":"minecraft:planks","id":"ss"},"meta":{"val":"0","id":"pi"}},"id":"ct"}}
:enddata
:endrule

rule:
plugin=vanillaBlocks
number=3
data:
JSON:{{"val":{"buildPass":{"val":"0","id":"pi"},"blockName":{"val":"minecraft:log","id":"ss"},"meta":{"val":"0","id":"pi"}},"id":"ct"}}
:enddata
:endrule

rule:
plugin=vanillaDoors
number=4
data:
JSON:{{"val":{"buildPass":{"val":"2","id":"pi"},"blockName":{"val":"minecraft:wooden_door","id":"ss"},"meta":{"val":"7","id":"pi"},"sideFlag":{"val":"8","id":"pb"}},"id":"ct"}}
:enddata
:endrule

rule:
plugin=vanillaBlocks
number=5
data:
JSON:{{"val":{"buildPass":{"val":"0","id":"pi"},"blockName":{"val":"minecraft:oak_stairs","id":"ss"},"meta":{"val":"3","id":"pi"}},"id":"ct"}}
:enddata
:endrule

rule:
plugin=vanillaBlocks
number=6
data:
JSON:{{"val":{"buildPass":{"val":"0","id":"pi"},"blockName":{"val":"minecraft:oak_stairs","id":"ss"},"meta":{"val":"1","id":"pi"}},"id":"ct"}}
:enddata
:endrule

rule:
plugin=vanillaBlocks
number=7
data:
JSON:{{"val":{"buildPass":{"val":"0","id":"pi"},"blockName":{"val":"minecraft:stained_glass_pane","id":"ss"},"meta":{"val":"0","id":"pi"}},"id":"ct"}}
:enddata
:endrule

rule:
plugin=vanillaDoors
number=8
data:
JSON:{{"val":{"buildPass":{"val":"2","id":"pi"},"blockName":{"val":"minecraft:wooden_door","id":"ss"},"meta":{"val":"8","id":"pi"},"sideFlag":{"val":"0","id":"pb"}},"id":"ct"}}
:enddata
:endrule

rule:
plugin=vanillaBlocks
number=9
data:
JSON:{{"val":{"buildPass":{"val":"0","id":"pi"},"blockName":{"val":"minecraft:oak_stairs","id":"ss"},"meta":{"val":"4","id":"pi"}},"id":"ct"}}
:enddata
:endrule

rule:
plugin=vanillaDoors
number=10
data:
JSON:{{"val":{"buildPass":{"val":"2","id":"pi"},"blockName":{"val":"minecraft:wooden_door","id":"ss"},"meta":{"val":"8","id":"pi"},"sideFlag":{"val":"0","id":"pb"}},"id":"ct"}}
:enddata
:endrule

rule:
plugin=vanillaBlocks
number=11
data:
JSON:{{"val":{"buildPass":{"val":"0","id":"pi"},"blockName":{"val":"minecraft:stone_brick_stairs","id":"ss"},"meta":{"val":"7","id":"pi"}},"id":"ct"}}
:enddata
:endrule

rule:
plugin=vanillaBlocks
number=12
data:
JSON:{{"val":{"buildPass":{"val":"0","id":"pi"},"blockName":{"val":"minecraft:stone_slab","id":"ss"},"meta":{"val":"13","id":"pi"}},"id":"ct"}}
:enddata
:endrule

rule:
plugin=vanillaBlocks
number=13
data:
JSON:{{"val":{"buildPass":{"val":"0","id":"pi"},"blockName":{"val":"minecraft:log","id":"ss"},"meta":{"val":"4","id":"pi"}},"id":"ct"}}
:enddata
:endrule

rule:
plugin=vanillaBlocks
number=14
data:
JSON:{{"val":{"buildPass":{"val":"0","id":"pi"},"blockName":{"val":"minecraft:log","id":"ss"},"meta":{"val":"8","id":"pi"}},"id":"ct"}}
:enddata
:endrule

rule:
plugin=vanillaBlocks
number=15
data:
JSON:{{"val":{"buildPass":{"val":"0","id":"pi"},"blockName":{"val":"minecraft:stone_brick_stairs","id":"ss"},"meta":{"val":"5","id":"pi"}},"id":"ct"}}
:enddata
:endrule

rule:
plugin=vanillaBlocks
number=16
data:
JSON:{{"val":{"buildPass":{"val":"0","id":"pi"},"blockName":{"val":"minecraft:stone_brick_stairs","id":"ss"},"meta":{"val":"4","id":"pi"}},"id":"ct"}}
:enddata
:endrule

rule:
plugin=vanillaBlocks
number=17
data:
JSON:{{"val":{"buildPass":{"val":"0","id":"pi"},"blockName":{"val":"minecraft:cobblestone","id":"ss"},"meta":{"val":"0","id":"pi"}},"id":"ct"}}
:enddata
:endrule

rule:
plugin=vanillaBlocks
number=18
data:
JSON:{{"val":{"buildPass":{"val":"0","id":"pi"},"blockName":{"val":"minecraft:fence","id":"ss"},"meta":{"val":"0","id":"pi"}},"id":"ct"}}
:enddata
:endrule

rule:
plugin=vanillaBlocks
number=19
data:
JSON:{{"val":{"buildPass":{"val":"0","id":"pi"},"blockName":{"val":"minecraft:oak_stairs","id":"ss"},"meta":{"val":"7","id":"pi"}},"id":"ct"}}
:enddata
:endrule

rule:
plugin=vanillaBlocks
number=20
data:
JSON:{{"val":{"buildPass":{"val":"0","id":"pi"},"blockName":{"val":"minecraft:oak_stairs","id":"ss"},"meta":{"val":"2","id":"pi"}},"id":"ct"}}
:enddata
:endrule

rule:
plugin=vanillaBlocks
number=21
data:
JSON:{{"val":{"buildPass":{"val":"0","id":"pi"},"blockName":{"val":"minecraft:cobblestone_wall","id":"ss"},"meta":{"val":"0","id":"pi"}},"id":"ct"}}
:enddata
:endrule

rule:
plugin=vanillaDoors
number=22
data:
JSON:{{"val":{"buildPass":{"val":"2","id":"pi"},"blockName":{"val":"minecraft:wooden_door","id":"ss"},"meta":{"val":"8","id":"pi"},"sideFlag":{"val":"0","id":"pb"}},"id":"ct"}}
:enddata
:endrule

rule:
plugin=vanillaBlocks
number=23
data:
JSON:{{"val":{"buildPass":{"val":"0","id":"pi"},"blockName":{"val":"minecraft:oak_stairs","id":"ss"},"meta":{"val":"0","id":"pi"}},"id":"ct"}}
:enddata
:endrule

rule:
plugin=vanillaBlocks
number=24
data:
JSON:{{"val":{"buildPass":{"val":"0","id":"pi"},"blockName":{"val":"minecraft:spruce_stairs","id":"ss"},"meta":{"val":"5","id":"pi"}},"id":"ct"}}
:enddata
:endrule

rule:
plugin=vanillaBlocks
number=25
data:
JSON:{{"val":{"buildPass":{"val":"0","id":"pi"},"blockName":{"val":"minecraft:spruce_stairs","id":"ss"},"meta":{"val":"6","id":"pi"}},"id":"ct"}}
:enddata
:endrule

rule:
plugin=vanillaBlocks
number=26
data:
JSON:{{"val":{"buildPass":{"val":"0","id":"pi"},"blockName":{"val":"minecraft:spruce_stairs","id":"ss"},"meta":{"val":"4","id":"pi"}},"id":"ct"}}
:enddata
:endrule

rule:
plugin=vanillaBlocks
number=27
data:
JSON:{{"val":{"buildPass":{"val":"0","id":"pi"},"blockName":{"val":"minecraft:oak_stairs","id":"ss"},"meta":{"val":"6","id":"pi"}},"id":"ct"}}
:enddata
:endrule

rule:
plugin=vanillaBlocks
number=28
data:
JSON:{{"val":{"buildPass":{"val":"0","id":"pi"},"blockName":{"val":"minecraft:oak_stairs","id":"ss"},"meta":{"val":"5","id":"pi"}},"id":"ct"}}
:enddata
:endrule

rule:
plugin=vanillaBlocks
number=29
data:
JSON:{{"val":{"buildPass":{"val":"0","id":"pi"},"blockName":{"val":"minecraft:wooden_slab","id":"ss"},"meta":{"val":"0","id":"pi"}},"id":"ct"}}
:enddata
:endrule

#### ENTITIES ####
entity:
plugin=vanillaEntities
number=0
data:
position=19,11,9
JSON:{{"val":{"xOffset":{"val":"0.2788149","id":"pf"},"rotation":{"val":"-136.6604","id":"pf"},"mobID":{"val":"notenoughpets.Ocelot_NEP","id":"ss"},"zOffset":{"val":"0.73440087","id":"pf"}},"id":"ct"}}
:enddata
:endentity

