# Ancient Warfare Structure Template File
# Auto-generated structure template file. created on: 11/1/2024 at: 22:49:31
# Lines beginning with # denote comments

header:
version=2.1
name=Small_hbm_factory
size=25,8,42
offset=8,0,42
:endheader

#### VALIDATION ####
validation:
type=ground
survival=true
worldGenEnabled=false
unique=false
preserveBlocks=false
selectionWeight=0
clusterValue=0
minDuplicateDistance=0
dimensionWhiteList=false
dimensionList=
biomeWhiteList=false
biomeList=
leveling=0
fill=0
border=0
validTargetBlocks=
blockSwap=false
data:
:enddata
:endvalidation

#### LAYERS ####
layer: 0
0,0,0,0,0,11,10,10,9,0,0,0,0,0,0,0,0,0,0,0,0,0,0,0,0
0,0,6,6,6,6,6,6,6,6,6,6,8,0,0,0,0,0,0,0,0,0,0,0,0
0,0,6,6,6,6,6,6,6,6,6,7,0,0,0,0,0,0,0,0,0,0,0,0,0
0,0,6,6,6,6,6,6,6,6,6,7,0,0,0,0,0,0,0,0,0,0,0,0,0
0,0,6,6,6,6,6,6,6,6,6,7,0,0,0,0,0,0,0,0,0,0,0,0,0
0,0,6,6,6,6,6,6,6,6,6,7,0,0,0,0,0,0,0,0,0,0,0,0,0
0,0,6,6,6,6,6,6,6,6,6,7,0,0,0,0,0,0,0,0,0,0,0,0,0
0,0,6,6,6,6,6,6,6,6,6,7,0,0,0,0,0,0,0,0,0,0,0,0,0
0,0,6,6,6,6,6,6,6,6,6,7,0,0,0,0,0,0,0,0,0,0,0,0,0
0,0,2,6,6,6,6,6,6,6,6,2,8,0,0,0,0,0,0,0,0,0,0,0,0
0,0,2,6,6,6,6,6,6,6,6,2,0,0,0,0,0,0,0,0,0,0,0,0,0
0,0,2,6,6,6,6,6,6,6,6,2,0,0,0,0,0,0,0,0,0,0,0,0,0
0,0,2,6,6,6,6,6,6,6,6,2,0,0,0,0,0,0,0,0,0,0,0,0,0
0,0,2,6,6,6,6,6,6,6,6,2,0,0,0,0,0,0,0,0,0,0,0,0,0
0,0,2,6,6,6,6,6,6,6,6,2,0,0,0,0,0,0,0,0,0,0,0,0,0
0,0,2,6,6,6,6,6,6,6,6,2,0,0,0,0,0,0,0,0,0,0,0,0,0
0,0,2,6,6,6,6,6,6,6,6,2,0,0,0,0,0,0,0,0,0,0,0,0,0
0,0,2,6,6,6,6,6,6,6,6,2,0,0,0,0,0,0,0,0,0,0,0,0,0
0,0,2,6,6,6,6,6,6,6,6,2,0,0,0,0,0,0,0,0,0,0,0,0,0
0,0,2,6,6,6,6,6,6,6,6,2,0,0,0,0,0,0,0,0,0,0,0,0,0
0,0,2,6,6,6,6,6,6,6,6,2,0,0,0,0,0,0,0,0,0,0,0,0,0
0,0,2,6,6,6,6,6,6,6,6,2,0,0,0,0,0,0,0,0,0,0,0,0,0
0,0,2,6,6,6,6,6,6,6,6,2,0,0,0,0,0,0,0,0,0,0,0,0,0
0,0,2,4,4,6,6,5,7,7,4,2,0,0,0,0,0,0,0,0,0,0,0,0,0
0,0,2,4,4,6,6,2,4,4,4,2,0,0,0,0,0,0,0,0,0,0,0,0,0
0,0,2,2,2,2,2,2,2,2,2,2,2,2,2,2,2,2,2,2,2,2,2,2,0
0,0,2,2,2,2,2,2,2,2,2,2,2,2,2,2,2,2,2,2,2,2,2,2,0
0,0,2,2,2,2,2,2,2,2,2,2,2,2,2,2,2,2,2,2,2,2,2,2,0
0,0,2,2,2,2,2,2,2,2,2,2,2,2,2,2,2,2,2,2,2,2,2,2,0
0,0,2,2,2,2,2,2,2,2,2,2,2,2,2,2,2,2,2,2,2,2,2,2,0
0,0,2,2,2,2,2,2,2,2,2,2,2,2,2,2,2,2,2,2,2,2,2,2,0
0,0,2,2,2,2,2,2,2,2,2,2,2,2,2,2,2,2,2,2,2,2,2,2,0
0,0,2,2,2,2,2,2,2,2,2,2,2,2,2,2,2,2,2,2,2,2,2,2,0
0,0,2,2,2,2,2,2,2,2,2,2,2,2,2,2,2,2,2,2,2,2,2,2,0
0,0,0,0,0,0,0,2,2,2,2,0,0,0,0,0,0,0,0,0,0,0,0,0,0
0,0,0,0,0,0,0,2,2,2,2,0,0,0,0,0,0,0,0,0,0,0,0,0,0
0,0,0,0,0,0,0,2,2,2,2,0,0,0,0,0,0,0,0,0,0,0,0,0,0
0,0,0,0,0,0,0,2,5,5,2,0,0,0,0,0,0,0,0,0,0,0,0,0,0
0,0,0,0,0,0,0,4,3,3,4,0,0,0,0,0,0,0,0,0,0,0,0,0,0
0,0,0,0,0,0,0,4,3,3,4,0,0,0,0,0,0,0,0,0,0,0,0,0,0
0,0,0,0,0,0,0,2,3,3,2,0,0,0,0,0,0,0,0,0,0,0,0,0,0
1,0,0,0,0,0,0,0,0,0,0,0,0,0,0,0,0,0,0,0,0,0,0,0,0
:endlayer
layer: 1
0,0,0,0,0,0,17,17,0,0,0,0,0,0,0,0,0,0,0,0,0,0,0,0,0
0,0,10,18,18,18,20,19,18,18,18,10,8,0,0,0,0,0,0,0,0,0,0,0,0
0,0,10,8,0,0,17,17,0,0,0,0,0,0,0,0,0,0,0,0,0,0,0,0,0
0,0,10,0,0,0,0,0,0,0,0,8,0,0,0,0,0,0,0,0,0,0,0,0,0
0,0,10,8,0,0,0,0,8,0,0,0,0,0,0,0,0,0,0,0,0,0,0,0,0
0,0,10,16,0,0,0,0,0,0,0,0,0,0,0,0,0,0,0,0,0,0,0,0,0
0,0,10,0,0,0,0,0,0,0,0,0,0,0,0,0,0,0,0,0,0,0,0,0,0
0,0,10,0,0,0,0,0,0,0,0,0,0,0,0,0,0,0,0,0,0,0,0,0,0
0,0,10,0,0,0,0,0,0,0,0,0,0,0,0,0,0,0,0,0,0,0,0,0,0
0,0,10,0,0,0,8,0,0,0,8,10,8,0,0,0,0,0,0,0,0,0,0,0,0
0,0,10,0,0,0,0,0,0,0,0,10,0,0,0,0,0,0,0,0,0,0,0,0,0
0,0,10,0,0,0,8,0,0,0,8,10,0,0,0,0,0,0,0,0,0,0,0,0,0
0,0,10,0,0,0,0,0,0,0,15,10,0,0,0,0,0,0,0,0,0,0,0,0,0
0,0,10,0,0,0,0,0,0,0,0,10,0,0,0,0,0,0,0,0,0,0,0,0,0
0,0,10,0,0,0,0,0,0,0,0,10,0,0,0,0,0,0,0,0,0,0,0,0,0
0,0,10,0,0,0,0,0,0,0,0,10,0,0,0,0,0,0,0,0,0,0,0,0,0
0,0,10,0,0,0,0,0,0,0,0,10,0,0,0,0,0,0,0,0,0,0,0,0,0
0,0,10,0,0,0,0,0,0,0,0,10,0,0,0,0,0,0,0,0,0,0,0,0,0
0,0,10,0,0,0,0,0,0,0,0,10,0,0,0,0,0,0,0,0,0,0,0,0,0
0,0,10,0,0,0,0,0,0,0,0,10,0,0,0,0,0,0,0,0,0,0,0,0,0
0,0,10,0,0,0,0,0,0,0,0,10,0,0,0,0,0,0,0,0,0,0,0,0,0
0,0,10,0,0,0,0,0,0,0,0,10,0,0,0,0,0,0,0,0,0,0,0,0,0
0,0,10,0,0,0,0,0,0,0,0,10,0,0,0,0,0,0,0,0,0,0,0,0,0
0,0,10,0,0,11,14,14,9,0,0,10,0,0,0,0,0,0,0,0,0,0,0,0,0
0,0,10,0,0,11,10,10,9,0,0,10,0,0,0,0,0,0,0,0,0,0,0,0,0
0,0,10,10,10,10,10,10,10,10,10,10,10,10,10,10,10,10,10,10,10,10,10,10,0
0,0,10,13,13,13,13,13,13,13,13,13,13,13,13,13,13,13,13,13,13,13,13,10,0
0,0,10,13,13,13,13,13,13,13,13,13,13,13,13,13,13,13,13,13,13,13,13,10,0
0,0,10,13,13,13,13,13,13,13,13,13,13,13,13,13,13,13,13,13,13,13,13,10,0
0,0,10,13,13,13,13,13,13,13,13,13,13,13,13,13,13,13,13,13,13,13,13,10,0
0,0,10,13,13,13,13,13,13,13,13,13,13,13,13,13,13,13,13,13,13,13,13,10,0
0,0,10,13,13,13,13,13,13,13,13,13,13,13,13,13,13,13,13,13,13,13,13,10,0
0,0,10,13,13,13,13,13,13,13,13,13,13,13,13,13,13,13,13,13,13,13,13,10,0
0,0,10,10,10,10,10,10,10,10,10,10,10,10,10,10,10,10,10,10,10,10,10,10,0
0,0,0,0,0,0,0,10,10,10,10,0,0,0,0,0,0,0,0,0,0,0,0,0,0
0,0,0,0,0,0,0,11,10,10,9,0,0,0,0,0,0,0,0,0,0,0,0,0,0
0,0,0,0,0,0,0,11,10,10,9,0,0,0,0,0,0,0,0,0,0,0,0,0,0
0,0,0,0,0,0,0,10,12,12,10,0,0,0,0,0,0,0,0,0,0,0,0,0,0
0,0,0,0,0,0,0,0,0,0,0,0,0,0,0,0,0,0,0,0,0,0,0,0,0
0,0,0,0,0,0,0,0,0,0,0,0,0,0,0,0,0,0,0,0,0,0,0,0,0
0,0,0,0,0,0,0,10,0,0,10,0,0,0,0,0,0,0,0,0,0,0,0,0,0
0,0,0,0,0,0,0,0,0,0,0,0,0,0,0,0,0,0,0,0,0,0,0,0,0
:endlayer
layer: 2
0,0,0,0,0,0,0,0,0,0,0,0,0,0,0,0,0,0,0,0,0,0,0,0,0
0,0,10,18,18,18,24,23,18,18,18,10,8,0,0,0,0,0,0,0,0,0,0,0,0
0,0,18,8,0,0,0,0,0,0,0,0,0,0,0,0,0,0,0,0,0,0,0,0,0
0,0,18,0,0,0,0,0,0,0,0,0,0,0,0,0,0,0,0,0,0,0,0,0,0
0,0,18,8,0,0,0,0,8,0,0,0,0,0,0,0,0,0,0,0,0,0,0,0,0
0,0,10,16,0,0,0,0,0,0,0,0,0,0,0,0,0,0,0,0,0,0,0,0,0
0,0,18,0,0,0,0,0,0,0,0,0,0,0,0,0,0,0,0,0,0,0,0,0,0
0,0,18,0,0,0,0,0,0,0,0,0,0,0,0,0,0,0,0,0,0,0,0,0,0
0,0,18,0,0,0,0,0,0,0,0,0,0,0,0,0,0,0,0,0,0,0,0,0,0
0,0,10,0,0,0,8,0,0,0,8,10,8,0,0,0,0,0,0,0,0,0,0,0,0
0,0,18,0,0,0,0,0,0,0,0,18,0,0,0,0,0,0,0,0,0,0,0,0,0
0,0,18,0,0,0,8,0,0,0,8,18,0,0,0,0,0,0,0,0,0,0,0,0,0
0,0,18,0,0,0,0,0,0,0,15,18,0,0,0,0,0,0,0,0,0,0,0,0,0
0,0,10,0,0,0,0,0,0,0,0,10,0,0,0,0,0,0,0,0,0,0,0,0,0
0,0,18,0,0,0,0,0,0,0,0,18,0,0,0,0,0,0,0,0,0,0,0,0,0
0,0,18,0,0,0,0,0,0,0,0,18,0,0,0,0,0,0,0,0,0,0,0,0,0
0,0,18,0,0,0,0,0,0,0,0,18,0,0,0,0,0,0,0,0,0,0,0,0,0
0,0,10,0,0,0,0,0,0,0,0,10,0,0,0,0,0,0,0,0,0,0,0,0,0
0,0,18,0,0,0,0,0,0,0,0,18,0,0,0,0,0,0,0,0,0,0,0,0,0
0,0,18,0,0,0,0,0,0,0,0,18,0,0,0,0,0,0,0,0,0,0,0,0,0
0,0,18,0,0,0,0,0,0,0,0,18,0,0,0,0,0,0,0,0,0,0,0,0,0
0,0,10,0,0,0,0,0,0,0,0,10,0,0,0,0,0,0,0,0,0,0,0,0,0
0,0,18,0,0,0,0,0,0,0,0,18,0,0,0,0,0,0,0,0,0,0,0,0,0
0,0,18,0,0,0,0,0,0,0,0,18,0,0,0,0,0,0,0,0,0,0,0,0,0
0,0,18,0,0,0,17,17,0,0,0,18,0,0,0,0,0,0,0,0,0,0,0,0,0
0,0,10,18,18,18,20,19,18,18,18,18,18,18,18,10,18,18,18,10,18,18,18,10,0
0,0,18,0,0,0,17,17,0,0,0,0,0,0,0,0,0,0,0,0,0,0,0,18,0
0,0,18,0,0,0,0,0,0,0,0,0,0,0,0,0,0,0,0,0,0,0,0,18,0
0,0,18,0,0,0,0,0,0,0,0,0,0,0,0,0,0,0,0,0,0,0,0,18,0
0,0,10,0,0,0,0,0,0,0,0,0,0,0,0,0,0,0,0,0,0,0,0,18,0
0,0,18,0,0,0,0,0,0,0,0,0,0,0,0,0,0,0,0,0,0,0,0,18,0
0,0,18,0,0,0,0,0,0,0,0,0,0,0,0,0,0,0,0,0,0,0,0,18,0
0,0,18,0,0,0,0,22,17,17,22,0,0,0,0,0,0,0,0,0,0,0,0,18,0
0,0,10,18,18,18,10,18,19,20,18,10,18,18,18,10,18,18,18,10,18,18,18,10,0
0,0,0,0,0,0,0,10,17,17,10,0,0,0,0,0,0,0,0,0,0,0,0,0,0
0,0,0,0,0,0,0,0,0,0,0,0,0,0,0,0,0,0,0,0,0,0,0,0,0
0,0,0,0,0,0,0,0,0,0,0,0,0,0,0,0,0,0,0,0,0,0,0,0,0
0,0,0,0,0,0,0,10,0,0,10,0,0,0,0,0,0,0,0,0,0,0,0,0,0
0,0,0,0,0,0,0,0,0,0,0,0,0,0,0,0,0,0,0,0,0,0,0,0,0
0,0,0,0,0,0,0,0,0,0,0,0,0,0,0,0,0,0,0,0,0,0,0,0,0
0,0,0,0,0,0,0,10,0,0,10,0,0,0,0,0,0,0,0,0,0,0,0,0,0
0,0,0,0,0,0,0,21,0,0,0,0,0,0,0,0,0,0,0,0,0,0,0,0,0
:endlayer
layer: 3
0,0,0,0,0,0,0,0,0,0,0,0,0,0,0,0,0,0,0,0,0,0,0,0,0
0,0,10,18,18,18,18,18,18,18,18,10,8,0,0,0,0,0,0,0,0,0,0,0,0
0,0,18,8,0,0,0,0,0,0,0,0,0,0,0,0,0,0,0,0,0,0,0,0,0
0,0,18,0,0,0,0,0,0,0,0,0,0,0,0,0,0,0,0,0,0,0,0,0,0
0,0,18,8,0,0,0,0,8,0,0,0,0,0,0,0,0,0,0,0,0,0,0,0,0
0,0,10,16,0,0,0,0,0,0,0,0,0,0,0,0,0,0,0,0,0,0,0,0,0
0,0,18,0,0,0,0,0,0,0,0,0,0,0,0,0,0,0,0,0,0,0,0,0,0
0,0,25,0,0,0,0,0,0,0,0,0,0,0,0,0,0,0,0,0,0,0,0,0,0
0,0,18,0,0,0,0,0,0,0,0,0,0,0,0,0,0,0,0,0,0,0,0,0,0
0,0,10,0,0,0,8,0,0,0,8,10,8,0,0,0,0,0,0,0,0,0,0,0,0
0,0,18,0,0,0,0,0,0,0,0,18,0,0,0,0,0,0,0,0,0,0,0,0,0
0,0,25,0,0,0,8,0,0,0,8,25,0,0,0,0,0,0,0,0,0,0,0,0,0
0,0,18,0,0,0,0,0,0,0,15,18,0,0,0,0,0,0,0,0,0,0,0,0,0
0,0,10,0,0,0,0,0,0,0,0,10,0,0,0,0,0,0,0,0,0,0,0,0,0
0,0,18,0,0,0,0,0,0,0,0,18,0,0,0,0,0,0,0,0,0,0,0,0,0
0,0,25,0,0,0,0,0,0,0,0,25,0,0,0,0,0,0,0,0,0,0,0,0,0
0,0,18,0,0,0,0,0,0,0,0,18,0,0,0,0,0,0,0,0,0,0,0,0,0
0,0,10,0,0,0,0,0,0,0,0,10,0,0,0,0,0,0,0,0,0,0,0,0,0
0,0,18,0,0,0,0,0,0,0,0,18,0,0,0,0,0,0,0,0,0,0,0,0,0
0,0,25,0,0,0,0,0,0,0,0,25,0,0,0,0,0,0,0,0,0,0,0,0,0
0,0,18,0,0,0,0,0,0,0,0,18,0,0,0,0,0,0,0,0,0,0,0,0,0
0,0,10,0,0,0,0,0,0,0,0,10,0,0,0,0,0,0,0,0,0,0,0,0,0
0,0,18,0,0,0,0,0,0,0,0,18,0,0,0,0,0,0,0,0,0,0,0,0,0
0,0,25,0,0,0,0,0,0,0,0,25,0,0,0,0,0,0,0,0,0,0,0,0,0
0,0,18,0,0,0,0,0,0,0,0,18,0,0,0,0,0,0,0,0,0,0,0,0,0
0,0,10,18,25,18,29,28,18,25,18,10,18,25,18,10,18,25,18,10,18,25,18,10,0
0,0,18,0,0,0,0,0,0,0,0,0,0,0,0,0,0,0,0,0,0,0,0,18,0
0,0,25,0,0,0,0,0,0,0,0,0,0,0,0,0,0,0,0,0,0,0,0,18,0
0,0,18,0,0,0,0,0,0,0,0,0,0,0,0,0,0,0,0,0,0,0,0,18,0
0,0,10,0,0,0,0,0,0,0,0,0,0,0,0,0,0,0,0,0,0,0,0,18,0
0,0,18,0,0,0,0,0,0,0,0,0,0,0,0,0,0,0,0,0,0,0,0,18,0
0,0,18,0,0,0,0,0,0,0,0,0,0,0,0,0,0,0,0,0,0,0,0,18,0
0,0,18,0,0,0,0,22,0,0,22,0,0,0,0,0,0,0,0,0,0,0,0,18,0
0,0,10,18,25,18,10,18,27,26,18,10,18,25,18,10,18,25,18,10,18,25,18,10,0
0,0,0,0,0,0,0,10,0,0,10,0,0,0,0,0,0,0,0,0,0,0,0,0,0
0,0,0,0,0,0,0,0,0,0,0,0,0,0,0,0,0,0,0,0,0,0,0,0,0
0,0,0,0,0,0,0,0,0,0,0,0,0,0,0,0,0,0,0,0,0,0,0,0,0
0,0,0,0,0,0,0,10,0,0,10,0,0,0,0,0,0,0,0,0,0,0,0,0,0
0,0,0,0,0,0,0,0,0,0,0,0,0,0,0,0,0,0,0,0,0,0,0,0,0
0,0,0,0,0,0,0,0,0,0,0,0,0,0,0,0,0,0,0,0,0,0,0,0,0
0,0,0,0,0,0,0,10,0,0,10,0,0,0,0,0,0,0,0,0,0,0,0,0,0
0,0,0,0,0,0,0,0,0,0,0,0,0,0,0,0,0,0,0,0,0,0,0,0,0
:endlayer
layer: 4
0,0,0,0,0,0,0,0,0,0,0,0,0,0,0,0,0,0,0,0,0,0,0,0,0
0,0,10,18,18,18,18,18,18,18,18,10,8,0,0,0,0,0,0,0,0,0,0,0,0
0,0,18,34,35,35,35,35,35,0,0,0,0,0,0,0,0,0,0,0,0,0,0,0,0
0,0,18,0,0,0,0,0,35,0,0,0,0,0,0,0,0,0,0,0,0,0,0,0,0
0,0,18,34,35,35,35,35,34,0,0,0,0,0,0,0,0,0,0,0,0,0,0,0,0
0,0,10,16,0,0,0,0,0,0,0,0,0,0,0,0,0,0,0,0,0,0,0,0,0
0,0,18,0,0,0,0,0,0,0,0,0,0,0,0,0,0,0,0,0,0,0,0,0,0
0,0,25,0,0,0,0,0,0,0,0,0,0,0,0,0,0,0,0,0,0,0,0,0,0
0,0,18,0,0,0,0,0,0,0,0,0,0,0,0,0,0,0,0,0,0,0,0,0,0
0,0,10,35,35,35,34,35,35,35,34,10,8,0,0,0,0,0,0,0,0,0,0,0,0
0,0,18,0,0,0,0,0,0,0,0,18,0,0,0,0,0,0,0,0,0,0,0,0,0
0,0,25,35,35,35,34,35,35,35,34,25,0,0,0,0,0,0,0,0,0,0,0,0,0
0,0,18,0,0,0,0,0,0,0,15,18,0,0,0,0,0,0,0,0,0,0,0,0,0
0,0,10,0,0,0,0,0,0,0,0,10,0,0,0,0,0,0,0,0,0,0,0,0,0
0,0,18,0,0,0,0,0,0,0,0,18,0,0,0,0,0,0,0,0,0,0,0,0,0
0,0,25,0,0,0,0,0,0,0,0,25,0,0,0,0,0,0,0,0,0,0,0,0,0
0,0,18,0,0,0,0,0,0,0,0,18,0,0,0,0,0,0,0,0,0,0,0,0,0
0,0,10,0,0,0,0,0,0,0,0,10,0,0,0,0,0,0,0,0,0,0,0,0,0
0,0,18,0,0,0,0,0,0,0,0,18,0,0,0,0,0,0,0,0,0,0,0,0,0
0,0,25,0,0,0,0,0,0,0,0,25,0,0,0,0,0,0,0,0,0,0,0,0,0
0,0,18,0,0,0,0,0,0,0,0,18,0,0,0,0,0,0,0,0,0,0,0,0,0
0,0,10,0,0,0,0,0,0,0,0,10,0,0,0,0,0,0,0,0,0,0,0,0,0
0,0,18,0,0,0,0,0,0,0,0,18,0,0,0,0,0,0,0,0,0,0,0,0,0
0,0,25,0,0,0,0,0,0,0,0,25,0,0,0,0,0,0,0,0,0,0,0,0,0
0,0,18,0,0,0,0,0,0,0,0,18,0,0,0,0,0,0,0,0,0,0,0,0,0
0,0,10,18,25,18,18,18,18,25,18,10,18,25,18,10,18,25,18,10,18,25,18,10,0
0,0,18,0,0,0,0,0,0,0,0,0,0,0,0,0,0,0,0,0,0,0,0,18,0
0,0,25,0,0,0,0,0,0,0,0,0,0,0,0,0,0,0,0,0,0,0,0,18,0
0,0,18,0,0,0,0,0,0,0,0,0,0,0,0,0,0,0,0,0,0,0,0,18,0
0,0,10,0,0,0,0,0,0,0,0,0,0,0,0,0,0,0,0,0,0,0,0,18,0
0,0,18,0,0,0,0,0,0,0,0,0,0,0,0,0,0,0,0,0,0,0,0,18,0
0,0,18,0,0,0,0,0,0,0,0,0,0,0,0,0,0,0,0,0,0,0,0,18,0
0,0,18,0,0,0,0,22,33,33,22,0,0,0,0,0,0,0,0,0,0,0,0,18,0
0,0,10,18,25,18,10,18,0,0,18,10,18,25,18,10,18,25,18,10,18,25,18,10,0
0,0,0,0,0,0,0,10,0,0,10,0,0,0,0,0,0,0,0,0,0,0,0,0,0
0,0,0,0,0,0,0,32,0,0,31,0,0,0,0,0,0,0,0,0,0,0,0,0,0
0,0,0,0,0,0,0,32,0,0,31,0,0,0,0,0,0,0,0,0,0,0,0,0,0
0,0,0,0,0,0,0,10,0,0,10,0,0,0,0,0,0,0,0,0,0,0,0,0,0
0,0,0,0,0,0,0,32,0,0,31,0,0,0,0,0,0,0,0,0,0,0,0,0,0
0,0,0,0,0,0,0,32,0,0,31,0,0,0,0,0,0,0,0,0,0,0,0,0,0
0,0,0,0,0,0,0,10,30,30,10,0,0,0,0,0,0,0,0,0,0,0,0,0,0
0,0,0,0,0,0,0,0,0,0,0,0,0,0,0,0,0,0,0,0,0,0,0,0,0
:endlayer
layer: 5
0,7,7,7,7,7,7,7,7,7,7,7,7,0,0,0,0,0,0,0,0,0,0,0,0
0,7,10,18,18,18,18,18,18,18,18,10,4,0,0,0,0,0,0,0,0,0,0,0,0
0,7,18,0,0,0,0,0,8,0,0,8,0,0,0,0,0,0,0,0,0,0,0,0,0
0,7,18,0,0,0,0,0,0,0,0,8,0,0,0,0,0,0,0,0,0,0,0,0,0
0,7,18,0,0,0,0,0,8,0,0,8,0,0,0,0,0,0,0,0,0,0,0,0,0
0,7,10,0,0,0,0,0,0,0,0,8,0,0,0,0,0,0,0,0,0,0,0,0,0
0,7,18,0,0,0,0,0,0,0,0,8,0,0,0,0,0,0,0,0,0,0,0,0,0
0,7,18,0,0,0,0,0,0,0,0,8,0,0,0,0,0,0,0,0,0,0,0,0,0
0,7,18,0,0,0,0,0,0,0,0,8,0,0,0,0,0,0,0,0,0,0,0,0,0
0,7,10,0,0,0,8,0,0,0,8,10,4,0,0,0,0,0,0,0,0,0,0,0,0
0,7,18,0,0,0,0,0,0,0,0,18,7,0,0,0,0,0,0,0,0,0,0,0,0
0,7,18,0,0,0,8,0,0,0,8,18,7,0,0,0,0,0,0,0,0,0,0,0,0
0,7,18,0,0,0,0,0,0,0,0,18,7,0,0,0,0,0,0,0,0,0,0,0,0
0,7,10,0,0,0,0,0,0,0,0,10,7,0,0,0,0,0,0,0,0,0,0,0,0
0,7,18,0,0,0,0,0,0,0,0,18,7,0,0,0,0,0,0,0,0,0,0,0,0
0,7,18,0,0,0,0,0,0,0,0,18,7,0,0,0,0,0,0,0,0,0,0,0,0
0,7,18,0,0,0,0,0,0,0,0,10,7,0,0,0,0,0,0,0,0,0,0,0,0
0,7,10,0,0,0,0,0,0,0,0,10,7,0,0,0,0,0,0,0,0,0,0,0,0
0,7,18,0,0,0,0,0,0,0,0,18,7,0,0,0,0,0,0,0,0,0,0,0,0
0,7,18,0,0,0,0,0,0,0,0,18,7,0,0,0,0,0,0,0,0,0,0,0,0
0,7,18,0,0,0,0,0,0,0,0,18,7,0,0,0,0,0,0,0,0,0,0,0,0
0,7,10,0,0,0,0,0,0,0,0,10,7,0,0,0,0,0,0,0,0,0,0,0,0
0,7,18,0,0,0,0,0,0,0,0,18,7,0,0,0,0,0,0,0,0,0,0,0,0
0,7,18,0,0,0,0,0,0,0,0,18,7,0,0,0,0,0,0,0,0,0,0,0,0
0,7,18,0,0,0,0,0,0,0,0,18,7,7,7,7,7,7,7,7,7,7,7,7,7
0,7,10,18,18,18,18,18,18,18,18,10,18,18,18,10,18,18,18,10,18,18,18,10,7
0,7,18,0,0,0,0,0,0,0,0,0,0,0,0,0,0,8,0,0,0,0,0,18,7
0,7,18,0,0,0,0,0,0,0,0,0,0,0,0,0,0,8,0,0,0,0,0,18,7
0,7,18,0,0,0,0,0,0,0,0,0,0,0,0,0,0,8,0,0,0,0,0,18,7
0,7,10,0,0,0,0,0,0,0,0,0,0,0,0,0,0,8,0,0,0,0,0,18,7
0,7,18,0,0,0,0,0,0,0,0,0,0,0,0,0,0,8,0,0,0,0,0,18,7
0,7,18,0,0,0,0,0,0,0,0,0,0,0,0,0,0,8,0,0,0,0,0,18,7
0,7,18,0,0,0,0,22,22,22,22,0,0,0,0,0,0,8,0,0,0,0,0,18,7
0,7,10,18,18,18,10,10,18,18,10,10,18,18,18,10,18,18,18,10,18,18,18,18,7
0,7,7,7,7,7,7,11,30,30,9,7,7,7,7,7,7,7,7,7,7,7,7,7,7
0,0,0,0,0,0,0,11,37,37,9,0,0,0,0,0,0,0,0,0,0,0,0,0,0
0,0,0,0,0,0,0,11,37,37,9,0,0,0,0,0,0,0,0,0,0,0,0,0,0
0,0,0,0,0,0,0,11,37,37,9,0,0,0,0,0,0,0,0,0,0,0,0,0,0
0,0,0,0,0,0,0,11,37,37,9,0,0,0,0,0,0,0,0,0,0,0,0,0,0
0,0,0,0,0,0,0,11,36,36,9,0,0,0,0,0,0,0,0,0,0,0,0,0,0
0,0,0,0,0,0,0,11,12,12,9,0,0,0,0,0,0,0,0,0,0,0,0,0,0
0,0,0,0,0,0,0,0,0,0,0,0,0,0,0,0,0,0,0,0,0,0,0,0,0
:endlayer
layer: 6
0,0,0,0,0,0,0,0,0,0,0,0,0,0,0,0,0,0,0,0,0,0,0,0,0
0,0,10,10,10,10,10,10,10,10,10,10,0,0,0,0,0,0,0,0,0,0,0,0,0
0,0,10,1,1,1,1,1,1,1,1,10,0,0,0,0,0,0,0,0,0,0,0,0,0
0,0,10,1,1,4,1,1,4,1,1,10,0,0,0,0,0,0,0,0,0,0,0,0,0
0,0,10,1,4,38,4,4,38,4,1,10,0,0,0,0,0,0,0,0,0,0,0,0,0
0,0,10,1,4,38,4,4,38,4,1,10,0,0,0,0,0,0,0,0,0,0,0,0,0
0,0,10,1,1,4,4,4,4,1,1,10,0,0,0,0,0,0,0,0,0,0,0,0,0
0,0,10,1,1,4,4,4,4,1,1,10,0,0,0,0,0,0,0,0,0,0,0,0,0
0,0,10,1,4,38,4,4,38,4,1,10,0,0,0,0,0,0,0,0,0,0,0,0,0
0,0,10,1,4,38,4,4,38,4,1,10,0,0,0,0,0,0,0,0,0,0,0,0,0
0,0,10,1,1,4,4,4,4,1,1,10,0,0,0,0,0,0,0,0,0,0,0,0,0
0,0,10,1,1,4,4,4,1,1,1,10,0,0,0,0,0,0,0,0,0,0,0,0,0
0,0,10,1,1,4,4,4,4,1,1,10,0,0,0,0,0,0,0,0,0,0,0,0,0
0,0,10,1,4,38,4,4,38,4,1,10,0,0,0,0,0,0,0,0,0,0,0,0,0
0,0,10,1,4,38,4,4,38,4,1,10,0,0,0,0,0,0,0,0,0,0,0,0,0
0,0,10,1,1,4,4,4,4,4,1,10,0,0,0,0,0,0,0,0,0,0,0,0,0
0,0,10,1,1,4,4,4,4,4,1,10,0,0,0,0,0,0,0,0,0,0,0,0,0
0,0,10,1,4,38,4,4,38,4,1,10,0,0,0,0,0,0,0,0,0,0,0,0,0
0,0,10,1,4,38,4,4,38,4,1,10,0,0,0,0,0,0,0,0,0,0,0,0,0
0,0,10,1,1,4,4,4,4,1,1,10,0,0,0,0,0,0,0,0,0,0,0,0,0
0,0,10,1,1,4,4,4,4,1,1,10,0,0,0,0,0,0,0,0,0,0,0,0,0
0,0,10,1,4,38,4,4,38,4,1,10,0,0,0,0,0,0,0,0,0,0,0,0,0
0,0,10,1,4,38,4,4,38,4,1,10,0,0,0,0,0,0,0,0,0,0,0,0,0
0,0,10,1,1,4,1,1,4,1,1,10,0,0,0,0,0,0,0,0,0,0,0,0,0
0,0,10,1,1,1,1,1,1,1,1,10,0,0,0,0,0,0,0,0,0,0,0,0,0
0,0,10,1,1,1,1,1,1,1,1,10,10,10,10,10,10,10,10,10,10,10,10,10,0
0,0,10,1,1,1,1,1,1,1,1,1,1,1,1,1,1,1,1,1,1,1,1,10,0
0,0,10,1,1,4,4,1,1,1,4,4,1,1,4,4,1,1,1,4,4,1,1,10,0
0,0,10,1,4,38,38,4,1,4,38,38,4,4,38,38,4,1,4,38,38,4,1,10,0
0,0,10,1,1,4,4,4,4,4,4,4,4,4,4,4,4,1,1,4,4,1,1,10,0
0,0,10,1,4,38,38,4,1,4,38,38,4,4,38,38,4,1,4,38,38,4,1,10,0
0,0,10,1,1,4,4,1,1,1,4,4,1,1,4,4,1,1,1,4,4,1,1,10,0
0,0,10,1,1,1,1,1,1,1,1,1,1,1,1,1,1,1,1,1,1,1,1,10,0
0,0,10,10,10,10,10,10,10,10,10,10,10,10,10,10,10,10,10,10,10,10,10,10,0
0,0,0,0,0,0,0,0,0,0,0,0,0,0,0,0,0,0,0,0,0,0,0,0,0
0,0,0,0,0,0,0,0,0,0,0,0,0,0,0,0,0,0,0,0,0,0,0,0,0
0,0,0,0,0,0,0,0,0,0,0,0,0,0,0,0,0,0,0,0,0,0,0,0,0
0,0,0,0,0,0,0,0,0,0,0,0,0,0,0,0,0,0,0,0,0,0,0,0,0
0,0,0,0,0,0,0,0,0,0,0,0,0,0,0,0,0,0,0,0,0,0,0,0,0
0,0,0,0,0,0,0,0,0,0,0,0,0,0,0,0,0,0,0,0,0,0,0,0,0
0,0,0,0,0,0,0,0,0,0,0,0,0,0,0,0,0,0,0,0,0,0,0,0,0
0,0,0,0,0,0,0,0,0,0,0,0,0,0,0,0,0,0,0,0,0,0,0,0,0
:endlayer
layer: 7
0,0,0,0,0,0,0,0,0,0,0,0,0,0,0,0,0,0,0,0,0,0,0,0,0
0,0,0,0,0,0,0,0,0,0,0,0,0,0,0,0,0,0,0,0,0,0,0,0,0
0,0,0,0,0,0,0,0,0,0,0,0,0,0,0,0,0,0,0,0,0,0,0,0,0
0,0,0,0,0,0,0,0,0,0,0,0,0,0,0,0,0,0,0,0,0,0,0,0,0
0,0,0,0,0,1,0,0,1,0,0,0,0,0,0,0,0,0,0,0,0,0,0,0,0
0,0,0,0,0,1,0,0,1,0,0,0,0,0,0,0,0,0,0,0,0,0,0,0,0
0,0,0,0,0,0,0,0,0,0,0,0,0,0,0,0,0,0,0,0,0,0,0,0,0
0,0,0,0,0,0,0,0,0,0,0,0,0,0,0,0,0,0,0,0,0,0,0,0,0
0,0,0,0,0,1,0,0,1,0,0,0,0,0,0,0,0,0,0,0,0,0,0,0,0
0,0,0,0,0,1,0,0,1,0,0,0,0,0,0,0,0,0,0,0,0,0,0,0,0
0,0,0,0,0,0,0,0,0,0,0,0,0,0,0,0,0,0,0,0,0,0,0,0,0
0,0,0,0,0,0,0,0,0,0,0,0,0,0,0,0,0,0,0,0,0,0,0,0,0
0,0,0,0,0,0,0,0,0,0,0,0,0,0,0,0,0,0,0,0,0,0,0,0,0
0,0,0,0,0,1,0,0,1,0,0,0,0,0,0,0,0,0,0,0,0,0,0,0,0
0,0,0,0,0,1,0,0,1,0,0,0,0,0,0,0,0,0,0,0,0,0,0,0,0
0,0,0,0,0,0,0,0,0,0,0,0,0,0,0,0,0,0,0,0,0,0,0,0,0
0,0,0,0,0,0,0,0,0,0,0,0,0,0,0,0,0,0,0,0,0,0,0,0,0
0,0,0,0,0,1,0,0,1,0,0,0,0,0,0,0,0,0,0,0,0,0,0,0,0
0,0,0,0,0,1,0,0,1,0,0,0,0,0,0,0,0,0,0,0,0,0,0,0,0
0,0,0,0,0,0,0,0,0,0,0,0,0,0,0,0,0,0,0,0,0,0,0,0,0
0,0,0,0,0,0,0,0,0,0,0,0,0,0,0,0,0,0,0,0,0,0,0,0,0
0,0,0,0,0,1,0,0,1,0,0,0,0,0,0,0,0,0,0,0,0,0,0,0,0
0,0,0,0,0,1,0,0,1,0,0,0,0,0,0,0,0,0,0,0,0,0,0,0,0
0,0,0,0,0,0,0,0,0,0,0,0,0,0,0,0,0,0,0,0,0,0,0,0,0
0,0,0,0,0,0,0,0,0,0,0,0,0,0,0,0,0,0,0,0,0,0,0,0,0
0,0,0,0,0,0,0,0,0,0,0,0,0,0,0,0,0,0,0,0,0,0,0,0,0
0,0,0,0,0,0,0,0,0,0,0,0,0,0,0,0,0,0,0,0,0,0,0,0,0
0,0,0,0,0,0,0,0,0,0,0,0,0,0,0,0,0,0,0,0,0,0,0,0,0
0,0,0,0,0,1,1,0,0,0,1,1,0,0,1,1,0,0,0,1,1,0,0,0,0
0,0,0,0,0,0,0,0,0,0,0,0,0,0,0,0,0,0,0,0,0,0,0,0,0
0,0,0,0,0,1,1,0,0,0,1,1,0,0,1,1,0,0,0,1,1,0,0,0,0
0,0,0,0,0,0,0,0,0,0,0,0,0,0,0,0,0,0,0,0,0,0,0,0,0
0,0,0,0,0,0,0,0,0,0,0,0,0,0,0,0,0,0,0,0,0,0,0,0,0
0,0,0,0,0,0,0,0,0,0,0,0,0,0,0,0,0,0,0,0,0,0,0,0,0
0,0,0,0,0,0,0,0,0,0,0,0,0,0,0,0,0,0,0,0,0,0,0,0,0
0,0,0,0,0,0,0,0,0,0,0,0,0,0,0,0,0,0,0,0,0,0,0,0,0
0,0,0,0,0,0,0,0,0,0,0,0,0,0,0,0,0,0,0,0,0,0,0,0,0
0,0,0,0,0,0,0,0,0,0,0,0,0,0,0,0,0,0,0,0,0,0,0,0,0
0,0,0,0,0,0,0,0,0,0,0,0,0,0,0,0,0,0,0,0,0,0,0,0,0
0,0,0,0,0,0,0,0,0,0,0,0,0,0,0,0,0,0,0,0,0,0,0,0,0
0,0,0,0,0,0,0,0,0,0,0,0,0,0,0,0,0,0,0,0,0,0,0,0,0
0,0,0,0,0,0,0,0,0,0,0,0,0,0,0,0,0,0,0,0,0,0,0,0,0
:endlayer

#### RULES ####
rule:
plugin=vanillaBlocks
number=1
data:
JSON:{{"val":{"buildPass":{"val":"0","id":"pi"},"blockName":{"val":"minecraft:stone_slab","id":"ss"},"meta":{"val":"0","id":"pi"}},"id":"ct"}}
:enddata
:endrule

rule:
plugin=vanillaBlocks
number=2
data:
JSON:{{"val":{"buildPass":{"val":"0","id":"pi"},"blockName":{"val":"minecraft:dirt","id":"ss"},"meta":{"val":"0","id":"pi"}},"id":"ct"}}
:enddata
:endrule

rule:
plugin=vanillaBlocks
number=3
data:
JSON:{{"val":{"buildPass":{"val":"0","id":"pi"},"blockName":{"val":"minecraft:sand","id":"ss"},"meta":{"val":"0","id":"pi"}},"id":"ct"}}
:enddata
:endrule

rule:
plugin=vanillaBlocks
number=4
data:
JSON:{{"val":{"buildPass":{"val":"0","id":"pi"},"blockName":{"val":"minecraft:double_stone_slab","id":"ss"},"meta":{"val":"0","id":"pi"}},"id":"ct"}}
:enddata
:endrule

rule:
plugin=vanillaBlocks
number=5
data:
JSON:{{"val":{"buildPass":{"val":"0","id":"pi"},"blockName":{"val":"minecraft:grass","id":"ss"},"meta":{"val":"0","id":"pi"}},"id":"ct"}}
:enddata
:endrule

rule:
plugin=vanillaBlocks
number=6
data:
JSON:{{"val":{"buildPass":{"val":"0","id":"pi"},"blockName":{"val":"minecraft:stone","id":"ss"},"meta":{"val":"0","id":"pi"}},"id":"ct"}}
:enddata
:endrule

rule:
plugin=vanillaBlocks
number=7
data:
JSON:{{"val":{"buildPass":{"val":"0","id":"pi"},"blockName":{"val":"minecraft:stone_slab","id":"ss"},"meta":{"val":"8","id":"pi"}},"id":"ct"}}
:enddata
:endrule

rule:
plugin=vanillaBlocks
number=8
data:
JSON:{{"val":{"buildPass":{"val":"0","id":"pi"},"blockName":{"val":"minecraft:fence","id":"ss"},"meta":{"val":"0","id":"pi"}},"id":"ct"}}
:enddata
:endrule

rule:
plugin=vanillaBlocks
number=9
data:
JSON:{{"val":{"buildPass":{"val":"0","id":"pi"},"blockName":{"val":"minecraft:brick_stairs","id":"ss"},"meta":{"val":"1","id":"pi"}},"id":"ct"}}
:enddata
:endrule

rule:
plugin=vanillaBlocks
number=10
data:
JSON:{{"val":{"buildPass":{"val":"0","id":"pi"},"blockName":{"val":"minecraft:brick_block","id":"ss"},"meta":{"val":"0","id":"pi"}},"id":"ct"}}
:enddata
:endrule

rule:
plugin=vanillaBlocks
number=11
data:
JSON:{{"val":{"buildPass":{"val":"0","id":"pi"},"blockName":{"val":"minecraft:brick_stairs","id":"ss"},"meta":{"val":"0","id":"pi"}},"id":"ct"}}
:enddata
:endrule

rule:
plugin=vanillaBlocks
number=12
data:
JSON:{{"val":{"buildPass":{"val":"0","id":"pi"},"blockName":{"val":"minecraft:brick_stairs","id":"ss"},"meta":{"val":"3","id":"pi"}},"id":"ct"}}
:enddata
:endrule

rule:
plugin=vanillaBlocks
number=13
data:
JSON:{{"val":{"buildPass":{"val":"0","id":"pi"},"blockName":{"val":"minecraft:planks","id":"ss"},"meta":{"val":"1","id":"pi"}},"id":"ct"}}
:enddata
:endrule

rule:
plugin=vanillaBlocks
number=14
data:
JSON:{{"val":{"buildPass":{"val":"0","id":"pi"},"blockName":{"val":"minecraft:brick_stairs","id":"ss"},"meta":{"val":"2","id":"pi"}},"id":"ct"}}
:enddata
:endrule

rule:
plugin=vanillaBlocks
number=15
data:
JSON:{{"val":{"buildPass":{"val":"2","id":"pi"},"blockName":{"val":"minecraft:ladder","id":"ss"},"meta":{"val":"4","id":"pi"}},"id":"ct"}}
:enddata
:endrule

rule:
plugin=vanillaBlocks
number=16
data:
JSON:{{"val":{"buildPass":{"val":"2","id":"pi"},"blockName":{"val":"minecraft:ladder","id":"ss"},"meta":{"val":"5","id":"pi"}},"id":"ct"}}
:enddata
:endrule

rule:
plugin=vanillaBlocks
number=17
data:
JSON:{{"val":{"buildPass":{"val":"2","id":"pi"},"blockName":{"val":"minecraft:wooden_pressure_plate","id":"ss"},"meta":{"val":"0","id":"pi"}},"id":"ct"}}
:enddata
:endrule

rule:
plugin=vanillaBlocks
number=18
data:
JSON:{{"val":{"buildPass":{"val":"0","id":"pi"},"blockName":{"val":"minecraft:stonebrick","id":"ss"},"meta":{"val":"0","id":"pi"}},"id":"ct"}}
:enddata
:endrule

rule:
plugin=vanillaDoors
number=19
data:
JSON:{{"val":{"buildPass":{"val":"2","id":"pi"},"blockName":{"val":"minecraft:wooden_door","id":"ss"},"meta":{"val":"1","id":"pi"},"sideFlag":{"val":"8","id":"pb"}},"id":"ct"}}
:enddata
:endrule

rule:
plugin=vanillaDoors
number=20
data:
JSON:{{"val":{"buildPass":{"val":"2","id":"pi"},"blockName":{"val":"minecraft:wooden_door","id":"ss"},"meta":{"val":"1","id":"pi"},"sideFlag":{"val":"9","id":"pb"}},"id":"ct"}}
:enddata
:endrule

rule:
plugin=vanillaSign
number=21
data:
JSON:{{"val":{"signContents0":{"val":"\"\"","id":"ss"},"signContents2":{"val":"\"Ltd.\"","id":"ss"},"buildPass":{"val":"2","id":"pi"},"signContents1":{"val":"\"Head\u0027 Mas","id":"ss"},"blockName":{"val":"minecraft:wall_sign","id":"ss"},"signContents3":{"val":"\"\"","id":"ss"},"meta":{"val":"3","id":"pi"}},"id":"ct"}}
:enddata
:endrule

rule:
plugin=vanillaBlocks
number=22
data:
JSON:{{"val":{"buildPass":{"val":"0","id":"pi"},"blockName":{"val":"minecraft:double_wooden_slab","id":"ss"},"meta":{"val":"3","id":"pi"}},"id":"ct"}}
:enddata
:endrule

rule:
plugin=vanillaDoors
number=23
data:
JSON:{{"val":{"buildPass":{"val":"2","id":"pi"},"blockName":{"val":"minecraft:wooden_door","id":"ss"},"meta":{"val":"8","id":"pi"},"sideFlag":{"val":"0","id":"pb"}},"id":"ct"}}
:enddata
:endrule

rule:
plugin=vanillaDoors
number=24
data:
JSON:{{"val":{"buildPass":{"val":"2","id":"pi"},"blockName":{"val":"minecraft:wooden_door","id":"ss"},"meta":{"val":"9","id":"pi"},"sideFlag":{"val":"0","id":"pb"}},"id":"ct"}}
:enddata
:endrule

rule:
plugin=vanillaBlocks
number=25
data:
JSON:{{"val":{"buildPass":{"val":"0","id":"pi"},"blockName":{"val":"minecraft:glass_pane","id":"ss"},"meta":{"val":"0","id":"pi"}},"id":"ct"}}
:enddata
:endrule

rule:
plugin=vanillaDoors
number=26
data:
JSON:{{"val":{"buildPass":{"val":"2","id":"pi"},"blockName":{"val":"minecraft:wooden_door","id":"ss"},"meta":{"val":"9","id":"pi"},"sideFlag":{"val":"0","id":"pb"}},"id":"ct"}}
:enddata
:endrule

rule:
plugin=vanillaDoors
number=27
data:
JSON:{{"val":{"buildPass":{"val":"2","id":"pi"},"blockName":{"val":"minecraft:wooden_door","id":"ss"},"meta":{"val":"8","id":"pi"},"sideFlag":{"val":"0","id":"pb"}},"id":"ct"}}
:enddata
:endrule

rule:
plugin=vanillaDoors
number=28
data:
JSON:{{"val":{"buildPass":{"val":"2","id":"pi"},"blockName":{"val":"minecraft:wooden_door","id":"ss"},"meta":{"val":"8","id":"pi"},"sideFlag":{"val":"0","id":"pb"}},"id":"ct"}}
:enddata
:endrule

rule:
plugin=vanillaDoors
number=29
data:
JSON:{{"val":{"buildPass":{"val":"2","id":"pi"},"blockName":{"val":"minecraft:wooden_door","id":"ss"},"meta":{"val":"9","id":"pi"},"sideFlag":{"val":"0","id":"pb"}},"id":"ct"}}
:enddata
:endrule

rule:
plugin=vanillaBlocks
number=30
data:
JSON:{{"val":{"buildPass":{"val":"0","id":"pi"},"blockName":{"val":"minecraft:brick_stairs","id":"ss"},"meta":{"val":"7","id":"pi"}},"id":"ct"}}
:enddata
:endrule

rule:
plugin=vanillaBlocks
number=31
data:
JSON:{{"val":{"buildPass":{"val":"0","id":"pi"},"blockName":{"val":"minecraft:brick_stairs","id":"ss"},"meta":{"val":"5","id":"pi"}},"id":"ct"}}
:enddata
:endrule

rule:
plugin=vanillaBlocks
number=32
data:
JSON:{{"val":{"buildPass":{"val":"0","id":"pi"},"blockName":{"val":"minecraft:brick_stairs","id":"ss"},"meta":{"val":"4","id":"pi"}},"id":"ct"}}
:enddata
:endrule

rule:
plugin=vanillaBlocks
number=33
data:
JSON:{{"val":{"buildPass":{"val":"0","id":"pi"},"blockName":{"val":"minecraft:jungle_stairs","id":"ss"},"meta":{"val":"6","id":"pi"}},"id":"ct"}}
:enddata
:endrule

rule:
plugin=vanillaBlocks
number=34
data:
JSON:{{"val":{"buildPass":{"val":"0","id":"pi"},"blockName":{"val":"minecraft:double_wooden_slab","id":"ss"},"meta":{"val":"0","id":"pi"}},"id":"ct"}}
:enddata
:endrule

rule:
plugin=vanillaBlocks
number=35
data:
JSON:{{"val":{"buildPass":{"val":"0","id":"pi"},"blockName":{"val":"minecraft:wooden_slab","id":"ss"},"meta":{"val":"8","id":"pi"}},"id":"ct"}}
:enddata
:endrule

rule:
plugin=vanillaBlocks
number=36
data:
JSON:{{"val":{"buildPass":{"val":"0","id":"pi"},"blockName":{"val":"minecraft:brick_stairs","id":"ss"},"meta":{"val":"6","id":"pi"}},"id":"ct"}}
:enddata
:endrule

rule:
plugin=vanillaBlocks
number=37
data:
JSON:{{"val":{"buildPass":{"val":"0","id":"pi"},"blockName":{"val":"minecraft:stone_slab","id":"ss"},"meta":{"val":"12","id":"pi"}},"id":"ct"}}
:enddata
:endrule

rule:
plugin=vanillaBlocks
number=38
data:
JSON:{{"val":{"buildPass":{"val":"0","id":"pi"},"blockName":{"val":"minecraft:glowstone","id":"ss"},"meta":{"val":"0","id":"pi"}},"id":"ct"}}
:enddata
:endrule

#### ENTITIES ####
