# Ancient Warfare Structure Template File
# Auto-generated structure template file. created on: 11/5/2024 at: 11:53:17
# Lines beginning with # denote comments

header:
version=2.1
name=Stone_church
size=24,13,31
offset=7,-1,28
:endheader

#### VALIDATION ####
validation:
type=ground
survival=true
worldGenEnabled=false
unique=false
preserveBlocks=false
selectionWeight=0
clusterValue=0
minDuplicateDistance=0
dimensionWhiteList=false
dimensionList=
biomeWhiteList=false
biomeList=
leveling=0
fill=0
border=0
validTargetBlocks=
blockSwap=false
data:
:enddata
:endvalidation

#### LAYERS ####
layer: 0
1,0,0,0,0,0,0,0,0,0,0,0,0,1,0,0,0,0,0,0,0,0,0,0
0,3,4,4,4,4,4,4,4,4,4,4,3,0,0,0,0,0,0,0,0,0,0,0
0,4,5,5,5,5,5,5,5,5,5,5,5,4,4,4,4,4,4,4,4,4,0,0
0,4,5,5,5,5,5,5,5,5,5,5,5,5,5,5,5,5,5,5,5,4,0,0
0,4,5,5,5,5,5,5,5,5,5,5,5,5,6,6,6,6,6,6,5,4,0,0
0,4,5,5,5,5,5,5,5,5,5,5,5,5,6,6,6,6,6,6,5,4,0,0
0,3,4,4,4,5,5,5,5,5,5,5,5,5,6,6,6,6,6,6,5,4,0,0
0,4,5,5,5,5,5,5,5,5,5,5,5,5,6,6,6,6,6,6,5,4,0,0
0,4,5,5,5,5,5,5,5,5,5,5,5,5,6,6,6,6,6,6,5,4,0,0
0,4,4,4,4,5,5,5,5,5,5,5,4,5,5,5,5,5,5,5,5,4,0,0
0,4,5,13,4,5,5,5,5,5,5,5,3,4,4,4,4,4,4,4,4,4,1,1
1,3,5,5,5,5,5,5,5,5,5,5,3,0,0,0,0,9,12,2,11,0,0,1
0,4,5,5,5,5,5,5,5,5,5,5,4,0,9,0,0,0,0,0,0,0,0,1
0,4,5,5,5,5,5,5,5,5,5,5,4,0,0,9,0,0,0,0,0,0,0,1
0,4,5,5,5,5,5,5,5,5,5,5,4,0,9,0,0,0,0,0,0,0,0,10
0,4,5,6,6,6,6,6,6,6,6,5,4,0,0,0,0,0,0,0,0,0,0,1
0,4,5,6,6,6,6,6,6,6,6,5,4,0,0,0,0,0,9,0,0,0,0,1
0,4,5,5,5,5,6,6,5,5,5,5,4,0,0,0,9,0,0,0,0,0,0,1
0,4,5,5,5,5,6,6,5,5,5,5,4,0,0,0,0,0,0,0,0,0,0,1
0,4,5,5,5,5,6,6,5,5,5,5,4,0,0,0,0,0,0,0,0,0,0,1
0,4,5,5,5,5,6,6,5,5,5,5,4,0,0,8,0,0,0,0,0,0,0,1
0,4,5,5,5,5,6,6,5,5,5,5,4,0,0,0,0,0,0,0,0,0,0,1
0,4,5,5,5,5,6,6,5,5,5,5,4,0,0,0,0,0,0,0,0,0,0,1
0,4,5,5,5,5,6,6,5,5,5,5,4,0,0,0,0,0,0,0,0,0,0,1
0,4,5,5,5,5,6,6,5,5,5,5,4,1,1,1,1,1,1,7,1,1,1,1
0,4,5,5,5,5,6,6,5,5,5,5,4,0,0,0,0,0,0,0,0,0,0,0
0,3,4,4,4,3,3,3,3,4,4,4,3,0,0,0,0,0,0,0,0,0,0,0
0,0,0,0,0,0,2,2,0,0,0,0,0,0,0,0,0,0,0,0,0,0,0,0
0,0,1,0,0,0,0,0,0,0,0,1,0,0,0,0,0,0,0,0,0,0,0,0
0,0,0,0,0,0,0,0,0,0,0,0,0,0,0,0,0,0,0,0,0,0,0,0
0,0,0,0,0,0,0,0,0,0,0,0,0,0,0,0,0,0,0,0,0,0,0,0
:endlayer
layer: 1
1,0,0,0,0,0,0,0,0,0,0,0,0,1,0,0,0,0,0,0,0,0,0,0
0,3,4,19,19,19,19,19,19,19,19,4,3,0,0,0,0,0,0,0,0,0,0,0
0,4,0,0,0,0,0,0,0,0,0,0,3,4,4,4,4,4,4,4,4,4,0,0
0,14,0,0,0,0,0,0,0,0,0,0,3,0,0,0,0,0,0,0,0,4,0,0
0,14,0,0,0,0,0,0,0,0,0,0,0,0,0,0,0,0,0,0,0,4,0,0
0,4,0,0,0,0,0,0,0,0,0,0,0,0,0,0,0,0,0,0,0,4,0,0
0,3,18,18,18,0,0,0,0,0,0,0,0,0,0,0,0,0,0,0,0,4,0,0
0,4,0,0,3,0,0,0,0,0,0,0,0,0,0,0,0,0,0,0,0,4,0,0
0,4,0,0,15,0,0,0,0,0,0,0,3,0,0,0,0,0,0,0,0,4,0,0
0,4,4,4,4,0,0,0,0,0,0,17,3,0,0,0,0,0,0,0,0,4,0,0
0,4,0,0,15,0,0,0,0,0,0,17,3,4,4,4,4,4,4,15,4,4,0,0
1,3,0,0,3,0,0,0,0,0,0,17,3,0,0,0,0,0,0,0,0,0,0,0
0,4,0,12,3,0,0,0,0,0,0,0,4,0,0,0,0,0,0,0,0,0,0,0
0,4,0,3,3,0,0,0,0,0,0,0,4,0,0,0,0,0,0,0,0,0,0,0
0,4,15,3,0,0,0,0,0,0,0,0,4,0,0,0,0,0,0,0,0,0,0,0
0,4,0,0,0,0,0,0,0,0,0,0,4,0,0,0,0,0,0,0,0,0,0,0
0,4,0,0,0,0,0,0,0,0,0,0,4,0,0,0,0,0,0,0,0,0,0,0
0,4,0,0,0,0,0,0,0,0,0,0,4,0,0,0,0,0,0,0,0,0,0,0
0,14,0,0,0,0,0,0,0,0,0,0,4,0,0,0,0,0,0,0,0,0,0,0
0,4,0,0,0,0,0,0,0,0,0,0,4,0,0,0,0,0,0,0,0,0,0,0
0,14,0,0,0,0,0,0,0,0,0,0,4,0,0,8,0,0,0,0,0,0,0,0
0,4,0,0,0,0,0,0,0,0,0,0,4,0,0,0,0,0,0,0,0,0,0,0
0,14,0,0,0,0,0,0,0,0,0,0,4,0,0,0,0,0,0,0,0,0,0,0
0,4,0,0,0,0,0,0,0,0,0,0,4,0,0,0,0,0,0,0,0,0,0,0
0,14,0,0,0,0,0,0,0,0,0,0,4,0,0,0,0,0,0,0,0,0,0,0
0,4,0,0,0,0,0,0,0,0,0,0,4,0,0,0,0,0,0,0,0,0,0,0
0,3,4,14,4,3,16,15,3,4,14,4,3,0,0,0,0,0,0,0,0,0,0,0
0,0,0,0,0,0,0,0,0,0,0,0,0,0,0,0,0,0,0,0,0,0,0,0
0,0,1,0,0,0,0,0,0,0,0,1,0,0,0,0,0,0,0,0,0,0,0,0
0,0,0,0,0,0,0,0,0,0,0,0,0,0,0,0,0,0,0,0,0,0,0,0
0,0,0,0,0,0,0,0,0,0,0,0,0,0,0,0,0,0,0,0,0,0,0,0
:endlayer
layer: 2
1,0,0,0,0,0,0,0,0,0,0,0,0,1,0,0,0,0,0,0,0,0,0,0
0,3,4,19,19,27,19,19,27,19,19,4,3,0,0,0,0,0,0,0,0,0,0,0
0,4,0,0,0,0,0,0,0,0,0,0,3,4,4,4,4,4,4,4,4,4,0,0
0,14,0,0,0,0,0,0,0,0,0,0,3,0,0,0,0,0,0,0,0,4,0,0
0,14,0,0,0,0,0,0,0,0,0,0,0,0,0,0,0,0,0,0,0,4,0,0
0,4,0,0,0,0,0,0,0,0,0,0,0,0,0,0,0,0,0,0,0,4,0,0
0,3,0,0,0,0,0,0,0,0,0,0,0,0,0,0,0,0,0,0,0,4,0,0
0,4,18,18,18,0,0,0,0,0,0,0,0,0,0,0,0,0,0,0,0,4,0,0
0,4,0,0,26,0,0,0,0,0,0,0,3,0,0,0,0,0,0,0,0,4,0,0
0,4,4,4,4,0,0,0,0,0,0,17,3,0,0,0,0,0,0,0,0,4,0,0
0,4,0,0,25,0,0,0,0,0,0,17,3,4,4,14,14,14,4,24,4,4,0,0
1,3,0,0,3,0,0,0,0,0,0,17,3,0,0,0,0,0,0,0,0,0,0,0
0,4,0,0,3,0,0,0,0,0,0,0,4,0,0,0,0,0,0,0,0,0,0,0
0,4,0,3,0,0,0,0,0,0,0,0,4,0,0,0,0,0,0,0,0,0,0,0
0,4,23,3,0,0,0,0,0,0,0,0,4,0,0,0,0,0,0,0,0,0,0,0
0,4,0,0,0,0,0,0,0,0,0,0,4,0,0,0,0,0,0,0,0,0,0,0
0,4,0,0,0,0,0,0,0,0,0,0,4,0,0,0,0,0,0,0,0,0,0,0
0,4,0,0,0,0,0,0,0,0,0,0,4,0,0,0,0,0,0,0,0,0,0,0
0,14,0,0,0,0,0,0,0,0,0,0,4,0,0,0,0,0,0,0,0,0,0,0
0,4,0,0,0,0,0,0,0,0,0,0,4,0,0,0,0,0,0,0,0,0,0,0
0,14,0,0,0,0,0,0,0,0,0,0,4,0,0,22,0,0,0,0,0,0,0,0
0,4,0,0,0,0,0,0,0,0,0,0,4,0,0,0,0,0,0,0,0,0,0,0
0,14,0,0,0,0,0,0,0,0,0,0,4,0,0,0,0,0,0,0,0,0,0,0
0,4,0,0,0,0,0,0,0,0,0,0,4,0,0,0,0,0,0,0,0,0,0,0
0,14,0,0,0,0,0,0,0,0,0,0,4,0,0,0,0,0,0,0,0,0,0,0
0,4,0,0,0,0,0,0,0,0,0,0,4,0,0,0,0,0,0,0,0,0,0,0
0,3,4,14,4,3,21,20,3,4,14,4,3,0,0,0,0,0,0,0,0,0,0,0
0,0,0,0,0,0,0,0,0,0,0,0,0,0,0,0,0,0,0,0,0,0,0,0
0,0,1,0,0,0,0,0,0,0,0,1,0,0,0,0,0,0,0,0,0,0,0,0
0,0,0,0,0,0,0,0,0,0,0,0,0,0,0,0,0,0,0,0,0,0,0,0
0,0,0,0,0,0,0,0,0,0,0,0,0,0,0,0,0,0,0,0,0,0,0,0
:endlayer
layer: 3
1,0,0,0,0,0,0,0,0,0,0,0,0,1,0,0,0,0,0,0,0,0,0,0
0,3,4,19,19,30,30,30,30,19,19,4,3,0,0,0,0,0,0,0,0,0,0,0
0,4,0,0,0,0,0,0,0,0,0,0,3,4,4,4,4,4,4,4,4,4,0,0
0,14,0,0,0,0,0,0,0,0,0,0,3,0,0,0,0,0,0,0,0,4,0,0
0,14,0,0,0,0,0,0,0,0,0,0,0,0,0,0,0,0,0,0,0,4,0,0
0,4,0,0,0,0,0,0,0,0,0,0,0,0,0,0,0,0,0,0,0,4,0,0
0,3,0,0,0,0,0,0,0,0,0,0,0,0,0,0,0,0,0,0,0,4,0,0
0,4,0,0,0,0,0,0,0,0,0,0,0,0,0,0,0,0,0,0,0,4,0,0
0,4,18,18,18,0,0,0,0,0,0,0,3,0,0,0,0,0,0,0,0,4,0,0
0,4,13,13,13,5,5,5,5,5,5,13,3,0,0,0,0,0,0,0,0,4,0,0
0,4,5,5,13,5,5,5,5,5,5,13,3,4,4,14,14,14,4,4,4,4,0,0
1,3,5,5,13,5,5,5,5,5,5,13,3,0,0,0,0,0,0,0,0,0,0,0
0,4,13,13,0,0,0,0,0,0,5,5,4,0,0,0,0,0,0,0,0,0,0,0
0,4,5,13,0,0,0,0,0,0,5,5,4,0,0,0,0,0,0,0,0,0,0,0
0,4,13,13,0,0,0,0,0,0,5,5,4,0,0,0,0,0,0,0,0,0,0,0
0,4,5,5,0,0,0,0,0,0,5,5,4,0,0,0,0,0,0,0,0,0,0,0
0,4,5,5,0,0,0,0,0,0,5,5,4,0,0,0,0,0,0,0,0,0,0,0
0,4,5,5,0,0,0,0,0,0,5,5,4,0,0,0,0,0,0,0,0,0,0,0
0,4,5,5,0,0,0,0,0,0,5,5,4,0,0,0,0,0,0,0,0,0,0,0
0,4,5,5,0,0,0,0,0,0,5,5,4,0,0,0,0,0,0,0,0,0,0,0
0,4,5,5,0,0,0,0,0,0,5,5,4,0,0,0,0,0,0,0,0,0,0,0
0,4,5,5,0,0,0,0,0,0,5,5,4,0,0,0,0,0,0,0,0,0,0,0
0,4,5,5,0,0,0,0,0,0,5,5,4,0,0,0,0,0,0,0,0,0,0,0
0,4,5,5,5,5,5,5,5,5,5,5,4,0,0,0,0,0,0,0,0,0,0,0
0,4,5,5,5,5,5,5,5,5,5,5,4,0,0,0,0,0,0,0,0,0,0,0
0,4,5,5,5,5,29,29,5,5,5,5,4,0,0,0,0,0,0,0,0,0,0,0
0,3,4,4,4,3,29,28,3,4,4,4,3,0,0,0,0,0,0,0,0,0,0,0
0,5,5,5,5,5,5,5,5,5,5,5,5,0,0,0,0,0,0,0,0,0,0,0
0,5,13,5,5,5,5,5,5,5,5,13,5,0,0,0,0,0,0,0,0,0,0,0
0,0,0,0,0,0,0,0,0,0,0,0,0,0,0,0,0,0,0,0,0,0,0,0
0,0,0,0,0,0,0,0,0,0,0,0,0,0,0,0,0,0,0,0,0,0,0,0
:endlayer
layer: 4
1,0,0,0,0,0,0,0,0,0,0,0,0,1,0,0,0,0,0,0,0,0,0,0
0,3,4,19,19,19,30,30,19,19,19,4,3,0,0,0,0,0,0,0,0,0,0,0
0,4,0,0,0,0,0,0,0,0,0,0,3,4,4,4,4,4,4,4,4,4,0,0
0,14,0,0,0,0,0,0,0,0,0,0,3,0,0,0,0,0,0,0,0,4,0,0
0,14,0,0,0,0,0,0,0,0,0,0,0,0,0,0,0,0,0,0,0,4,0,0
0,4,0,0,0,0,0,0,0,0,0,0,0,0,0,0,0,0,0,0,0,4,0,0
0,3,0,0,0,0,0,0,0,0,0,0,0,0,0,0,0,0,0,0,0,4,0,0
0,4,0,0,0,0,0,0,0,0,0,0,0,0,0,0,0,0,0,0,0,4,0,0
0,4,0,0,0,0,0,0,0,0,0,0,3,0,0,0,0,0,0,0,0,4,0,0
0,4,0,0,0,17,17,17,17,17,17,17,3,0,0,0,0,0,0,0,0,4,0,0
0,4,0,0,0,0,0,0,0,0,0,0,3,4,4,4,4,4,4,4,4,4,0,0
1,3,0,17,17,17,17,17,17,17,17,0,3,0,0,0,0,0,0,0,0,0,0,0
0,4,0,17,0,0,0,0,0,0,17,0,4,0,0,0,0,0,0,0,0,0,0,0
0,4,0,17,0,0,0,0,0,0,17,0,4,0,0,0,0,0,0,0,0,0,0,0
0,4,0,17,0,0,0,0,0,0,17,0,4,0,0,0,0,0,0,0,0,0,0,0
0,4,0,17,0,0,0,0,0,0,17,0,4,0,0,0,0,0,0,0,0,0,0,0
0,4,0,17,0,0,0,0,0,0,17,0,4,0,0,0,0,0,0,0,0,0,0,0
0,4,0,17,0,0,0,0,0,0,17,0,14,0,0,0,0,0,0,0,0,0,0,0
0,4,0,17,0,0,0,0,0,0,17,0,14,0,0,0,0,0,0,0,0,0,0,0
0,4,0,17,0,0,0,0,0,0,17,0,14,0,0,0,0,0,0,0,0,0,0,0
0,4,0,17,0,0,0,0,0,0,17,0,14,0,0,0,0,0,0,0,0,0,0,0
0,14,0,17,0,0,0,0,0,0,17,0,4,0,0,0,0,0,0,0,0,0,0,0
0,14,0,17,0,0,0,0,0,0,17,0,4,0,0,0,0,0,0,0,0,0,0,0
0,14,0,17,17,17,17,17,17,17,17,0,4,0,0,0,0,0,0,0,0,0,0,0
0,4,0,0,0,0,0,0,0,0,0,0,4,0,0,0,0,0,0,0,0,0,0,0
0,4,0,0,0,0,0,0,0,0,0,0,4,0,0,0,0,0,0,0,0,0,0,0
0,3,4,4,33,33,33,33,33,33,4,32,3,0,0,0,0,0,0,0,0,0,0,0
0,31,0,0,0,0,0,0,0,0,0,0,31,0,0,0,0,0,0,0,0,0,0,0
0,31,31,31,31,31,31,31,31,31,31,31,31,0,0,0,0,0,0,0,0,0,0,0
0,0,0,0,0,0,0,0,0,0,0,0,0,0,0,0,0,0,0,0,0,0,0,0
0,0,0,0,0,0,0,0,0,0,0,0,0,0,0,0,0,0,0,0,0,0,0,0
:endlayer
layer: 5
1,0,0,0,0,0,0,0,0,0,0,0,0,1,0,0,0,0,0,0,0,0,0,0
0,3,4,19,19,19,27,27,19,19,19,4,3,3,18,18,18,18,18,18,18,18,0,0
28,4,0,0,0,0,0,0,0,0,0,0,3,4,4,4,4,4,4,4,4,4,0,0
37,14,0,0,0,0,0,0,0,0,0,0,3,0,0,0,0,0,0,0,0,4,0,0
29,14,0,0,0,0,0,0,0,0,0,0,0,0,0,0,0,0,0,0,0,4,0,0
28,4,0,0,0,0,0,0,0,0,0,0,0,0,0,0,0,0,0,0,0,4,0,0
0,3,0,0,0,0,0,0,0,0,0,0,0,0,0,0,0,0,0,0,0,4,0,0
0,4,0,0,0,0,0,0,0,0,0,0,0,0,0,0,0,0,0,0,0,4,0,0
0,4,0,0,0,0,0,0,0,0,0,0,3,0,0,0,0,0,0,0,0,4,0,0
0,4,0,0,0,0,0,0,0,0,0,0,3,0,0,0,0,0,0,0,0,4,0,0
0,4,0,0,0,0,0,0,0,0,0,0,3,4,4,4,4,4,4,4,4,4,0,0
1,3,0,0,0,0,0,0,0,0,0,0,3,36,36,36,36,36,36,36,36,2,0,0
0,4,0,0,0,0,0,0,0,0,0,0,4,0,0,0,0,0,0,0,0,0,0,0
0,4,0,0,0,0,0,0,0,0,0,0,4,0,0,0,0,0,0,0,0,0,0,0
0,4,0,0,0,0,0,0,0,0,0,0,4,0,0,0,0,0,0,0,0,0,0,0
0,4,0,0,0,0,0,0,0,0,0,0,4,0,0,0,0,0,0,0,0,0,0,0
0,4,0,0,0,0,0,0,0,0,0,0,4,0,0,0,0,0,0,0,0,0,0,0
0,4,0,0,0,0,0,0,0,0,0,0,14,0,0,0,0,0,0,0,0,0,0,0
0,4,0,0,0,0,0,0,0,0,0,0,14,0,0,0,0,0,0,0,0,0,0,0
0,4,0,0,0,0,0,0,0,0,0,0,14,0,0,0,0,0,0,0,0,0,0,0
0,4,0,0,0,0,0,0,0,0,0,0,14,0,0,0,0,0,0,0,0,0,0,0
0,14,0,0,0,0,0,0,0,0,0,0,4,0,0,0,0,0,0,0,0,0,0,0
0,14,0,0,0,0,0,0,0,0,0,0,4,0,0,0,0,0,0,0,0,0,0,0
0,14,0,0,0,0,0,0,0,0,0,0,4,0,0,0,0,0,0,0,0,0,0,0
0,4,0,0,0,0,0,0,0,0,0,0,4,0,0,0,0,0,0,0,0,0,0,0
0,4,0,0,0,0,0,0,0,0,35,0,4,0,0,0,0,0,0,0,0,0,0,0
0,3,4,4,33,33,33,33,33,33,4,34,3,0,0,0,0,0,0,0,0,0,0,0
0,0,0,0,0,0,0,0,0,0,0,0,0,0,0,0,0,0,0,0,0,0,0,0
0,0,0,0,0,0,0,0,0,0,0,0,0,0,0,0,0,0,0,0,0,0,0,0
0,0,0,0,0,0,0,0,0,0,0,0,0,0,0,0,0,0,0,0,0,0,0,0
0,0,0,0,0,0,0,0,0,0,0,0,0,0,0,0,0,0,0,0,0,0,0,0
:endlayer
layer: 6
12,0,0,0,0,0,0,0,0,0,0,0,0,11,0,0,0,0,0,0,0,0,0,0
12,3,4,19,27,30,19,19,30,27,19,4,3,11,0,0,0,0,0,0,0,0,0,0
12,4,0,0,0,0,0,0,0,0,0,0,3,39,38,38,38,38,38,38,38,18,0,0
12,4,0,0,0,0,0,0,0,0,0,0,3,0,0,0,0,0,0,0,0,3,0,0
12,4,0,0,0,0,0,0,0,0,0,0,3,0,0,0,0,0,0,0,0,4,0,0
12,4,0,0,0,0,0,0,0,0,0,0,3,0,0,0,0,0,0,0,0,4,0,0
12,3,0,0,0,0,0,0,0,0,0,0,3,0,0,0,0,0,0,0,8,4,0,0
12,4,0,0,0,0,0,0,0,0,0,0,3,0,0,0,0,0,0,0,0,4,0,0
12,4,0,0,0,0,0,0,0,0,0,0,3,0,0,0,0,0,0,0,0,4,0,0
12,4,0,0,0,0,0,0,0,0,0,0,3,0,0,0,0,0,0,0,0,3,0,0
12,4,0,0,0,0,0,0,0,0,0,0,3,36,36,36,36,36,36,36,36,2,0,0
12,3,0,0,0,0,0,0,0,0,0,0,3,0,0,0,0,0,0,0,0,0,0,0
0,4,0,0,0,0,0,0,0,0,0,0,4,0,0,0,0,0,0,0,0,0,0,0
0,4,0,0,0,0,0,0,0,0,0,0,4,0,0,0,0,0,0,0,0,0,0,0
0,4,0,0,0,0,0,0,0,0,0,0,4,0,0,0,0,0,0,0,0,0,0,0
0,4,0,0,0,0,0,0,0,0,0,0,4,0,0,0,0,0,0,0,0,0,0,0
0,4,0,0,0,0,0,0,0,0,0,0,4,0,0,0,0,0,0,0,0,0,0,0
0,4,0,0,0,0,0,0,0,0,0,0,14,0,0,0,0,0,0,0,0,0,0,0
0,4,0,0,0,0,0,0,0,0,0,0,14,0,0,0,0,0,0,0,0,0,0,0
0,4,0,0,0,0,0,0,0,0,0,0,14,0,0,0,0,0,0,0,0,0,0,0
0,4,0,0,0,0,0,0,0,0,0,0,14,0,0,0,0,0,0,0,0,0,0,0
0,4,0,0,0,0,0,0,0,0,0,0,4,0,0,0,0,0,0,0,0,0,0,0
0,4,0,0,0,0,0,0,0,0,0,0,4,0,0,0,0,0,0,0,0,0,0,0
0,4,0,0,0,0,0,0,0,0,0,0,4,0,0,0,0,0,0,0,0,0,0,0
0,4,0,0,0,0,0,0,0,0,0,0,4,0,0,0,0,0,0,0,0,0,0,0
0,4,0,0,0,0,0,0,0,0,0,0,4,0,0,0,0,0,0,0,0,0,0,0
0,3,4,4,33,33,33,33,33,33,4,4,3,0,0,0,0,0,0,0,0,0,0,0
0,0,0,0,0,0,0,0,0,0,0,0,0,0,0,0,0,0,0,0,0,0,0,0
0,0,0,0,0,0,0,0,0,0,0,0,0,0,0,0,0,0,0,0,0,0,0,0
0,0,0,0,0,0,0,0,0,0,0,0,0,0,0,0,0,0,0,0,0,0,0,0
0,0,0,0,0,0,0,0,0,0,0,0,0,0,0,0,0,0,0,0,0,0,0,0
:endlayer
layer: 7
0,12,0,0,0,0,0,0,0,0,0,0,11,0,0,0,0,0,0,0,0,0,0,0
0,12,4,19,27,27,19,19,27,27,19,4,11,0,0,0,0,0,0,0,0,0,0,0
0,40,0,0,0,0,0,0,0,0,0,0,39,0,0,0,0,0,0,0,0,0,0,0
0,40,0,0,0,0,0,0,0,0,0,0,39,38,38,38,38,38,38,38,38,18,0,0
0,40,0,0,0,0,0,0,0,0,0,0,3,0,0,0,0,0,0,0,0,3,0,0
0,40,0,0,0,0,0,0,0,0,0,0,3,0,0,0,0,0,0,0,0,4,0,0
0,40,0,0,0,0,0,0,0,0,0,0,3,0,0,0,0,0,0,0,0,4,0,0
0,40,0,0,0,0,0,0,0,0,0,0,3,0,0,0,0,0,0,0,0,4,0,0
0,40,0,0,0,0,0,0,0,0,0,0,3,0,0,0,0,0,0,0,0,3,0,0
0,40,0,0,0,0,0,0,0,0,0,0,39,36,36,36,36,36,36,36,36,2,0,0
0,40,0,0,0,0,0,0,0,0,0,0,39,0,0,0,0,0,0,0,0,0,0,0
0,40,0,0,0,0,0,0,0,0,0,0,39,0,0,0,0,0,0,0,0,0,0,0
0,40,0,0,0,0,0,0,0,0,0,0,39,0,0,0,0,0,0,0,0,0,0,0
0,40,0,0,0,0,0,0,0,0,0,0,39,0,0,0,0,0,0,0,0,0,0,0
0,40,0,0,0,0,0,0,0,0,0,0,39,0,0,0,0,0,0,0,0,0,0,0
0,40,0,0,0,0,0,0,0,0,0,0,39,0,0,0,0,0,0,0,0,0,0,0
0,40,0,0,0,0,0,0,0,0,0,0,39,0,0,0,0,0,0,0,0,0,0,0
0,40,0,0,0,0,0,0,0,0,0,0,39,0,0,0,0,0,0,0,0,0,0,0
0,40,0,0,0,0,0,0,0,0,0,0,39,0,0,0,0,0,0,0,0,0,0,0
0,40,0,0,0,0,0,0,0,0,0,0,39,0,0,0,0,0,0,0,0,0,0,0
0,40,0,0,0,0,0,0,0,0,0,0,39,0,0,0,0,0,0,0,0,0,0,0
0,40,0,0,0,0,0,0,0,0,0,0,39,0,0,0,0,0,0,0,0,0,0,0
0,40,0,0,0,0,0,0,0,0,0,0,39,0,0,0,0,0,0,0,0,0,0,0
0,40,0,0,0,0,0,0,0,0,0,0,39,0,0,0,0,0,0,0,0,0,0,0
0,40,0,0,0,0,0,0,0,0,0,0,39,0,0,0,0,0,0,0,0,0,0,0
0,40,0,0,0,0,0,0,0,0,0,0,39,0,0,0,0,0,0,0,0,0,0,0
0,12,3,4,33,33,33,33,33,33,4,3,11,0,0,0,0,0,0,0,0,0,0,0
0,12,0,0,0,0,0,0,0,0,0,0,11,0,0,0,0,0,0,0,0,0,0,0
0,0,0,0,0,0,0,0,0,0,0,0,0,0,0,0,0,0,0,0,0,0,0,0
0,0,0,0,0,0,0,0,0,0,0,0,0,0,0,0,0,0,0,0,0,0,0,0
0,0,0,0,0,0,0,0,0,0,0,0,0,0,0,0,0,0,0,0,0,0,0,0
:endlayer
layer: 8
0,0,12,0,0,0,0,0,0,0,0,11,0,0,0,0,0,0,0,0,0,0,0,0
0,0,12,4,19,19,19,19,19,19,4,11,0,0,0,0,0,0,0,0,0,0,0,0
0,0,40,0,0,0,0,0,0,0,0,39,0,0,0,0,0,0,0,0,0,0,0,0
0,0,40,0,0,0,0,0,0,0,0,39,0,0,0,0,0,0,0,0,0,0,0,0
0,0,40,0,0,0,0,0,0,0,0,39,38,38,38,38,38,38,38,38,38,18,0,0
0,0,40,0,0,0,0,0,0,0,0,0,3,0,0,0,0,0,0,0,0,3,0,0
0,0,40,0,0,0,0,0,0,0,0,0,3,0,0,0,0,0,0,0,0,4,0,0
0,0,40,0,0,0,0,0,0,0,0,0,3,0,0,0,0,0,0,0,0,3,0,0
0,0,40,0,0,0,0,0,0,0,0,36,36,36,36,36,36,36,36,36,36,2,0,0
0,0,40,0,0,0,0,0,0,0,0,39,0,0,0,0,0,0,0,0,0,0,0,0
0,0,40,0,0,0,0,0,0,0,0,39,0,0,0,0,0,0,0,0,0,0,0,0
0,0,40,0,0,0,0,0,0,0,0,39,0,0,0,0,0,0,0,0,0,0,0,0
0,0,40,0,0,0,0,0,0,0,0,39,0,0,0,0,0,0,0,0,0,0,0,0
0,0,40,0,0,0,0,0,0,0,0,39,0,0,0,0,0,0,0,0,0,0,0,0
0,0,40,0,0,0,0,0,0,0,0,39,0,0,0,0,0,0,0,0,0,0,0,0
0,0,40,0,0,0,0,0,0,0,0,39,0,0,0,0,0,0,0,0,0,0,0,0
0,0,40,0,0,0,0,0,0,0,0,39,0,0,0,0,0,0,0,0,0,0,0,0
0,0,40,0,0,0,0,0,0,0,0,39,0,0,0,0,0,0,0,0,0,0,0,0
0,0,40,0,0,0,0,0,0,0,0,39,0,0,0,0,0,0,0,0,0,0,0,0
0,0,40,0,0,0,0,0,0,0,0,39,0,0,0,0,0,0,0,0,0,0,0,0
0,0,40,0,0,0,0,0,0,0,0,39,0,0,0,0,0,0,0,0,0,0,0,0
0,0,40,0,0,0,0,0,0,0,0,39,0,0,0,0,0,0,0,0,0,0,0,0
0,0,40,0,0,0,0,0,0,0,0,39,0,0,0,0,0,0,0,0,0,0,0,0
0,0,40,0,0,0,0,0,0,0,0,39,0,0,0,0,0,0,0,0,0,0,0,0
0,0,40,0,0,0,0,0,0,0,0,39,0,0,0,0,0,0,0,0,0,0,0,0
0,0,40,0,0,0,0,0,0,0,0,39,0,0,0,0,0,0,0,0,0,0,0,0
0,0,12,4,33,33,33,33,33,33,4,11,0,0,0,0,0,0,0,0,0,0,0,0
0,0,12,0,0,0,0,0,0,0,0,11,0,0,0,0,0,0,0,0,0,0,0,0
0,0,0,0,0,0,0,0,0,0,0,0,0,0,0,0,0,0,0,0,0,0,0,0
0,0,0,0,0,0,0,0,0,0,0,0,0,0,0,0,0,0,0,0,0,0,0,0
0,0,0,0,0,0,0,0,0,0,0,0,0,0,0,0,0,0,0,0,0,0,0,0
:endlayer
layer: 9
0,0,0,12,0,0,0,0,0,0,11,0,0,0,0,0,0,0,0,0,0,0,0,0
0,0,0,12,4,19,19,19,19,4,11,0,0,0,0,0,0,0,0,0,0,0,0,0
0,0,0,40,0,0,0,0,0,0,39,0,0,0,0,0,0,0,0,0,0,0,0,0
0,0,0,40,0,0,0,0,0,0,39,0,0,0,0,0,0,0,0,0,0,0,0,0
0,0,0,40,0,0,0,0,0,0,39,0,0,0,0,0,0,0,0,0,0,0,0,0
0,0,0,40,0,0,0,0,0,0,38,38,38,38,38,38,38,38,38,38,38,18,0,0
0,0,0,40,0,0,0,0,0,0,3,3,3,3,3,3,3,3,3,3,3,3,0,0
0,0,0,40,0,0,0,0,0,0,39,36,36,36,36,36,36,36,36,36,36,2,0,0
0,0,0,40,0,0,0,0,0,0,39,0,0,0,0,0,0,0,0,0,0,0,0,0
0,0,0,40,0,0,0,0,0,0,39,0,0,0,0,0,0,0,0,0,0,0,0,0
0,0,0,40,0,0,0,0,0,0,39,0,0,0,0,0,0,0,0,0,0,0,0,0
0,0,0,40,0,0,0,0,0,0,39,0,0,0,0,0,0,0,0,0,0,0,0,0
0,0,0,40,0,0,0,0,0,0,39,0,0,0,0,0,0,0,0,0,0,0,0,0
0,0,0,40,0,0,0,0,0,0,39,0,0,0,0,0,0,0,0,0,0,0,0,0
0,0,0,40,0,0,0,0,0,0,39,0,0,0,0,0,0,0,0,0,0,0,0,0
0,0,0,40,0,0,0,0,0,0,39,0,0,0,0,0,0,0,0,0,0,0,0,0
0,0,0,40,0,0,0,0,0,0,39,0,0,0,0,0,0,0,0,0,0,0,0,0
0,0,0,40,0,0,0,0,0,0,39,0,0,0,0,0,0,0,0,0,0,0,0,0
0,0,0,40,0,0,0,0,0,0,39,0,0,0,0,0,0,0,0,0,0,0,0,0
0,0,0,40,0,0,0,0,0,0,39,0,0,0,0,0,0,0,0,0,0,0,0,0
0,0,0,40,0,0,0,0,0,0,39,0,0,0,0,0,0,0,0,0,0,0,0,0
0,0,0,40,0,0,0,0,0,0,39,0,0,0,0,0,0,0,0,0,0,0,0,0
0,0,0,40,0,0,0,0,0,0,39,0,0,0,0,0,0,0,0,0,0,0,0,0
0,0,0,40,0,0,0,0,0,0,39,0,0,0,0,0,0,0,0,0,0,0,0,0
0,0,0,40,0,0,0,0,0,0,39,0,0,0,0,0,0,0,0,0,0,0,0,0
0,0,0,40,0,0,0,0,0,0,39,0,0,0,0,0,0,0,0,0,0,0,0,0
0,0,0,12,4,33,33,33,33,4,11,0,0,0,0,0,0,0,0,0,0,0,0,0
0,0,0,12,0,0,0,0,0,0,11,0,0,0,0,0,0,0,0,0,0,0,0,0
0,0,0,0,0,0,0,0,0,0,0,0,0,0,0,0,0,0,0,0,0,0,0,0
0,0,0,0,0,0,0,0,0,0,0,0,0,0,0,0,0,0,0,0,0,0,0,0
0,0,0,0,0,0,0,0,0,0,0,0,0,0,0,0,0,0,0,0,0,0,0,0
:endlayer
layer: 10
0,0,0,0,12,0,0,0,0,11,0,0,0,0,0,0,0,0,0,0,0,0,0,0
0,0,0,0,12,4,4,4,4,11,0,0,0,0,0,0,0,0,0,0,0,0,0,0
0,0,0,0,40,0,0,0,0,39,0,0,0,0,0,0,0,0,0,0,0,0,0,0
0,0,0,0,40,0,0,0,0,39,0,0,0,0,0,0,0,0,0,0,0,0,0,0
0,0,0,0,40,0,0,0,0,39,0,0,0,0,0,0,0,0,0,0,0,0,0,0
0,0,0,0,40,0,0,0,0,39,0,0,0,0,0,0,0,0,0,0,0,0,0,0
0,0,0,0,40,0,0,0,0,39,41,41,41,41,41,41,41,41,41,41,41,3,0,0
0,0,0,0,40,0,0,0,0,39,0,0,0,0,0,0,0,0,0,0,0,0,0,0
0,0,0,0,40,0,0,0,0,39,0,0,0,0,0,0,0,0,0,0,0,0,0,0
0,0,0,0,40,0,0,0,0,39,0,0,0,0,0,0,0,0,0,0,0,0,0,0
0,0,0,0,40,0,0,0,0,39,0,0,0,0,0,0,0,0,0,0,0,0,0,0
0,0,0,0,40,0,0,0,0,39,0,0,0,0,0,0,0,0,0,0,0,0,0,0
0,0,0,0,40,0,0,0,0,39,0,0,0,0,0,0,0,0,0,0,0,0,0,0
0,0,0,0,40,0,0,0,0,39,0,0,0,0,0,0,0,0,0,0,0,0,0,0
0,0,0,0,40,0,0,0,0,39,0,0,0,0,0,0,0,0,0,0,0,0,0,0
0,0,0,0,40,0,0,0,0,39,0,0,0,0,0,0,0,0,0,0,0,0,0,0
0,0,0,0,40,0,0,0,0,39,0,0,0,0,0,0,0,0,0,0,0,0,0,0
0,0,0,0,40,0,0,0,0,39,0,0,0,0,0,0,0,0,0,0,0,0,0,0
0,0,0,0,40,0,0,0,0,39,0,0,0,0,0,0,0,0,0,0,0,0,0,0
0,0,0,0,40,0,0,0,0,39,0,0,0,0,0,0,0,0,0,0,0,0,0,0
0,0,0,0,40,0,0,0,0,39,0,0,0,0,0,0,0,0,0,0,0,0,0,0
0,0,0,0,40,0,0,0,0,39,0,0,0,0,0,0,0,0,0,0,0,0,0,0
0,0,0,0,40,0,0,0,0,39,0,0,0,0,0,0,0,0,0,0,0,0,0,0
0,0,0,0,40,0,0,0,0,39,0,0,0,0,0,0,0,0,0,0,0,0,0,0
0,0,0,0,40,0,0,0,0,39,0,0,0,0,0,0,0,0,0,0,0,0,0,0
0,0,0,0,40,0,0,0,0,39,0,0,0,0,0,0,0,0,0,0,0,0,0,0
0,0,0,0,12,4,33,33,4,11,0,0,0,0,0,0,0,0,0,0,0,0,0,0
0,0,0,0,12,0,0,0,0,11,0,0,0,0,0,0,0,0,0,0,0,0,0,0
0,0,0,0,0,0,0,0,0,0,0,0,0,0,0,0,0,0,0,0,0,0,0,0
0,0,0,0,0,0,0,0,0,0,0,0,0,0,0,0,0,0,0,0,0,0,0,0
0,0,0,0,0,0,0,0,0,0,0,0,0,0,0,0,0,0,0,0,0,0,0,0
:endlayer
layer: 11
0,0,0,0,0,12,0,0,11,0,0,0,0,0,0,0,0,0,0,0,0,0,0,0
0,0,0,0,0,12,4,4,11,0,0,0,0,0,0,0,0,0,0,0,0,0,0,0
0,0,0,0,0,40,42,28,39,0,0,0,0,0,0,0,0,0,0,0,0,0,0,0
0,0,0,0,0,40,42,28,39,0,0,0,0,0,0,0,0,0,0,0,0,0,0,0
0,0,0,0,0,40,42,28,39,0,0,0,0,0,0,0,0,0,0,0,0,0,0,0
0,0,0,0,0,40,42,28,39,0,0,0,0,0,0,0,0,0,0,0,0,0,0,0
0,0,0,0,0,40,42,28,39,0,0,0,0,0,0,0,0,0,0,0,0,0,0,0
0,0,0,0,0,40,42,28,39,0,0,0,0,0,0,0,0,0,0,0,0,0,0,0
0,0,0,0,0,40,42,28,39,0,0,0,0,0,0,0,0,0,0,0,0,0,0,0
0,0,0,0,0,40,42,28,39,0,0,0,0,0,0,0,0,0,0,0,0,0,0,0
0,0,0,0,0,40,42,28,39,0,0,0,0,0,0,0,0,0,0,0,0,0,0,0
0,0,0,0,0,40,42,28,39,0,0,0,0,0,0,0,0,0,0,0,0,0,0,0
0,0,0,0,0,40,42,28,39,0,0,0,0,0,0,0,0,0,0,0,0,0,0,0
0,0,0,0,0,40,42,28,39,0,0,0,0,0,0,0,0,0,0,0,0,0,0,0
0,0,0,0,0,40,42,28,39,0,0,0,0,0,0,0,0,0,0,0,0,0,0,0
0,0,0,0,0,40,42,28,39,0,0,0,0,0,0,0,0,0,0,0,0,0,0,0
0,0,0,0,0,40,42,28,39,0,0,0,0,0,0,0,0,0,0,0,0,0,0,0
0,0,0,0,0,40,42,28,39,0,0,0,0,0,0,0,0,0,0,0,0,0,0,0
0,0,0,0,0,40,42,28,39,0,0,0,0,0,0,0,0,0,0,0,0,0,0,0
0,0,0,0,0,40,42,28,39,0,0,0,0,0,0,0,0,0,0,0,0,0,0,0
0,0,0,0,0,40,42,28,39,0,0,0,0,0,0,0,0,0,0,0,0,0,0,0
0,0,0,0,0,40,42,28,39,0,0,0,0,0,0,0,0,0,0,0,0,0,0,0
0,0,0,0,0,40,42,28,39,0,0,0,0,0,0,0,0,0,0,0,0,0,0,0
0,0,0,0,0,40,42,28,39,0,0,0,0,0,0,0,0,0,0,0,0,0,0,0
0,0,0,0,0,40,42,28,39,0,0,0,0,0,0,0,0,0,0,0,0,0,0,0
0,0,0,0,0,40,42,28,39,0,0,0,0,0,0,0,0,0,0,0,0,0,0,0
0,0,0,0,0,12,3,3,11,0,0,0,0,0,0,0,0,0,0,0,0,0,0,0
0,0,0,0,0,12,0,0,11,0,0,0,0,0,0,0,0,0,0,0,0,0,0,0
0,0,0,0,0,0,0,0,0,0,0,0,0,0,0,0,0,0,0,0,0,0,0,0
0,0,0,0,0,0,0,0,0,0,0,0,0,0,0,0,0,0,0,0,0,0,0,0
0,0,0,0,0,0,0,0,0,0,0,0,0,0,0,0,0,0,0,0,0,0,0,0
:endlayer
layer: 12
0,0,0,0,0,0,12,11,0,0,0,0,0,0,0,0,0,0,0,0,0,0,0,0
0,0,0,0,0,0,12,11,0,0,0,0,0,0,0,0,0,0,0,0,0,0,0,0
0,0,0,0,0,0,12,11,0,0,0,0,0,0,0,0,0,0,0,0,0,0,0,0
0,0,0,0,0,0,12,11,0,0,0,0,0,0,0,0,0,0,0,0,0,0,0,0
0,0,0,0,0,0,12,11,0,0,0,0,0,0,0,0,0,0,0,0,0,0,0,0
0,0,0,0,0,0,12,11,0,0,0,0,0,0,0,0,0,0,0,0,0,0,0,0
0,0,0,0,0,0,12,11,0,0,0,0,0,0,0,0,0,0,0,0,0,0,0,0
0,0,0,0,0,0,12,11,0,0,0,0,0,0,0,0,0,0,0,0,0,0,0,0
0,0,0,0,0,0,12,11,0,0,0,0,0,0,0,0,0,0,0,0,0,0,0,0
0,0,0,0,0,0,12,11,0,0,0,0,0,0,0,0,0,0,0,0,0,0,0,0
0,0,0,0,0,0,12,11,0,0,0,0,0,0,0,0,0,0,0,0,0,0,0,0
0,0,0,0,0,0,12,11,0,0,0,0,0,0,0,0,0,0,0,0,0,0,0,0
0,0,0,0,0,0,12,11,0,0,0,0,0,0,0,0,0,0,0,0,0,0,0,0
0,0,0,0,0,0,12,11,0,0,0,0,0,0,0,0,0,0,0,0,0,0,0,0
0,0,0,0,0,0,12,11,0,0,0,0,0,0,0,0,0,0,0,0,0,0,0,0
0,0,0,0,0,0,12,11,0,0,0,0,0,0,0,0,0,0,0,0,0,0,0,0
0,0,0,0,0,0,12,11,0,0,0,0,0,0,0,0,0,0,0,0,0,0,0,0
0,0,0,0,0,0,12,11,0,0,0,0,0,0,0,0,0,0,0,0,0,0,0,0
0,0,0,0,0,0,12,11,0,0,0,0,0,0,0,0,0,0,0,0,0,0,0,0
0,0,0,0,0,0,12,11,0,0,0,0,0,0,0,0,0,0,0,0,0,0,0,0
0,0,0,0,0,0,12,11,0,0,0,0,0,0,0,0,0,0,0,0,0,0,0,0
0,0,0,0,0,0,12,11,0,0,0,0,0,0,0,0,0,0,0,0,0,0,0,0
0,0,0,0,0,0,12,11,0,0,0,0,0,0,0,0,0,0,0,0,0,0,0,0
0,0,0,0,0,0,12,11,0,0,0,0,0,0,0,0,0,0,0,0,0,0,0,0
0,0,0,0,0,0,12,11,0,0,0,0,0,0,0,0,0,0,0,0,0,0,0,0
0,0,0,0,0,0,12,11,0,0,0,0,0,0,0,0,0,0,0,0,0,0,0,0
0,0,0,0,0,0,12,11,0,0,0,0,0,0,0,0,0,0,0,0,0,0,0,0
0,0,0,0,0,0,2,2,0,0,0,0,0,0,0,0,0,0,0,0,0,0,0,0
0,0,0,0,0,0,0,0,0,0,0,0,0,0,0,0,0,0,0,0,0,0,0,0
0,0,0,0,0,0,0,0,0,0,0,0,0,0,0,0,0,0,0,0,0,0,0,0
0,0,0,0,0,0,0,0,0,0,0,0,0,0,0,0,0,0,0,0,0,0,0,0
:endlayer

#### RULES ####
rule:
plugin=vanillaBlocks
number=1
data:
JSON:{{"val":{"buildPass":{"val":"0","id":"pi"},"blockName":{"val":"minecraft:cobblestone_wall","id":"ss"},"meta":{"val":"0","id":"pi"}},"id":"ct"}}
:enddata
:endrule

rule:
plugin=vanillaBlocks
number=2
data:
JSON:{{"val":{"buildPass":{"val":"0","id":"pi"},"blockName":{"val":"minecraft:stone_brick_stairs","id":"ss"},"meta":{"val":"3","id":"pi"}},"id":"ct"}}
:enddata
:endrule

rule:
plugin=vanillaBlocks
number=3
data:
JSON:{{"val":{"buildPass":{"val":"0","id":"pi"},"blockName":{"val":"minecraft:stonebrick","id":"ss"},"meta":{"val":"0","id":"pi"}},"id":"ct"}}
:enddata
:endrule

rule:
plugin=vanillaBlocks
number=4
data:
JSON:{{"val":{"buildPass":{"val":"0","id":"pi"},"blockName":{"val":"minecraft:stonebrick","id":"ss"},"meta":{"val":"2","id":"pi"}},"id":"ct"}}
:enddata
:endrule

rule:
plugin=vanillaBlocks
number=5
data:
JSON:{{"val":{"buildPass":{"val":"0","id":"pi"},"blockName":{"val":"minecraft:stone_slab","id":"ss"},"meta":{"val":"8","id":"pi"}},"id":"ct"}}
:enddata
:endrule

rule:
plugin=vanillaBlocks
number=6
data:
JSON:{{"val":{"buildPass":{"val":"0","id":"pi"},"blockName":{"val":"minecraft:wool","id":"ss"},"meta":{"val":"13","id":"pi"}},"id":"ct"}}
:enddata
:endrule

rule:
plugin=vanillaBlocks
number=7
data:
JSON:{{"val":{"buildPass":{"val":"0","id":"pi"},"blockName":{"val":"minecraft:fence_gate","id":"ss"},"meta":{"val":"0","id":"pi"}},"id":"ct"}}
:enddata
:endrule

rule:
plugin=vanillaBlocks
number=8
data:
JSON:{{"val":{"buildPass":{"val":"0","id":"pi"},"blockName":{"val":"minecraft:fence","id":"ss"},"meta":{"val":"0","id":"pi"}},"id":"ct"}}
:enddata
:endrule

rule:
plugin=vanillaBlocks
number=9
data:
JSON:{{"val":{"buildPass":{"val":"0","id":"pi"},"blockName":{"val":"minecraft:sapling","id":"ss"},"meta":{"val":"1","id":"pi"}},"id":"ct"}}
:enddata
:endrule

rule:
plugin=vanillaBlocks
number=10
data:
JSON:{{"val":{"buildPass":{"val":"0","id":"pi"},"blockName":{"val":"minecraft:fence_gate","id":"ss"},"meta":{"val":"3","id":"pi"}},"id":"ct"}}
:enddata
:endrule

rule:
plugin=vanillaBlocks
number=11
data:
JSON:{{"val":{"buildPass":{"val":"0","id":"pi"},"blockName":{"val":"minecraft:stone_brick_stairs","id":"ss"},"meta":{"val":"1","id":"pi"}},"id":"ct"}}
:enddata
:endrule

rule:
plugin=vanillaBlocks
number=12
data:
JSON:{{"val":{"buildPass":{"val":"0","id":"pi"},"blockName":{"val":"minecraft:stone_brick_stairs","id":"ss"},"meta":{"val":"0","id":"pi"}},"id":"ct"}}
:enddata
:endrule

rule:
plugin=vanillaBlocks
number=13
data:
JSON:{{"val":{"buildPass":{"val":"0","id":"pi"},"blockName":{"val":"minecraft:double_stone_slab","id":"ss"},"meta":{"val":"0","id":"pi"}},"id":"ct"}}
:enddata
:endrule

rule:
plugin=vanillaBlocks
number=14
data:
JSON:{{"val":{"buildPass":{"val":"0","id":"pi"},"blockName":{"val":"minecraft:glass_pane","id":"ss"},"meta":{"val":"0","id":"pi"}},"id":"ct"}}
:enddata
:endrule

rule:
plugin=vanillaDoors
number=15
data:
JSON:{{"val":{"buildPass":{"val":"2","id":"pi"},"blockName":{"val":"minecraft:wooden_door","id":"ss"},"meta":{"val":"5","id":"pi"},"sideFlag":{"val":"8","id":"pb"}},"id":"ct"}}
:enddata
:endrule

rule:
plugin=vanillaDoors
number=16
data:
JSON:{{"val":{"buildPass":{"val":"2","id":"pi"},"blockName":{"val":"minecraft:wooden_door","id":"ss"},"meta":{"val":"5","id":"pi"},"sideFlag":{"val":"9","id":"pb"}},"id":"ct"}}
:enddata
:endrule

rule:
plugin=vanillaBlocks
number=17
data:
JSON:{{"val":{"buildPass":{"val":"0","id":"pi"},"blockName":{"val":"minecraft:nether_brick_fence","id":"ss"},"meta":{"val":"0","id":"pi"}},"id":"ct"}}
:enddata
:endrule

rule:
plugin=vanillaBlocks
number=18
data:
JSON:{{"val":{"buildPass":{"val":"0","id":"pi"},"blockName":{"val":"minecraft:stone_brick_stairs","id":"ss"},"meta":{"val":"2","id":"pi"}},"id":"ct"}}
:enddata
:endrule

rule:
plugin=vanillaBlocks
number=19
data:
JSON:{{"val":{"buildPass":{"val":"0","id":"pi"},"blockName":{"val":"minecraft:stained_glass_pane","id":"ss"},"meta":{"val":"13","id":"pi"}},"id":"ct"}}
:enddata
:endrule

rule:
plugin=vanillaDoors
number=20
data:
JSON:{{"val":{"buildPass":{"val":"2","id":"pi"},"blockName":{"val":"minecraft:wooden_door","id":"ss"},"meta":{"val":"8","id":"pi"},"sideFlag":{"val":"0","id":"pb"}},"id":"ct"}}
:enddata
:endrule

rule:
plugin=vanillaDoors
number=21
data:
JSON:{{"val":{"buildPass":{"val":"2","id":"pi"},"blockName":{"val":"minecraft:wooden_door","id":"ss"},"meta":{"val":"9","id":"pi"},"sideFlag":{"val":"0","id":"pb"}},"id":"ct"}}
:enddata
:endrule

rule:
plugin=vanillaBlocks
number=22
data:
JSON:{{"val":{"buildPass":{"val":"0","id":"pi"},"blockName":{"val":"minecraft:glowstone","id":"ss"},"meta":{"val":"0","id":"pi"}},"id":"ct"}}
:enddata
:endrule

rule:
plugin=vanillaDoors
number=23
data:
JSON:{{"val":{"buildPass":{"val":"2","id":"pi"},"blockName":{"val":"minecraft:wooden_door","id":"ss"},"meta":{"val":"8","id":"pi"},"sideFlag":{"val":"0","id":"pb"}},"id":"ct"}}
:enddata
:endrule

rule:
plugin=vanillaDoors
number=24
data:
JSON:{{"val":{"buildPass":{"val":"2","id":"pi"},"blockName":{"val":"minecraft:wooden_door","id":"ss"},"meta":{"val":"8","id":"pi"},"sideFlag":{"val":"0","id":"pb"}},"id":"ct"}}
:enddata
:endrule

rule:
plugin=vanillaDoors
number=25
data:
JSON:{{"val":{"buildPass":{"val":"2","id":"pi"},"blockName":{"val":"minecraft:wooden_door","id":"ss"},"meta":{"val":"8","id":"pi"},"sideFlag":{"val":"0","id":"pb"}},"id":"ct"}}
:enddata
:endrule

rule:
plugin=vanillaDoors
number=26
data:
JSON:{{"val":{"buildPass":{"val":"2","id":"pi"},"blockName":{"val":"minecraft:wooden_door","id":"ss"},"meta":{"val":"8","id":"pi"},"sideFlag":{"val":"0","id":"pb"}},"id":"ct"}}
:enddata
:endrule

rule:
plugin=vanillaBlocks
number=27
data:
JSON:{{"val":{"buildPass":{"val":"0","id":"pi"},"blockName":{"val":"minecraft:stained_glass_pane","id":"ss"},"meta":{"val":"7","id":"pi"}},"id":"ct"}}
:enddata
:endrule

rule:
plugin=vanillaBlocks
number=28
data:
JSON:{{"val":{"buildPass":{"val":"0","id":"pi"},"blockName":{"val":"minecraft:stone_brick_stairs","id":"ss"},"meta":{"val":"4","id":"pi"}},"id":"ct"}}
:enddata
:endrule

rule:
plugin=vanillaBlocks
number=29
data:
JSON:{{"val":{"buildPass":{"val":"0","id":"pi"},"blockName":{"val":"minecraft:stone_brick_stairs","id":"ss"},"meta":{"val":"6","id":"pi"}},"id":"ct"}}
:enddata
:endrule

rule:
plugin=vanillaBlocks
number=30
data:
JSON:{{"val":{"buildPass":{"val":"0","id":"pi"},"blockName":{"val":"minecraft:stained_glass_pane","id":"ss"},"meta":{"val":"15","id":"pi"}},"id":"ct"}}
:enddata
:endrule

rule:
plugin=vanillaBlocks
number=31
data:
JSON:{{"val":{"buildPass":{"val":"0","id":"pi"},"blockName":{"val":"minecraft:iron_bars","id":"ss"},"meta":{"val":"0","id":"pi"}},"id":"ct"}}
:enddata
:endrule

rule:
plugin=vanillaDoors
number=32
data:
JSON:{{"val":{"buildPass":{"val":"2","id":"pi"},"blockName":{"val":"minecraft:iron_door","id":"ss"},"meta":{"val":"1","id":"pi"},"sideFlag":{"val":"8","id":"pb"}},"id":"ct"}}
:enddata
:endrule

rule:
plugin=vanillaBlocks
number=33
data:
JSON:{{"val":{"buildPass":{"val":"0","id":"pi"},"blockName":{"val":"minecraft:stained_glass_pane","id":"ss"},"meta":{"val":"0","id":"pi"}},"id":"ct"}}
:enddata
:endrule

rule:
plugin=vanillaDoors
number=34
data:
JSON:{{"val":{"buildPass":{"val":"2","id":"pi"},"blockName":{"val":"minecraft:iron_door","id":"ss"},"meta":{"val":"8","id":"pi"},"sideFlag":{"val":"0","id":"pb"}},"id":"ct"}}
:enddata
:endrule

rule:
plugin=vanillaBlocks
number=35
data:
JSON:{{"val":{"buildPass":{"val":"2","id":"pi"},"blockName":{"val":"minecraft:stone_button","id":"ss"},"meta":{"val":"4","id":"pi"}},"id":"ct"}}
:enddata
:endrule

rule:
plugin=vanillaBlocks
number=36
data:
JSON:{{"val":{"buildPass":{"val":"0","id":"pi"},"blockName":{"val":"minecraft:birch_stairs","id":"ss"},"meta":{"val":"3","id":"pi"}},"id":"ct"}}
:enddata
:endrule

rule:
plugin=vanillaBlocks
number=37
data:
JSON:{{"val":{"buildPass":{"val":"0","id":"pi"},"blockName":{"val":"minecraft:stone_brick_stairs","id":"ss"},"meta":{"val":"7","id":"pi"}},"id":"ct"}}
:enddata
:endrule

rule:
plugin=vanillaBlocks
number=38
data:
JSON:{{"val":{"buildPass":{"val":"0","id":"pi"},"blockName":{"val":"minecraft:birch_stairs","id":"ss"},"meta":{"val":"2","id":"pi"}},"id":"ct"}}
:enddata
:endrule

rule:
plugin=vanillaBlocks
number=39
data:
JSON:{{"val":{"buildPass":{"val":"0","id":"pi"},"blockName":{"val":"minecraft:birch_stairs","id":"ss"},"meta":{"val":"1","id":"pi"}},"id":"ct"}}
:enddata
:endrule

rule:
plugin=vanillaBlocks
number=40
data:
JSON:{{"val":{"buildPass":{"val":"0","id":"pi"},"blockName":{"val":"minecraft:birch_stairs","id":"ss"},"meta":{"val":"0","id":"pi"}},"id":"ct"}}
:enddata
:endrule

rule:
plugin=vanillaBlocks
number=41
data:
JSON:{{"val":{"buildPass":{"val":"0","id":"pi"},"blockName":{"val":"minecraft:wooden_slab","id":"ss"},"meta":{"val":"2","id":"pi"}},"id":"ct"}}
:enddata
:endrule

rule:
plugin=vanillaBlocks
number=42
data:
JSON:{{"val":{"buildPass":{"val":"0","id":"pi"},"blockName":{"val":"minecraft:stone_brick_stairs","id":"ss"},"meta":{"val":"5","id":"pi"}},"id":"ct"}}
:enddata
:endrule

#### ENTITIES ####
entity:
plugin=vanillaLogicEntity
number=0
data:
position=0,0,6
JSON:{{"val":{"xOffset":{"val":"0.6496006","id":"pf"},"equipmentData":{"val":{"length":{"val":"5","id":"pi"},"equipmentContents":{"val":[],"id":"ls"}},"id":"ct"},"rotation":{"val":"-198.05054","id":"pf"},"mobID":{"val":"Villager","id":"ss"},"zOffset":{"val":"0.77895314","id":"pf"},"entityData":{"val":{"ForgeData":{"val":{},"id":"ct"},"Attributes":{"val":[{"val":{"Base":{"val":"20.0","id":"pd"},"Name":{"val":"generic.maxHealth","id":"ss"}},"id":"ct"},{"val":{"Base":{"val":"0.0","id":"pd"},"Name":{"val":"generic.knockbackResistance","id":"ss"}},"id":"ct"},{"val":{"Base":{"val":"0.5","id":"pd"},"Name":{"val":"generic.movementSpeed","id":"ss"}},"id":"ct"},{"val":{"Base":{"val":"16.0","id":"pd"},"Modifiers":{"val":[{"val":{"UUIDMost":{"val":"-958897157259440800","id":"pl"},"UUIDLeast":{"val":"-5037282993589708532","id":"pl"},"Amount":{"val":"-0.03319753866904584","id":"pd"},"Operation":{"val":"1","id":"pi"},"Name":{"val":"Random spawn bonus","id":"ss"}},"id":"ct"}],"id":"ls"},"Name":{"val":"generic.followRange","id":"ss"}},"id":"ct"}],"id":"ls"},"Riches":{"val":"0","id":"pi"},"Invulnerable":{"val":"0","id":"pb"},"VNExtendedVillager":{"val":{"SkinTone":{"val":"0","id":"pi"},"BiomeType":{"val":"0","id":"pi"},"Defined":{"val":"0","id":"pb"},"ProfessionLevel":{"val":"1","id":"pi"},"Career":{"val":"-1","id":"pi"}},"id":"ct"},"PortalCooldown":{"val":"0","id":"pi"},"AbsorptionAmount":{"val":"0.0","id":"pf"},"FallDistance":{"val":"0.0","id":"pf"},"HbmLivingProps":{"val":{"hfr_activation":{"val":"0.0","id":"pf"},"hfr_oxygen":{"val":"100","id":"pi"},"hfr_asbestos":{"val":"0","id":"pi"},"hfr_radiation":{"val":"9.286184E-13","id":"pf"},"hfr_blacklung":{"val":"0","id":"pi"},"hfr_bomb":{"val":"0","id":"pi"},"hfr_digamma":{"val":"0.0","id":"pf"},"hfr_contagion":{"val":"0","id":"pi"},"hfr_oil":{"val":"0","id":"pi"},"hfr_gravity":{"val":"1","id":"pb"},"hfr_cont_count":{"val":"0","id":"pi"}},"id":"ct"},"DeathTime":{"val":"0","id":"ps"},"DropChances":{"val":[{"val":"0.085","id":"pf"},{"val":"0.085","id":"pf"},{"val":"0.085","id":"pf"},{"val":"0.085","id":"pf"},{"val":"0.085","id":"pf"}],"id":"ls"},"PersistenceRequired":{"val":"0","id":"pb"},"HealF":{"val":"20.0","id":"pf"},"archTimeToReset":{"val":"0","id":"pi"},"Age":{"val":"0","id":"pi"},"Motion":{"val":[{"val":"0.0","id":"pd"},{"val":"-0.0784000015258789","id":"pd"},{"val":"0.0","id":"pd"}],"id":"ls"},"Leashed":{"val":"0","id":"pb"},"Health":{"val":"20","id":"ps"},"Air":{"val":"300","id":"ps"},"OnGround":{"val":"1","id":"pb"},"Dimension":{"val":"0","id":"pi"},"Offers":{"val":{"Recipes":{"val":[{"val":{"maxUses":{"val":"7","id":"pi"},"buy":{"val":{"id":{"val":"388","id":"ps"},"Count":{"val":"16","id":"pb"},"Damage":{"val":"0","id":"ps"}},"id":"ct"},"sell":{"val":{"id":{"val":"7054","id":"ps"},"Count":{"val":"1","id":"pb"},"Damage":{"val":"2","id":"ps"}},"id":"ct"},"uses":{"val":"0","id":"pi"}},"id":"ct"}],"id":"ls"}},"id":"ct"},"Rotation":{"val":[{"val":"-738.05054","id":"pf"},{"val":"0.0","id":"pf"}],"id":"ls"},"Profession":{"val":"512","id":"pi"},"CustomName":{"val":"","id":"ss"},"Pos":{"val":[{"val":"435.3503993661169","id":"pd"},{"val":"13.0","id":"pd"},{"val":"-360.778953156281","id":"pd"}],"id":"ls"},"Fire":{"val":"-1","id":"ps"},"CanPickUpLoot":{"val":"0","id":"pb"},"HurtTime":{"val":"0","id":"ps"},"AttackTime":{"val":"0","id":"ps"},"CustomNameVisible":{"val":"0","id":"pb"}},"id":"ct"}},"id":"ct"}}
:enddata
:endentity

entity:
plugin=vanillaLogicEntity
number=1
data:
position=3,1,2
JSON:{{"val":{"xOffset":{"val":"0.25874317","id":"pf"},"equipmentData":{"val":{"length":{"val":"5","id":"pi"},"equipmentContents":{"val":[],"id":"ls"}},"id":"ct"},"rotation":{"val":"-73.94983","id":"pf"},"mobID":{"val":"Villager","id":"ss"},"zOffset":{"val":"0.3248642","id":"pf"},"entityData":{"val":{"ForgeData":{"val":{},"id":"ct"},"Attributes":{"val":[{"val":{"Base":{"val":"20.0","id":"pd"},"Name":{"val":"generic.maxHealth","id":"ss"}},"id":"ct"},{"val":{"Base":{"val":"0.0","id":"pd"},"Name":{"val":"generic.knockbackResistance","id":"ss"}},"id":"ct"},{"val":{"Base":{"val":"0.5","id":"pd"},"Name":{"val":"generic.movementSpeed","id":"ss"}},"id":"ct"},{"val":{"Base":{"val":"16.0","id":"pd"},"Modifiers":{"val":[{"val":{"UUIDMost":{"val":"-6399884855950752536","id":"pl"},"UUIDLeast":{"val":"-5094253166276662727","id":"pl"},"Amount":{"val":"7.984530144574868E-4","id":"pd"},"Operation":{"val":"1","id":"pi"},"Name":{"val":"Random spawn bonus","id":"ss"}},"id":"ct"}],"id":"ls"},"Name":{"val":"generic.followRange","id":"ss"}},"id":"ct"}],"id":"ls"},"Riches":{"val":"0","id":"pi"},"Invulnerable":{"val":"0","id":"pb"},"VNExtendedVillager":{"val":{"SkinTone":{"val":"0","id":"pi"},"BiomeType":{"val":"0","id":"pi"},"Defined":{"val":"1","id":"pb"},"ProfessionLevel":{"val":"0","id":"pi"},"Career":{"val":"1","id":"pi"}},"id":"ct"},"PortalCooldown":{"val":"0","id":"pi"},"AbsorptionAmount":{"val":"0.0","id":"pf"},"FallDistance":{"val":"0.0","id":"pf"},"HbmLivingProps":{"val":{"hfr_activation":{"val":"0.0","id":"pf"},"hfr_oxygen":{"val":"100","id":"pi"},"hfr_asbestos":{"val":"0","id":"pi"},"hfr_radiation":{"val":"1.6334064E-12","id":"pf"},"hfr_blacklung":{"val":"0","id":"pi"},"hfr_bomb":{"val":"0","id":"pi"},"hfr_digamma":{"val":"0.0","id":"pf"},"hfr_contagion":{"val":"0","id":"pi"},"hfr_oil":{"val":"0","id":"pi"},"hfr_gravity":{"val":"1","id":"pb"},"hfr_cont_count":{"val":"0","id":"pi"}},"id":"ct"},"DeathTime":{"val":"0","id":"ps"},"DropChances":{"val":[{"val":"0.085","id":"pf"},{"val":"0.085","id":"pf"},{"val":"0.085","id":"pf"},{"val":"0.085","id":"pf"},{"val":"0.085","id":"pf"}],"id":"ls"},"PersistenceRequired":{"val":"0","id":"pb"},"HealF":{"val":"20.0","id":"pf"},"archTimeToReset":{"val":"0","id":"pi"},"Age":{"val":"0","id":"pi"},"Motion":{"val":[{"val":"0.0","id":"pd"},{"val":"-0.0784000015258789","id":"pd"},{"val":"0.0","id":"pd"}],"id":"ls"},"Leashed":{"val":"0","id":"pb"},"Health":{"val":"20","id":"ps"},"Air":{"val":"300","id":"ps"},"OnGround":{"val":"1","id":"pb"},"Dimension":{"val":"0","id":"pi"},"Offers":{"val":{"Recipes":{"val":[{"val":{"maxUses":{"val":"7","id":"pi"},"buy":{"val":{"id":{"val":"266","id":"ps"},"Count":{"val":"9","id":"pb"},"Damage":{"val":"0","id":"ps"}},"id":"ct"},"sell":{"val":{"id":{"val":"388","id":"ps"},"Count":{"val":"1","id":"pb"},"Damage":{"val":"0","id":"ps"}},"id":"ct"},"uses":{"val":"0","id":"pi"}},"id":"ct"}],"id":"ls"}},"id":"ct"},"Rotation":{"val":[{"val":"-613.9498","id":"pf"},{"val":"-7.861776","id":"pf"}],"id":"ls"},"Profession":{"val":"5","id":"pi"},"CustomName":{"val":"","id":"ss"},"Pos":{"val":[{"val":"432.74125685693485","id":"pd"},{"val":"14.0","id":"pd"},{"val":"-356.32486420733875","id":"pd"}],"id":"ls"},"Fire":{"val":"-1","id":"ps"},"CanPickUpLoot":{"val":"0","id":"pb"},"HurtTime":{"val":"0","id":"ps"},"AttackTime":{"val":"0","id":"ps"},"CustomNameVisible":{"val":"0","id":"pb"}},"id":"ct"}},"id":"ct"}}
:enddata
:endentity

entity:
plugin=vanillaLogicEntity
number=2
data:
position=2,1,5
JSON:{{"val":{"xOffset":{"val":"0.519193","id":"pf"},"equipmentData":{"val":{"length":{"val":"5","id":"pi"},"equipmentContents":{"val":[],"id":"ls"}},"id":"ct"},"rotation":{"val":"270.3193","id":"pf"},"mobID":{"val":"Villager","id":"ss"},"zOffset":{"val":"0.86958677","id":"pf"},"entityData":{"val":{"ForgeData":{"val":{},"id":"ct"},"Attributes":{"val":[{"val":{"Base":{"val":"20.0","id":"pd"},"Name":{"val":"generic.maxHealth","id":"ss"}},"id":"ct"},{"val":{"Base":{"val":"0.0","id":"pd"},"Name":{"val":"generic.knockbackResistance","id":"ss"}},"id":"ct"},{"val":{"Base":{"val":"0.5","id":"pd"},"Name":{"val":"generic.movementSpeed","id":"ss"}},"id":"ct"},{"val":{"Base":{"val":"16.0","id":"pd"},"Modifiers":{"val":[{"val":{"UUIDMost":{"val":"3743098930128701907","id":"pl"},"UUIDLeast":{"val":"-7981124348090980092","id":"pl"},"Amount":{"val":"-0.05179734976678696","id":"pd"},"Operation":{"val":"1","id":"pi"},"Name":{"val":"Random spawn bonus","id":"ss"}},"id":"ct"}],"id":"ls"},"Name":{"val":"generic.followRange","id":"ss"}},"id":"ct"}],"id":"ls"},"Riches":{"val":"0","id":"pi"},"Invulnerable":{"val":"0","id":"pb"},"VNExtendedVillager":{"val":{"SkinTone":{"val":"0","id":"pi"},"BiomeType":{"val":"0","id":"pi"},"Defined":{"val":"1","id":"pb"},"ProfessionLevel":{"val":"1","id":"pi"},"Career":{"val":"1","id":"pi"}},"id":"ct"},"PortalCooldown":{"val":"0","id":"pi"},"AbsorptionAmount":{"val":"0.0","id":"pf"},"FallDistance":{"val":"0.0","id":"pf"},"HbmLivingProps":{"val":{"hfr_activation":{"val":"0.0","id":"pf"},"hfr_oxygen":{"val":"100","id":"pi"},"hfr_asbestos":{"val":"0","id":"pi"},"hfr_radiation":{"val":"1.1448717E-12","id":"pf"},"hfr_blacklung":{"val":"0","id":"pi"},"hfr_bomb":{"val":"0","id":"pi"},"hfr_digamma":{"val":"0.0","id":"pf"},"hfr_contagion":{"val":"0","id":"pi"},"hfr_oil":{"val":"0","id":"pi"},"hfr_gravity":{"val":"1","id":"pb"},"hfr_cont_count":{"val":"0","id":"pi"}},"id":"ct"},"DeathTime":{"val":"0","id":"ps"},"DropChances":{"val":[{"val":"0.085","id":"pf"},{"val":"0.085","id":"pf"},{"val":"0.085","id":"pf"},{"val":"0.085","id":"pf"},{"val":"0.085","id":"pf"}],"id":"ls"},"PersistenceRequired":{"val":"0","id":"pb"},"HealF":{"val":"18.5","id":"pf"},"archTimeToReset":{"val":"0","id":"pi"},"Age":{"val":"0","id":"pi"},"Motion":{"val":[{"val":"0.0","id":"pd"},{"val":"-0.0784000015258789","id":"pd"},{"val":"0.0","id":"pd"}],"id":"ls"},"Leashed":{"val":"0","id":"pb"},"Health":{"val":"19","id":"ps"},"Air":{"val":"300","id":"ps"},"OnGround":{"val":"1","id":"pb"},"Dimension":{"val":"0","id":"pi"},"Offers":{"val":{"Recipes":{"val":[{"val":{"maxUses":{"val":"7","id":"pi"},"buy":{"val":{"id":{"val":"388","id":"ps"},"Count":{"val":"1","id":"pb"},"Damage":{"val":"0","id":"ps"}},"id":"ct"},"sell":{"val":{"id":{"val":"331","id":"ps"},"Count":{"val":"4","id":"pb"},"Damage":{"val":"0","id":"ps"}},"id":"ct"},"uses":{"val":"0","id":"pi"}},"id":"ct"}],"id":"ls"}},"id":"ct"},"Rotation":{"val":[{"val":"90.3193","id":"pf"},{"val":"35.810215","id":"pf"}],"id":"ls"},"Profession":{"val":"2","id":"pi"},"CustomName":{"val":"","id":"ss"},"Pos":{"val":[{"val":"433.4808069929042","id":"pd"},{"val":"14.5","id":"pd"},{"val":"-359.86958679494035","id":"pd"}],"id":"ls"},"Fire":{"val":"-1","id":"ps"},"CanPickUpLoot":{"val":"0","id":"pb"},"HurtTime":{"val":"0","id":"ps"},"AttackTime":{"val":"0","id":"ps"},"CustomNameVisible":{"val":"0","id":"pb"}},"id":"ct"}},"id":"ct"}}
:enddata
:endentity

