# Ancient Warfare Structure Template File
# Auto-generated structure template file. created on: 11/8/2024 at: 15:2:58
# Lines beginning with # denote comments

header:
version=2.1
name=Test_hbm_building
size=15,17,12
offset=12,0,13
:endheader

#### VALIDATION ####
validation:
type=ground
survival=true
worldGenEnabled=false
unique=false
preserveBlocks=false
selectionWeight=0
clusterValue=0
minDuplicateDistance=0
dimensionWhiteList=false
dimensionList=
biomeWhiteList=false
biomeList=
leveling=0
fill=0
border=0
validTargetBlocks=
blockSwap=false
data:
:enddata
:endvalidation

#### LAYERS ####
layer: 0
1,1,1,1,1,1,1,1,1,1,1,1,1,1,0
1,3,3,1,5,5,5,5,5,5,5,5,5,1,0
1,3,3,1,5,5,5,5,5,5,5,5,5,1,0
1,3,3,1,5,5,5,5,5,5,5,5,5,1,0
1,3,3,1,5,5,5,5,5,5,5,5,5,1,0
1,3,3,3,5,5,5,5,5,5,5,5,5,1,0
1,3,3,1,5,5,5,5,5,5,5,5,5,1,0
1,1,1,1,5,5,5,5,5,5,5,5,5,1,1
0,0,0,1,5,5,5,5,5,5,5,5,4,4,1
0,0,0,1,5,5,5,5,5,5,5,4,4,4,3
0,0,0,1,1,1,1,1,1,1,1,4,4,4,3
0,0,0,0,0,0,0,0,0,0,1,1,2,2,1
:endlayer
layer: 1
1,8,8,1,8,9,8,8,8,10,11,8,11,1,0
9,0,0,8,0,0,0,0,0,0,0,0,0,11,0
11,14,0,9,0,0,0,0,0,0,0,0,0,8,0
8,13,0,11,0,0,0,0,0,0,0,0,0,8,0
9,0,0,11,0,0,0,0,0,0,0,0,0,8,0
9,0,0,12,0,0,0,0,0,0,0,0,0,8,0
8,0,0,11,0,0,0,0,0,0,0,0,0,9,0
11,8,9,10,0,0,0,0,0,0,0,0,0,11,1
0,0,0,8,0,0,0,0,0,0,0,0,0,0,8
0,0,0,11,0,0,0,0,0,0,0,0,0,0,6
0,0,0,1,8,8,8,10,9,8,9,0,0,0,7
0,0,0,0,0,0,0,0,0,0,1,8,7,6,1
:endlayer
layer: 2
1,8,8,1,8,11,8,8,10,8,11,11,9,1,0
8,0,0,11,0,0,0,0,0,0,0,0,0,11,0
9,0,0,10,0,0,0,0,0,0,0,0,0,1,0
8,14,0,8,0,0,0,0,0,0,0,0,0,18,0
8,13,0,9,0,0,0,0,0,0,0,0,0,18,0
8,0,0,20,0,0,0,0,0,0,0,0,0,1,0
9,0,0,11,0,0,0,0,0,0,0,0,0,8,0
11,11,9,8,0,0,0,0,0,0,0,0,0,10,1
0,0,0,11,0,0,0,0,0,0,0,0,0,0,10
0,0,0,8,0,0,0,0,0,0,0,0,0,0,19
0,0,0,1,11,1,18,18,1,8,11,0,0,0,17
0,0,0,0,0,0,0,0,0,0,1,8,16,15,1
:endlayer
layer: 3
1,8,9,1,8,8,8,9,8,9,11,8,9,1,0
8,0,0,9,0,0,0,0,0,0,0,0,0,9,0
9,0,0,8,0,0,0,0,0,0,0,0,0,1,0
10,0,0,11,0,0,0,0,0,0,0,0,0,18,0
8,14,0,9,0,0,0,0,0,0,0,0,0,18,0
11,13,0,10,0,0,0,0,0,0,0,0,0,1,0
8,0,0,8,0,0,0,0,0,0,0,0,0,9,0
10,9,9,9,0,0,0,0,0,0,0,0,0,9,1
0,0,0,8,0,0,0,0,0,0,0,0,0,0,11
0,0,0,8,0,0,0,0,0,0,0,0,0,0,9
0,0,0,1,8,1,18,18,1,9,8,0,0,0,8
0,0,0,0,0,0,0,0,0,0,1,9,8,11,1
:endlayer
layer: 4
1,2,2,1,9,9,11,9,8,9,10,10,8,1,0
11,0,0,9,5,5,5,5,5,5,5,5,5,10,0
8,0,0,8,5,5,5,5,5,5,5,5,5,8,0
9,0,0,8,5,5,5,5,5,5,5,5,5,8,0
11,0,0,8,5,5,5,5,5,5,5,5,5,10,0
11,14,21,11,5,5,5,5,5,5,5,5,5,8,0
8,2,2,2,5,5,5,5,5,5,5,5,5,8,0
10,8,8,8,5,5,5,5,5,5,5,5,5,10,1
0,0,0,9,5,5,5,5,5,5,5,5,5,5,10
0,0,0,8,5,5,5,5,5,5,5,5,5,5,9
0,0,0,1,8,11,8,8,11,11,11,5,5,5,8
0,0,0,0,0,0,0,0,0,0,1,8,11,11,1
:endlayer
layer: 5
1,9,8,1,10,11,9,11,9,9,9,9,8,1,0
9,0,0,10,0,0,0,0,0,0,0,0,0,9,0
11,0,0,9,0,0,0,0,0,0,0,0,0,8,0
11,0,0,11,0,0,0,0,0,0,0,0,0,8,0
9,0,21,8,0,0,0,0,0,0,0,0,0,9,0
11,0,24,9,0,0,0,0,0,0,0,0,0,11,0
9,0,0,23,0,0,0,0,0,0,0,0,0,8,0
8,9,9,10,0,0,0,0,0,0,11,22,11,9,1
0,0,0,8,0,0,0,0,0,0,8,0,0,0,8
0,0,0,9,0,0,0,0,0,0,11,0,0,0,11
0,0,0,1,9,11,8,8,11,8,11,0,0,0,9
0,0,0,0,0,0,0,0,0,0,1,8,9,8,1
:endlayer
layer: 6
1,9,10,1,8,8,9,8,11,8,8,11,11,1,0
8,0,0,9,0,0,0,0,0,0,0,0,0,9,0
9,0,0,11,0,0,0,0,0,0,0,0,0,18,0
9,0,21,8,0,0,0,0,0,0,0,0,0,18,0
10,0,24,11,0,0,0,0,0,0,0,0,0,18,0
8,0,0,9,0,0,0,0,0,0,0,0,0,18,0
11,0,0,20,0,0,0,0,0,0,0,0,0,8,0
9,9,9,8,0,0,0,0,0,0,8,20,9,8,1
0,0,0,9,0,0,0,0,0,0,8,0,0,0,18
0,0,0,9,0,0,0,0,0,0,11,0,0,0,18
0,0,0,1,11,18,18,18,18,8,9,0,0,0,18
0,0,0,0,0,0,0,0,0,0,1,18,18,18,1
:endlayer
layer: 7
1,9,8,1,9,9,9,8,9,10,8,10,8,1,0
9,0,0,10,0,0,0,0,0,0,0,0,0,8,0
11,0,21,11,0,0,0,0,0,0,0,0,0,18,0
11,0,24,9,0,0,0,0,0,0,0,0,0,18,0
8,0,0,8,0,0,0,0,0,0,0,0,0,18,0
11,0,0,11,0,0,0,0,0,0,0,0,0,18,0
11,0,0,8,0,0,0,0,0,0,0,0,0,10,0
9,8,11,9,0,0,0,0,0,0,8,11,8,8,1
0,0,0,11,0,0,0,0,0,0,11,0,0,0,18
0,0,0,10,0,0,0,0,0,0,8,0,0,0,18
0,0,0,1,8,18,18,18,18,9,9,0,0,0,18
0,0,0,0,0,0,0,0,0,0,1,18,18,18,1
:endlayer
layer: 8
1,2,2,2,2,2,2,2,2,2,2,2,2,1,0
8,2,2,2,5,5,5,5,5,5,5,5,5,9,0
11,13,24,9,5,5,5,5,5,5,5,5,5,8,0
8,0,0,9,5,5,5,5,5,5,5,5,5,8,0
9,0,0,8,5,5,5,5,5,5,5,5,5,9,0
8,0,0,8,5,5,5,5,5,5,5,5,5,10,0
8,0,0,9,5,5,5,5,5,5,5,5,5,11,0
9,8,9,9,5,5,5,5,5,5,5,5,5,9,1
0,0,0,8,5,5,5,5,5,5,5,5,5,5,10
0,0,0,8,5,5,5,5,5,5,5,5,5,5,8
0,0,0,1,9,11,9,10,10,8,8,5,5,5,11
0,0,0,0,0,0,0,0,0,0,1,11,11,10,1
:endlayer
layer: 9
1,9,8,1,9,8,11,8,8,8,11,8,9,1,0
10,0,0,12,0,0,0,0,0,0,0,0,0,10,0
11,14,0,8,0,0,0,0,0,0,0,0,0,9,0
9,13,0,9,0,0,0,0,0,0,0,0,0,9,0
8,0,0,8,0,0,0,0,0,0,0,0,0,11,0
11,0,0,9,0,0,0,0,0,0,0,0,0,10,0
8,0,0,8,0,0,0,0,0,0,0,0,0,10,0
8,10,11,9,0,0,0,0,0,0,9,9,11,8,1
0,0,0,9,0,0,0,0,0,0,23,0,0,0,8
0,0,0,8,0,0,0,0,0,0,11,0,0,0,8
0,0,0,1,8,8,11,9,8,11,9,0,0,0,8
0,0,0,0,0,0,0,0,0,0,1,11,9,9,1
:endlayer
layer: 10
1,8,9,1,18,18,18,18,11,18,18,18,8,1,0
9,0,0,20,0,0,0,0,0,0,0,0,0,8,0
11,0,0,10,0,0,0,0,0,0,0,0,0,18,0
11,14,0,9,0,0,0,0,0,0,0,0,0,18,0
10,13,0,9,0,0,0,0,0,0,0,0,0,18,0
10,0,0,9,0,0,0,0,0,0,0,0,0,18,0
8,0,0,8,0,0,0,0,0,0,0,0,0,11,0
11,8,8,10,0,0,0,0,0,0,8,8,9,11,1
0,0,0,9,0,0,0,0,0,0,20,0,0,0,18
0,0,0,8,0,0,0,0,0,0,8,0,0,0,18
0,0,0,1,9,18,18,18,18,10,11,0,0,0,18
0,0,0,0,0,0,0,0,0,0,1,18,18,18,1
:endlayer
layer: 11
1,8,8,1,9,8,9,10,8,8,8,8,8,1,0
9,0,0,8,0,0,0,0,0,0,0,0,0,9,0
8,0,0,9,0,0,0,0,0,0,0,0,0,18,0
9,0,0,9,0,0,0,0,0,0,0,0,0,18,0
9,14,0,11,0,0,0,0,0,0,0,0,0,18,0
10,13,0,8,0,0,0,0,0,0,0,0,0,18,0
8,0,0,9,0,0,0,0,0,0,0,0,0,9,0
11,9,8,8,0,0,0,0,0,0,9,10,8,11,1
0,0,0,11,0,0,0,0,0,0,8,0,0,0,18
0,0,0,8,0,0,0,0,0,0,8,0,0,0,18
0,0,0,1,8,18,18,18,18,9,8,0,0,0,18
0,0,0,0,0,0,0,0,0,0,1,18,18,18,1
:endlayer
layer: 12
1,2,2,2,2,2,2,2,2,2,2,8,8,1,0
9,26,26,9,25,25,25,25,25,25,25,25,25,8,0
8,0,0,8,25,25,25,25,25,25,25,25,25,9,0
8,0,0,11,25,25,25,25,25,25,25,25,25,9,0
8,0,0,8,25,25,25,25,25,25,25,25,25,9,0
11,14,0,8,25,25,25,25,25,25,25,25,25,9,0
8,2,2,9,25,25,25,25,25,25,25,25,25,9,0
8,11,9,10,25,25,25,25,25,25,25,25,25,9,1
0,0,0,9,25,25,25,25,25,25,25,25,25,25,9
0,0,0,10,25,25,25,25,25,25,25,25,25,25,9
0,0,0,1,10,9,8,8,10,8,11,25,25,25,8
0,0,0,0,0,0,0,0,0,0,1,8,11,8,1
:endlayer
layer: 13
27,27,27,27,27,27,27,27,27,27,27,27,27,27,0
27,0,0,0,0,0,0,0,0,0,0,0,0,27,0
8,26,26,9,0,0,0,0,0,0,0,0,0,27,0
11,0,0,11,0,0,0,0,0,0,0,0,0,27,0
9,0,0,11,0,0,0,0,0,0,0,0,0,27,0
10,0,0,9,0,0,0,0,0,0,0,0,0,27,0
10,0,0,28,0,0,0,0,0,0,0,0,0,27,0
8,8,9,8,0,0,0,0,0,0,0,0,0,27,27
0,0,0,27,0,0,0,0,0,0,0,0,0,0,27
0,0,0,27,0,0,0,0,0,0,0,0,0,0,27
0,0,0,27,27,27,27,27,27,27,27,0,0,0,27
0,0,0,0,0,0,0,0,0,0,27,27,27,27,27
:endlayer
layer: 14
0,0,0,0,0,0,0,0,0,0,0,0,0,0,0
0,0,0,0,0,0,0,0,0,0,0,0,0,0,0
0,0,0,0,0,0,0,0,0,0,0,0,0,0,0
10,26,26,8,0,0,0,0,0,0,0,0,0,0,0
8,0,0,9,0,0,0,0,0,0,0,0,0,0,0
9,0,0,10,0,0,0,0,0,0,0,0,0,0,0
8,0,0,29,0,0,0,0,0,0,0,0,0,0,0
9,9,9,8,0,0,0,0,0,0,0,0,0,0,0
0,0,0,0,0,0,0,0,0,0,0,0,0,0,0
0,0,0,0,0,0,0,0,0,0,0,0,0,0,0
0,0,0,0,0,0,0,0,0,0,0,0,0,0,0
0,0,0,0,0,0,0,0,0,0,0,0,0,0,0
:endlayer
layer: 15
0,0,0,0,0,0,0,0,0,0,0,0,0,0,0
0,0,0,0,0,0,0,0,0,0,0,0,0,0,0
0,0,0,0,0,0,0,0,0,0,0,0,0,0,0
0,0,0,0,0,0,0,0,0,0,0,0,0,0,0
9,26,26,11,0,0,0,0,0,0,0,0,0,0,0
9,26,26,9,0,0,0,0,0,0,0,0,0,0,0
8,26,26,8,0,0,0,0,0,0,0,0,0,0,0
11,9,8,10,0,0,0,0,0,0,0,0,0,0,0
0,0,0,0,0,0,0,0,0,0,0,0,0,0,0
0,0,0,0,0,0,0,0,0,0,0,0,0,0,0
0,0,0,0,0,0,0,0,0,0,0,0,0,0,0
0,0,0,0,0,0,0,0,0,0,0,0,0,0,0
:endlayer
layer: 16
0,0,0,0,0,0,0,0,0,0,0,0,0,0,0
0,0,0,0,0,0,0,0,0,0,0,0,0,0,0
0,0,0,0,0,0,0,0,0,0,0,0,0,0,0
0,0,0,0,0,0,0,0,0,0,0,0,0,0,0
0,0,0,0,0,0,0,0,0,0,0,0,0,0,0
0,0,0,0,0,0,0,0,0,0,0,0,0,0,0
0,0,0,0,0,0,0,0,0,0,0,0,0,0,0
0,0,0,0,0,0,0,0,0,0,0,0,0,0,0
0,0,0,0,0,0,0,0,0,0,0,0,0,0,0
0,0,0,0,0,0,0,0,0,0,0,0,0,0,0
0,0,0,0,0,0,0,0,0,0,0,0,0,0,0
0,0,0,0,0,0,0,0,0,0,0,0,0,0,0
:endlayer

#### RULES ####
rule:
plugin=modBlockDefault
number=1
data:
JSON:{{"val":{"blockName":{"val":"hbm:tile.concrete_pillar","id":"ss"},"meta":{"val":"0","id":"pi"}},"id":"ct"}}
:enddata
:endrule

rule:
plugin=modBlockDefault
number=2
data:
JSON:{{"val":{"blockName":{"val":"hbm:tile.concrete_pillar","id":"ss"},"meta":{"val":"4","id":"pi"}},"id":"ct"}}
:enddata
:endrule

rule:
plugin=modBlockDefault
number=3
data:
JSON:{{"val":{"blockName":{"val":"hbm:tile.concrete_pillar","id":"ss"},"meta":{"val":"8","id":"pi"}},"id":"ct"}}
:enddata
:endrule

rule:
plugin=vanillaBlocks
number=4
data:
JSON:{{"val":{"buildPass":{"val":"0","id":"pi"},"blockName":{"val":"minecraft:wool","id":"ss"},"meta":{"val":"7","id":"pi"}},"id":"ct"}}
:enddata
:endrule

rule:
plugin=vanillaBlocks
number=5
data:
JSON:{{"val":{"buildPass":{"val":"0","id":"pi"},"blockName":{"val":"minecraft:planks","id":"ss"},"meta":{"val":"1","id":"pi"}},"id":"ct"}}
:enddata
:endrule

rule:
plugin=vanillaDoors
number=6
data:
JSON:{{"val":{"buildPass":{"val":"2","id":"pi"},"blockName":{"val":"minecraft:wooden_door","id":"ss"},"meta":{"val":"7","id":"pi"},"sideFlag":{"val":"9","id":"pb"}},"id":"ct"}}
:enddata
:endrule

rule:
plugin=vanillaDoors
number=7
data:
JSON:{{"val":{"buildPass":{"val":"2","id":"pi"},"blockName":{"val":"minecraft:wooden_door","id":"ss"},"meta":{"val":"7","id":"pi"},"sideFlag":{"val":"8","id":"pb"}},"id":"ct"}}
:enddata
:endrule

rule:
plugin=modBlockDefault
number=8
data:
JSON:{{"val":{"blockName":{"val":"hbm:tile.brick_concrete","id":"ss"},"meta":{"val":"0","id":"pi"}},"id":"ct"}}
:enddata
:endrule

rule:
plugin=modBlockDefault
number=9
data:
JSON:{{"val":{"blockName":{"val":"hbm:tile.brick_concrete_mossy","id":"ss"},"meta":{"val":"0","id":"pi"}},"id":"ct"}}
:enddata
:endrule

rule:
plugin=modBlockDefault
number=10
data:
JSON:{{"val":{"blockName":{"val":"hbm:tile.brick_concrete_broken","id":"ss"},"meta":{"val":"0","id":"pi"}},"id":"ct"}}
:enddata
:endrule

rule:
plugin=modBlockDefault
number=11
data:
JSON:{{"val":{"blockName":{"val":"hbm:tile.brick_concrete_cracked","id":"ss"},"meta":{"val":"0","id":"pi"}},"id":"ct"}}
:enddata
:endrule

rule:
plugin=modBlockDefault
number=12
data:
JSON:{{"val":{"blockName":{"val":"hbm:tile.door_office","id":"ss"},"meta":{"val":"4","id":"pi"}},"id":"ct"}}
:enddata
:endrule

rule:
plugin=vanillaBlocks
number=13
data:
JSON:{{"val":{"buildPass":{"val":"0","id":"pi"},"blockName":{"val":"minecraft:oak_stairs","id":"ss"},"meta":{"val":"7","id":"pi"}},"id":"ct"}}
:enddata
:endrule

rule:
plugin=vanillaBlocks
number=14
data:
JSON:{{"val":{"buildPass":{"val":"0","id":"pi"},"blockName":{"val":"minecraft:oak_stairs","id":"ss"},"meta":{"val":"2","id":"pi"}},"id":"ct"}}
:enddata
:endrule

rule:
plugin=vanillaDoors
number=15
data:
JSON:{{"val":{"buildPass":{"val":"2","id":"pi"},"blockName":{"val":"minecraft:wooden_door","id":"ss"},"meta":{"val":"9","id":"pi"},"sideFlag":{"val":"0","id":"pb"}},"id":"ct"}}
:enddata
:endrule

rule:
plugin=vanillaDoors
number=16
data:
JSON:{{"val":{"buildPass":{"val":"2","id":"pi"},"blockName":{"val":"minecraft:wooden_door","id":"ss"},"meta":{"val":"8","id":"pi"},"sideFlag":{"val":"0","id":"pb"}},"id":"ct"}}
:enddata
:endrule

rule:
plugin=vanillaDoors
number=17
data:
JSON:{{"val":{"buildPass":{"val":"2","id":"pi"},"blockName":{"val":"minecraft:wooden_door","id":"ss"},"meta":{"val":"8","id":"pi"},"sideFlag":{"val":"0","id":"pb"}},"id":"ct"}}
:enddata
:endrule

rule:
plugin=vanillaBlocks
number=18
data:
JSON:{{"val":{"buildPass":{"val":"0","id":"pi"},"blockName":{"val":"minecraft:glass_pane","id":"ss"},"meta":{"val":"0","id":"pi"}},"id":"ct"}}
:enddata
:endrule

rule:
plugin=vanillaDoors
number=19
data:
JSON:{{"val":{"buildPass":{"val":"2","id":"pi"},"blockName":{"val":"minecraft:wooden_door","id":"ss"},"meta":{"val":"9","id":"pi"},"sideFlag":{"val":"0","id":"pb"}},"id":"ct"}}
:enddata
:endrule

rule:
plugin=modBlockDefault
number=20
data:
JSON:{{"val":{"blockName":{"val":"hbm:tile.door_office","id":"ss"},"meta":{"val":"8","id":"pi"}},"id":"ct"}}
:enddata
:endrule

rule:
plugin=vanillaBlocks
number=21
data:
JSON:{{"val":{"buildPass":{"val":"0","id":"pi"},"blockName":{"val":"minecraft:oak_stairs","id":"ss"},"meta":{"val":"6","id":"pi"}},"id":"ct"}}
:enddata
:endrule

rule:
plugin=modBlockDefault
number=22
data:
JSON:{{"val":{"blockName":{"val":"hbm:tile.door_office","id":"ss"},"meta":{"val":"7","id":"pi"}},"id":"ct"}}
:enddata
:endrule

rule:
plugin=modBlockDefault
number=23
data:
JSON:{{"val":{"blockName":{"val":"hbm:tile.door_office","id":"ss"},"meta":{"val":"6","id":"pi"}},"id":"ct"}}
:enddata
:endrule

rule:
plugin=vanillaBlocks
number=24
data:
JSON:{{"val":{"buildPass":{"val":"0","id":"pi"},"blockName":{"val":"minecraft:oak_stairs","id":"ss"},"meta":{"val":"3","id":"pi"}},"id":"ct"}}
:enddata
:endrule

rule:
plugin=modBlockDefault
number=25
data:
JSON:{{"val":{"blockName":{"val":"hbm:tile.brick_light","id":"ss"},"meta":{"val":"0","id":"pi"}},"id":"ct"}}
:enddata
:endrule

rule:
plugin=modBlockDefault
number=26
data:
JSON:{{"val":{"blockName":{"val":"hbm:tile.asphalt","id":"ss"},"meta":{"val":"0","id":"pi"}},"id":"ct"}}
:enddata
:endrule

rule:
plugin=vanillaBlocks
number=27
data:
JSON:{{"val":{"buildPass":{"val":"0","id":"pi"},"blockName":{"val":"minecraft:stone_slab","id":"ss"},"meta":{"val":"0","id":"pi"}},"id":"ct"}}
:enddata
:endrule

rule:
plugin=modBlockDefault
number=28
data:
JSON:{{"val":{"blockName":{"val":"hbm:tile.door_metal","id":"ss"},"meta":{"val":"0","id":"pi"}},"id":"ct"}}
:enddata
:endrule

rule:
plugin=modBlockDefault
number=29
data:
JSON:{{"val":{"blockName":{"val":"hbm:tile.door_metal","id":"ss"},"meta":{"val":"8","id":"pi"}},"id":"ct"}}
:enddata
:endrule

#### ENTITIES ####
